{
  "version": 8,
  "blockIdVersion": 11,
  "anchorX": 0,
  "anchorY": -1,
  "anchorZ": 19,
  "blocks": [
    {
      "x": -11,
      "y": -1,
      "z": -1,
      "name": "Rock_Stone_Mossy"
    },
    {
      "x": -11,
      "y": 0,
      "z": -1,
      "name": "Plant_Moss_Block_Green",
      "support": 15
    },
    {
      "x": -11,
      "y": -1,
      "z": 1,
      "name": "Plant_Moss_Block_Green",
      "support": 15
    },
    {
      "x": -11,
      "y": 0,
      "z": 1,
      "name": "Plant_Moss_Block_Green",
      "support": 15
    },
    {
      "x": -11,
      "y": -1,
      "z": 2,
      "name": "Rock_Sandstone_Red_Brick_Pillar_Middle"
    },
    {
      "x": -11,
      "y": -1,
      "z": 3,
      "name": "Rock_Basalt_Brick_Smooth"
    },
    {
      "x": -11,
      "y": 0,
      "z": 3,
      "name": "Rock_Basalt_Brick_Smooth"
    },
    {
      "x": -11,
      "y": 1,
      "z": 3,
      "name": "Rock_Sandstone_Red_Brick_Pillar_Base"
    },
    {
      "x": -11,
      "y": 2,
      "z": 3,
      "name": "Soil_Clay_Black"
    },
    {
      "x": -11,
      "y": 3,
      "z": 3,
      "name": "Soil_Clay_Black"
    },
    {
      "x": -11,
      "y": 4,
      "z": 3,
      "name": "Soil_Clay_Black"
    },
    {
      "x": -11,
      "y": 5,
      "z": 3,
      "name": "Soil_Clay_Black"
    },
    {
      "x": -11,
      "y": -1,
      "z": 4,
      "name": "Rock_Basalt_Brick_Smooth"
    },
    {
      "x": -11,
      "y": 0,
      "z": 4,
      "name": "Rock_Basalt_Brick_Smooth"
    },
    {
      "x": -11,
      "y": 1,
      "z": 4,
      "name": "Rock_Sandstone_Red_Brick_Pillar_Base"
    },
    {
      "x": -11,
      "y": 2,
      "z": 4,
      "name": "Rock_Sandstone_Red_Brick_Pillar_Middle"
    },
    {
      "x": -11,
      "y": 3,
      "z": 4,
      "name": "Rock_Sandstone_Red_Brick_Pillar_Middle"
    },
    {
      "x": -11,
      "y": 4,
      "z": 4,
      "name": "Rock_Sandstone_Red_Brick_Pillar_Middle"
    },
    {
      "x": -11,
      "y": 5,
      "z": 4,
      "name": "Soil_Clay_Black"
    },
    {
      "x": -10,
      "y": -1,
      "z": -1,
      "name": "Rock_Basalt_Cobble"
    },
    {
      "x": -10,
      "y": 0,
      "z": -1,
      "name": "Rock_Basalt_Brick_Decorative"
    },
    {
      "x": -10,
      "y": 1,
      "z": -1,
      "name": "Soil_Clay_Black"
    },
    {
      "x": -10,
      "y": 2,
      "z": -1,
      "name": "Ore_Cobalt_Slate_Cracked"
    },
    {
      "x": -10,
      "y": 3,
      "z": -1,
      "name": "Rock_Slate"
    },
    {
      "x": -10,
      "y": 4,
      "z": -1,
      "name": "Rock_Slate"
    },
    {
      "x": -10,
      "y": -1,
      "z": 0,
      "name": "Rock_Basalt_Cobble"
    },
    {
      "x": -10,
      "y": 0,
      "z": 0,
      "name": "Rock_Basalt_Brick_Decorative"
    },
    {
      "x": -10,
      "y": 1,
      "z": 0,
      "name": "Soil_Clay_Black"
    },
    {
      "x": -10,
      "y": 2,
      "z": 0,
      "name": "Ore_Cobalt_Slate_Cracked"
    },
    {
      "x": -10,
      "y": 3,
      "z": 0,
      "name": "Rock_Slate"
    },
    {
      "x": -10,
      "y": 4,
      "z": 0,
      "name": "Rock_Slate_Cobble"
    },
    {
      "x": -10,
      "y": 5,
      "z": 0,
      "name": "Rock_Slate_Cobble"
    },
    {
      "x": -10,
      "y": -1,
      "z": 1,
      "name": "Rock_Basalt_Cobble"
    },
    {
      "x": -10,
      "y": 0,
      "z": 1,
      "name": "Rock_Basalt_Brick_Decorative"
    },
    {
      "x": -10,
      "y": 1,
      "z": 1,
      "name": "Soil_Clay_Black"
    },
    {
      "x": -10,
      "y": 2,
      "z": 1,
      "name": "Rock_Slate"
    },
    {
      "x": -10,
      "y": 3,
      "z": 1,
      "name": "Rock_Slate"
    },
    {
      "x": -10,
      "y": 4,
      "z": 1,
      "name": "Rock_Slate"
    },
    {
      "x": -10,
      "y": 5,
      "z": 1,
      "name": "Rock_Slate_Cobble"
    },
    {
      "x": -10,
      "y": -1,
      "z": 2,
      "name": "Rock_Basalt_Cobble"
    },
    {
      "x": -10,
      "y": 0,
      "z": 2,
      "name": "Rock_Basalt_Brick_Decorative"
    },
    {
      "x": -10,
      "y": 1,
      "z": 2,
      "name": "Soil_Clay_Black"
    },
    {
      "x": -10,
      "y": 2,
      "z": 2,
      "name": "Rock_Slate"
    },
    {
      "x": -10,
      "y": 3,
      "z": 2,
      "name": "Rock_Slate"
    },
    {
      "x": -10,
      "y": 4,
      "z": 2,
      "name": "Rock_Slate"
    },
    {
      "x": -10,
      "y": 5,
      "z": 2,
      "name": "Rock_Slate_Cobble"
    },
    {
      "x": -10,
      "y": -1,
      "z": 3,
      "name": "Soil_Clay_Black"
    },
    {
      "x": -10,
      "y": 0,
      "z": 3,
      "name": "Soil_Clay_Black"
    },
    {
      "x": -10,
      "y": 1,
      "z": 3,
      "name": "Soil_Clay_Black"
    },
    {
      "x": -10,
      "y": 2,
      "z": 3,
      "name": "Soil_Clay_Black"
    },
    {
      "x": -10,
      "y": 3,
      "z": 3,
      "name": "Soil_Clay_Black"
    },
    {
      "x": -10,
      "y": 4,
      "z": 3,
      "name": "Soil_Clay_Black"
    },
    {
      "x": -10,
      "y": 5,
      "z": 3,
      "name": "Soil_Clay_Black"
    },
    {
      "x": -10,
      "y": -1,
      "z": 4,
      "name": "Soil_Clay_Black"
    },
    {
      "x": -10,
      "y": 0,
      "z": 4,
      "name": "Soil_Clay_Black"
    },
    {
      "x": -10,
      "y": 1,
      "z": 4,
      "name": "Soil_Clay_Black"
    },
    {
      "x": -10,
      "y": 2,
      "z": 4,
      "name": "Soil_Clay_Black"
    },
    {
      "x": -10,
      "y": 3,
      "z": 4,
      "name": "Soil_Clay_Black"
    },
    {
      "x": -10,
      "y": 4,
      "z": 4,
      "name": "Soil_Clay_Black"
    },
    {
      "x": -10,
      "y": 5,
      "z": 4,
      "name": "Soil_Clay_Black"
    },
    {
      "x": -10,
      "y": -1,
      "z": 5,
      "name": "Plant_Moss_Block_Green",
      "support": 15
    },
    {
      "x": -9,
      "y": -1,
      "z": -1,
      "name": "Rock_Basalt_Cobble"
    },
    {
      "x": -9,
      "y": 2,
      "z": -1,
      "name": "Rock_Slate_Cobble"
    },
    {
      "x": -9,
      "y": -1,
      "z": 0,
      "name": "Rock_Basalt_Cobble"
    },
    {
      "x": -9,
      "y": 2,
      "z": 0,
      "name": "Rock_Slate_Cobble"
    },
    {
      "x": -9,
      "y": -1,
      "z": 1,
      "name": "Rock_Basalt_Cobble"
    },
    {
      "x": -9,
      "y": 2,
      "z": 1,
      "name": "Rock_Slate_Cobble"
    },
    {
      "x": -9,
      "y": -1,
      "z": 2,
      "name": "Rock_Basalt_Cobble"
    },
    {
      "x": -9,
      "y": 2,
      "z": 2,
      "name": "Rock_Slate_Cobble"
    },
    {
      "x": -9,
      "y": -1,
      "z": 3,
      "name": "Rock_Basalt_Cobble"
    },
    {
      "x": -9,
      "y": 0,
      "z": 3,
      "name": "Rock_Basalt_Brick_Decorative"
    },
    {
      "x": -9,
      "y": 1,
      "z": 3,
      "name": "Soil_Clay_Black"
    },
    {
      "x": -9,
      "y": 2,
      "z": 3,
      "name": "Rock_Slate"
    },
    {
      "x": -9,
      "y": 3,
      "z": 3,
      "name": "Rock_Slate"
    },
    {
      "x": -9,
      "y": 4,
      "z": 3,
      "name": "Rock_Slate"
    },
    {
      "x": -9,
      "y": 5,
      "z": 3,
      "name": "Rock_Slate"
    },
    {
      "x": -9,
      "y": -1,
      "z": 4,
      "name": "Rock_Basalt_Cobble"
    },
    {
      "x": -9,
      "y": 0,
      "z": 4,
      "name": "Rock_Basalt_Brick_Decorative"
    },
    {
      "x": -9,
      "y": 1,
      "z": 4,
      "name": "Soil_Clay_Black"
    },
    {
      "x": -9,
      "y": 2,
      "z": 4,
      "name": "Rock_Slate"
    },
    {
      "x": -9,
      "y": 3,
      "z": 4,
      "name": "Rock_Slate"
    },
    {
      "x": -9,
      "y": 4,
      "z": 4,
      "name": "Rock_Slate"
    },
    {
      "x": -9,
      "y": 5,
      "z": 4,
      "name": "Rock_Slate"
    },
    {
      "x": -9,
      "y": -1,
      "z": 5,
      "name": "Rock_Basalt_Cobble"
    },
    {
      "x": -9,
      "y": 0,
      "z": 5,
      "name": "Rock_Basalt_Brick_Decorative"
    },
    {
      "x": -9,
      "y": 1,
      "z": 5,
      "name": "Soil_Clay_Black"
    },
    {
      "x": -9,
      "y": 2,
      "z": 5,
      "name": "Rock_Slate"
    },
    {
      "x": -9,
      "y": 3,
      "z": 5,
      "name": "Rock_Slate"
    },
    {
      "x": -9,
      "y": 4,
      "z": 5,
      "name": "Ore_Cobalt_Slate_Cracked"
    },
    {
      "x": -9,
      "y": 5,
      "z": 5,
      "name": "Ore_Cobalt_Slate_Cracked"
    },
    {
      "x": -9,
      "y": -1,
      "z": 6,
      "name": "Rock_Stone_Mossy"
    },
    {
      "x": -9,
      "y": 0,
      "z": 6,
      "name": "Plant_Moss_Block_Green",
      "support": 15
    },
    {
      "x": -9,
      "y": -1,
      "z": 7,
      "name": "Plant_Moss_Block_Green",
      "support": 15
    },
    {
      "x": -8,
      "y": -1,
      "z": -1,
      "name": "Rock_Basalt_Cobble"
    },
    {
      "x": -8,
      "y": 2,
      "z": -1,
      "name": "Rock_Slate_Cobble"
    },
    {
      "x": -8,
      "y": -1,
      "z": 0,
      "name": "Rock_Basalt_Cobble"
    },
    {
      "x": -8,
      "y": 2,
      "z": 0,
      "name": "Rock_Slate_Cobble"
    },
    {
      "x": -8,
      "y": -1,
      "z": 1,
      "name": "Rock_Basalt_Cobble"
    },
    {
      "x": -8,
      "y": 2,
      "z": 1,
      "name": "Rock_Slate_Cobble"
    },
    {
      "x": -8,
      "y": -1,
      "z": 2,
      "name": "Rock_Basalt_Cobble"
    },
    {
      "x": -8,
      "y": 2,
      "z": 2,
      "name": "Rock_Slate"
    },
    {
      "x": -8,
      "y": -1,
      "z": 3,
      "name": "Rock_Basalt_Cobble"
    },
    {
      "x": -8,
      "y": 2,
      "z": 3,
      "name": "Rock_Slate"
    },
    {
      "x": -8,
      "y": -1,
      "z": 4,
      "name": "Rock_Basalt_Cobble"
    },
    {
      "x": -8,
      "y": 0,
      "z": 4,
      "name": "Plant_Moss_Block_Green_Dark",
      "support": 15
    },
    {
      "x": -8,
      "y": 1,
      "z": 4,
      "name": "Plant_Moss_Block_Green_Dark",
      "support": 15
    },
    {
      "x": -8,
      "y": 2,
      "z": 4,
      "name": "Rock_Slate"
    },
    {
      "x": -8,
      "y": 3,
      "z": 4,
      "name": "Plant_Moss_Block_Green_Dark",
      "support": 15
    },
    {
      "x": -8,
      "y": -1,
      "z": 5,
      "name": "Rock_Basalt_Cobble"
    },
    {
      "x": -8,
      "y": 1,
      "z": 5,
      "name": "Plant_Moss_Block_Green_Dark",
      "support": 15
    },
    {
      "x": -8,
      "y": 2,
      "z": 5,
      "name": "Plant_Moss_Block_Green_Dark",
      "support": 15
    },
    {
      "x": -8,
      "y": 3,
      "z": 5,
      "name": "Plant_Moss_Block_Green_Dark",
      "support": 15
    },
    {
      "x": -8,
      "y": 4,
      "z": 5,
      "name": "Plant_Moss_Block_Green_Dark",
      "support": 15
    },
    {
      "x": -8,
      "y": -1,
      "z": 6,
      "name": "Rock_Basalt_Cobble"
    },
    {
      "x": -8,
      "y": 0,
      "z": 6,
      "name": "Rock_Basalt_Brick_Decorative"
    },
    {
      "x": -8,
      "y": 1,
      "z": 6,
      "name": "Soil_Clay_Black"
    },
    {
      "x": -8,
      "y": 2,
      "z": 6,
      "name": "Ore_Cobalt_Slate_Cracked"
    },
    {
      "x": -8,
      "y": 3,
      "z": 6,
      "name": "Rock_Slate"
    },
    {
      "x": -8,
      "y": 4,
      "z": 6,
      "name": "Ore_Cobalt_Slate_Cracked"
    },
    {
      "x": -8,
      "y": 5,
      "z": 6,
      "name": "Ore_Cobalt_Slate_Cracked"
    },
    {
      "x": -8,
      "y": -1,
      "z": 7,
      "name": "Rock_Stone_Mossy"
    },
    {
      "x": -8,
      "y": 0,
      "z": 7,
      "name": "Plant_Moss_Block_Green",
      "support": 15
    },
    {
      "x": -8,
      "y": -1,
      "z": 8,
      "name": "Plant_Moss_Block_Green",
      "support": 15
    },
    {
      "x": -7,
      "y": -1,
      "z": -1,
      "name": "Rock_Basalt_Cobble"
    },
    {
      "x": -7,
      "y": 2,
      "z": -1,
      "name": "Ore_Cobalt_Slate_Cracked"
    },
    {
      "x": -7,
      "y": -1,
      "z": 0,
      "name": "Rock_Basalt_Cobble"
    },
    {
      "x": -7,
      "y": 2,
      "z": 0,
      "name": "Rock_Slate_Cobble"
    },
    {
      "x": -7,
      "y": -1,
      "z": 1,
      "name": "Rock_Basalt_Cobble"
    },
    {
      "x": -7,
      "y": 2,
      "z": 1,
      "name": "Rock_Slate_Cobble"
    },
    {
      "x": -7,
      "y": -1,
      "z": 2,
      "name": "Rock_Basalt_Cobble"
    },
    {
      "x": -7,
      "y": 2,
      "z": 2,
      "name": "Rock_Slate"
    },
    {
      "x": -7,
      "y": -1,
      "z": 3,
      "name": "Rock_Basalt_Cobble"
    },
    {
      "x": -7,
      "y": 2,
      "z": 3,
      "name": "Rock_Slate"
    },
    {
      "x": -7,
      "y": -1,
      "z": 4,
      "name": "Rock_Basalt_Cobble"
    },
    {
      "x": -7,
      "y": 1,
      "z": 4,
      "name": "Plant_Moss_Block_Green_Dark",
      "support": 15
    },
    {
      "x": -7,
      "y": 2,
      "z": 4,
      "name": "Plant_Moss_Block_Green_Dark",
      "support": 15
    },
    {
      "x": -7,
      "y": -1,
      "z": 5,
      "name": "Rock_Basalt_Cobble"
    },
    {
      "x": -7,
      "y": 1,
      "z": 5,
      "name": "Plant_Moss_Block_Green_Dark",
      "support": 15
    },
    {
      "x": -7,
      "y": 2,
      "z": 5,
      "name": "Plant_Moss_Block_Green_Dark",
      "support": 15
    },
    {
      "x": -7,
      "y": 3,
      "z": 5,
      "name": "Plant_Moss_Block_Green_Dark",
      "support": 15
    },
    {
      "x": -7,
      "y": -1,
      "z": 6,
      "name": "Rock_Basalt_Cobble"
    },
    {
      "x": -7,
      "y": 2,
      "z": 6,
      "name": "Ore_Cobalt_Slate_Cracked"
    },
    {
      "x": -7,
      "y": 3,
      "z": 6,
      "name": "Rock_Crystal_Yellow_Medium"
    },
    {
      "x": -7,
      "y": -1,
      "z": 7,
      "name": "Rock_Basalt_Cobble"
    },
    {
      "x": -7,
      "y": 0,
      "z": 7,
      "name": "Rock_Basalt_Brick_Decorative"
    },
    {
      "x": -7,
      "y": 1,
      "z": 7,
      "name": "Soil_Clay_Black"
    },
    {
      "x": -7,
      "y": 2,
      "z": 7,
      "name": "Ore_Cobalt_Slate_Cracked"
    },
    {
      "x": -7,
      "y": 3,
      "z": 7,
      "name": "Ore_Cobalt_Slate_Cracked"
    },
    {
      "x": -7,
      "y": 4,
      "z": 7,
      "name": "Ore_Cobalt_Slate_Cracked"
    },
    {
      "x": -7,
      "y": 5,
      "z": 7,
      "name": "Ore_Cobalt_Slate_Cracked"
    },
    {
      "x": -7,
      "y": -1,
      "z": 8,
      "name": "Rock_Stone_Mossy"
    },
    {
      "x": -7,
      "y": 0,
      "z": 8,
      "name": "Rock_Stone_Mossy"
    },
    {
      "x": -6,
      "y": -1,
      "z": -1,
      "name": "Rock_Basalt_Cobble"
    },
    {
      "x": -6,
      "y": 2,
      "z": -1,
      "name": "Ore_Cobalt_Slate_Cracked"
    },
    {
      "x": -6,
      "y": -1,
      "z": 0,
      "name": "Rock_Basalt_Cobble"
    },
    {
      "x": -6,
      "y": 2,
      "z": 0,
      "name": "Ore_Cobalt_Slate_Cracked"
    },
    {
      "x": -6,
      "y": -1,
      "z": 1,
      "name": "Rock_Basalt_Cobble"
    },
    {
      "x": -6,
      "y": 2,
      "z": 1,
      "name": "Rock_Slate_Cobble"
    },
    {
      "x": -6,
      "y": -1,
      "z": 2,
      "name": "Rock_Basalt_Cobble"
    },
    {
      "x": -6,
      "y": 2,
      "z": 2,
      "name": "Rock_Slate"
    },
    {
      "x": -6,
      "y": -1,
      "z": 3,
      "name": "Rock_Basalt_Cobble"
    },
    {
      "x": -6,
      "y": 2,
      "z": 3,
      "name": "Rock_Slate"
    },
    {
      "x": -6,
      "y": -1,
      "z": 4,
      "name": "Rock_Basalt_Cobble"
    },
    {
      "x": -6,
      "y": 2,
      "z": 4,
      "name": "Rock_Slate"
    },
    {
      "x": -6,
      "y": -1,
      "z": 5,
      "name": "Rock_Basalt_Cobble"
    },
    {
      "x": -6,
      "y": 2,
      "z": 5,
      "name": "Ore_Cobalt_Slate_Cracked"
    },
    {
      "x": -6,
      "y": -1,
      "z": 6,
      "name": "Rock_Basalt_Cobble"
    },
    {
      "x": -6,
      "y": 2,
      "z": 6,
      "name": "Ore_Cobalt_Slate_Cracked"
    },
    {
      "x": -6,
      "y": -1,
      "z": 7,
      "name": "Rock_Basalt_Cobble"
    },
    {
      "x": -6,
      "y": 2,
      "z": 7,
      "name": "Rock_Slate_Cobble"
    },
    {
      "x": -6,
      "y": 3,
      "z": 7,
      "name": "Rock_Crystal_Yellow_Large"
    },
    {
      "x": -6,
      "y": -1,
      "z": 8,
      "name": "Rock_Basalt_Cobble"
    },
    {
      "x": -6,
      "y": 0,
      "z": 8,
      "name": "Rock_Basalt_Brick_Decorative"
    },
    {
      "x": -6,
      "y": 1,
      "z": 8,
      "name": "Soil_Clay_Black"
    },
    {
      "x": -6,
      "y": 2,
      "z": 8,
      "name": "Ore_Cobalt_Slate_Cracked"
    },
    {
      "x": -6,
      "y": 3,
      "z": 8,
      "name": "Ore_Cobalt_Slate_Cracked"
    },
    {
      "x": -6,
      "y": 4,
      "z": 8,
      "name": "Rock_Slate_Cobble"
    },
    {
      "x": -6,
      "y": 5,
      "z": 8,
      "name": "Rock_Slate_Cobble"
    },
    {
      "x": -6,
      "y": -1,
      "z": 9,
      "name": "Rock_Stone_Mossy"
    },
    {
      "x": -6,
      "y": 0,
      "z": 9,
      "name": "Rock_Stone_Mossy"
    },
    {
      "x": -6,
      "y": 1,
      "z": 9,
      "name": "Plant_Moss_Block_Green",
      "support": 15
    },
    {
      "x": -5,
      "y": -1,
      "z": -1,
      "name": "Rock_Basalt_Cobble"
    },
    {
      "x": -5,
      "y": 2,
      "z": -1,
      "name": "Rock_Slate"
    },
    {
      "x": -5,
      "y": -1,
      "z": 0,
      "name": "Rock_Basalt_Cobble"
    },
    {
      "x": -5,
      "y": 2,
      "z": 0,
      "name": "Rock_Slate"
    },
    {
      "x": -5,
      "y": -1,
      "z": 1,
      "name": "Rock_Basalt_Cobble"
    },
    {
      "x": -5,
      "y": 2,
      "z": 1,
      "name": "Ore_Cobalt_Slate_Cracked"
    },
    {
      "x": -5,
      "y": -1,
      "z": 2,
      "name": "Rock_Basalt_Cobble"
    },
    {
      "x": -5,
      "y": 2,
      "z": 2,
      "name": "Rock_Slate"
    },
    {
      "x": -5,
      "y": -1,
      "z": 3,
      "name": "Rock_Basalt_Cobble"
    },
    {
      "x": -5,
      "y": 2,
      "z": 3,
      "name": "Rock_Slate"
    },
    {
      "x": -5,
      "y": -1,
      "z": 4,
      "name": "Rock_Basalt_Cobble"
    },
    {
      "x": -5,
      "y": 2,
      "z": 4,
      "name": "Rock_Slate"
    },
    {
      "x": -5,
      "y": -1,
      "z": 5,
      "name": "Rock_Basalt_Cobble"
    },
    {
      "x": -5,
      "y": 2,
      "z": 5,
      "name": "Ore_Cobalt_Slate_Cracked"
    },
    {
      "x": -5,
      "y": -1,
      "z": 6,
      "name": "Rock_Basalt_Cobble"
    },
    {
      "x": -5,
      "y": 2,
      "z": 6,
      "name": "Ore_Cobalt_Slate_Cracked"
    },
    {
      "x": -5,
      "y": -1,
      "z": 7,
      "name": "Rock_Basalt_Cobble"
    },
    {
      "x": -5,
      "y": 2,
      "z": 7,
      "name": "Rock_Slate_Cobble"
    },
    {
      "x": -5,
      "y": -1,
      "z": 8,
      "name": "Rock_Basalt_Cobble"
    },
    {
      "x": -5,
      "y": 2,
      "z": 8,
      "name": "Rock_Slate"
    },
    {
      "x": -5,
      "y": 3,
      "z": 8,
      "name": "Rock_Slate"
    },
    {
      "x": -5,
      "y": 4,
      "z": 8,
      "name": "Rock_Slate"
    },
    {
      "x": -5,
      "y": 5,
      "z": 8,
      "name": "Rock_Slate"
    },
    {
      "x": -5,
      "y": -1,
      "z": 9,
      "name": "Rock_Basalt_Cobble"
    },
    {
      "x": -5,
      "y": 0,
      "z": 9,
      "name": "Rock_Basalt_Brick_Decorative"
    },
    {
      "x": -5,
      "y": 1,
      "z": 9,
      "name": "Soil_Clay_Black"
    },
    {
      "x": -5,
      "y": 2,
      "z": 9,
      "name": "Rock_Sandstone_Red_Brick_Pillar_Base"
    },
    {
      "x": -5,
      "y": 3,
      "z": 9,
      "name": "Rock_Sandstone_Red_Brick_Pillar_Middle"
    },
    {
      "x": -5,
      "y": 4,
      "z": 9,
      "name": "Rock_Sandstone_Red_Brick_Pillar_Middle"
    },
    {
      "x": -5,
      "y": 5,
      "z": 9,
      "name": "Rock_Sandstone_Red_Brick_Pillar_Middle"
    },
    {
      "x": -4,
      "y": -1,
      "z": -1,
      "name": "Rock_Basalt_Cobble"
    },
    {
      "x": -4,
      "y": 2,
      "z": -1,
      "name": "Rock_Slate"
    },
    {
      "x": -4,
      "y": -1,
      "z": 0,
      "name": "Rock_Basalt_Cobble"
    },
    {
      "x": -4,
      "y": 2,
      "z": 0,
      "name": "Rock_Slate"
    },
    {
      "x": -4,
      "y": -1,
      "z": 1,
      "name": "Rock_Basalt_Cobble"
    },
    {
      "x": -4,
      "y": 2,
      "z": 1,
      "name": "Rock_Slate"
    },
    {
      "x": -4,
      "y": -1,
      "z": 2,
      "name": "Rock_Basalt_Cobble"
    },
    {
      "x": -4,
      "y": 2,
      "z": 2,
      "name": "Rock_Slate"
    },
    {
      "x": -4,
      "y": -1,
      "z": 3,
      "name": "Rock_Basalt_Cobble"
    },
    {
      "x": -4,
      "y": 2,
      "z": 3,
      "name": "Ore_Cobalt_Slate_Cracked"
    },
    {
      "x": -4,
      "y": -1,
      "z": 4,
      "name": "Rock_Basalt_Cobble"
    },
    {
      "x": -4,
      "y": 2,
      "z": 4,
      "name": "Ore_Cobalt_Slate_Cracked"
    },
    {
      "x": -4,
      "y": -1,
      "z": 5,
      "name": "Rock_Basalt_Cobble"
    },
    {
      "x": -4,
      "y": 2,
      "z": 5,
      "name": "Ore_Cobalt_Slate_Cracked"
    },
    {
      "x": -4,
      "y": -1,
      "z": 6,
      "name": "Rock_Basalt_Cobble"
    },
    {
      "x": -4,
      "y": 0,
      "z": 6,
      "name": "Rock_Slate"
    },
    {
      "x": -4,
      "y": 2,
      "z": 6,
      "name": "Rock_Slate_Cobble"
    },
    {
      "x": -4,
      "y": -1,
      "z": 7,
      "name": "Rock_Basalt_Cobble"
    },
    {
      "x": -4,
      "y": 0,
      "z": 7,
      "name": "Rock_Slate"
    },
    {
      "x": -4,
      "y": 2,
      "z": 7,
      "name": "Rock_Slate_Cobble"
    },
    {
      "x": -4,
      "y": -1,
      "z": 8,
      "name": "Rock_Basalt_Cobble"
    },
    {
      "x": -4,
      "y": 2,
      "z": 8,
      "name": "Rock_Slate"
    },
    {
      "x": -4,
      "y": 3,
      "z": 8,
      "name": "Rock_Slate"
    },
    {
      "x": -4,
      "y": 4,
      "z": 8,
      "name": "Rock_Slate"
    },
    {
      "x": -4,
      "y": 5,
      "z": 8,
      "name": "Rock_Slate_Cobble"
    },
    {
      "x": -4,
      "y": -1,
      "z": 9,
      "name": "Rock_Basalt_Cobble"
    },
    {
      "x": -4,
      "y": 0,
      "z": 9,
      "name": "Rock_Basalt_Brick_Decorative"
    },
    {
      "x": -4,
      "y": 1,
      "z": 9,
      "name": "Soil_Clay_Black"
    },
    {
      "x": -4,
      "y": 2,
      "z": 9,
      "name": "Rock_Sandstone_Red_Brick_Pillar_Base"
    },
    {
      "x": -4,
      "y": 3,
      "z": 9,
      "name": "Rock_Sandstone_Red_Brick_Pillar_Middle"
    },
    {
      "x": -4,
      "y": 4,
      "z": 9,
      "name": "Rock_Sandstone_Red_Brick_Pillar_Middle"
    },
    {
      "x": -4,
      "y": -1,
      "z": 10,
      "name": "Plant_Moss_Block_Green",
      "support": 15
    },
    {
      "x": -3,
      "y": -1,
      "z": -1,
      "name": "Rock_Basalt_Cobble"
    },
    {
      "x": -3,
      "y": 2,
      "z": -1,
      "name": "Rock_Slate"
    },
    {
      "x": -3,
      "y": 3,
      "z": -1,
      "name": "Furniture_Human_Ruins_Bench",
      "rotation": 2
    },
    {
      "x": -3,
      "y": 4,
      "z": -1,
      "name": "Furniture_Human_Ruins_Bench",
      "filler": 1024,
      "rotation": 2
    },
    {
      "x": -3,
      "y": -1,
      "z": 0,
      "name": "Rock_Basalt_Cobble"
    },
    {
      "x": -3,
      "y": 2,
      "z": 0,
      "name": "Rock_Slate"
    },
    {
      "x": -3,
      "y": -1,
      "z": 1,
      "name": "Rock_Basalt_Cobble"
    },
    {
      "x": -3,
      "y": 2,
      "z": 1,
      "name": "Rock_Slate"
    },
    {
      "x": -3,
      "y": -1,
      "z": 2,
      "name": "Rock_Basalt_Cobble"
    },
    {
      "x": -3,
      "y": 2,
      "z": 2,
      "name": "Rock_Slate"
    },
    {
      "x": -3,
      "y": 3,
      "z": 2,
      "name": "Furniture_Human_Ruins_Bench",
      "rotation": 2
    },
    {
      "x": -3,
      "y": 4,
      "z": 2,
      "name": "Furniture_Human_Ruins_Bench",
      "filler": 1024,
      "rotation": 2
    },
    {
      "x": -3,
      "y": -1,
      "z": 3,
      "name": "Rock_Basalt_Cobble"
    },
    {
      "x": -3,
      "y": 2,
      "z": 3,
      "name": "Ore_Cobalt_Slate_Cracked"
    },
    {
      "x": -3,
      "y": -1,
      "z": 4,
      "name": "Rock_Basalt_Cobble"
    },
    {
      "x": -3,
      "y": 2,
      "z": 4,
      "name": "Ore_Cobalt_Slate_Cracked"
    },
    {
      "x": -3,
      "y": -1,
      "z": 5,
      "name": "Rock_Basalt_Cobble"
    },
    {
      "x": -3,
      "y": 2,
      "z": 5,
      "name": "Rock_Slate_Cobble"
    },
    {
      "x": -3,
      "y": 3,
      "z": 5,
      "name": "Furniture_Human_Ruins_Bench",
      "rotation": 2
    },
    {
      "x": -3,
      "y": 4,
      "z": 5,
      "name": "Furniture_Human_Ruins_Bench",
      "filler": 1024,
      "rotation": 2
    },
    {
      "x": -3,
      "y": -1,
      "z": 6,
      "name": "Rock_Basalt_Cobble"
    },
    {
      "x": -3,
      "y": 2,
      "z": 6,
      "name": "Rock_Slate_Cobble"
    },
    {
      "x": -3,
      "y": -1,
      "z": 7,
      "name": "Rock_Basalt_Cobble"
    },
    {
      "x": -3,
      "y": 2,
      "z": 7,
      "name": "Rock_Slate_Cobble"
    },
    {
      "x": -3,
      "y": -1,
      "z": 8,
      "name": "Rock_Basalt_Cobble"
    },
    {
      "x": -3,
      "y": 2,
      "z": 8,
      "name": "Rock_Slate"
    },
    {
      "x": -3,
      "y": 3,
      "z": 8,
      "name": "Rock_Slate"
    },
    {
      "x": -3,
      "y": 4,
      "z": 8,
      "name": "Rock_Slate"
    },
    {
      "x": -3,
      "y": 5,
      "z": 8,
      "name": "Rock_Slate"
    },
    {
      "x": -3,
      "y": -1,
      "z": 9,
      "name": "Rock_Basalt_Cobble"
    },
    {
      "x": -3,
      "y": 2,
      "z": 9,
      "name": "Rock_Slate"
    },
    {
      "x": -3,
      "y": 3,
      "z": 9,
      "name": "Rock_Basalt_Brick_Smooth"
    },
    {
      "x": -3,
      "y": 4,
      "z": 9,
      "name": "Rock_Basalt_Brick_Smooth"
    },
    {
      "x": -3,
      "y": 5,
      "z": 9,
      "name": "Rock_Basalt_Brick_Smooth"
    },
    {
      "x": -3,
      "y": -1,
      "z": 10,
      "name": "Soil_Clay_Black"
    },
    {
      "x": -3,
      "y": 0,
      "z": 10,
      "name": "Soil_Clay_Black"
    },
    {
      "x": -3,
      "y": 1,
      "z": 10,
      "name": "Soil_Clay_Black"
    },
    {
      "x": -3,
      "y": 2,
      "z": 10,
      "name": "Rock_Basalt_Brick_Pillar_Base"
    },
    {
      "x": -3,
      "y": 3,
      "z": 10,
      "name": "Rock_Basalt_Brick_Pillar_Middle"
    },
    {
      "x": -3,
      "y": 4,
      "z": 10,
      "name": "Rock_Basalt_Brick_Pillar_Middle"
    },
    {
      "x": -3,
      "y": 5,
      "z": 10,
      "name": "Rock_Basalt_Brick_Pillar_Middle"
    },
    {
      "x": -2,
      "y": -1,
      "z": -1,
      "name": "Rock_Basalt_Cobble"
    },
    {
      "x": -2,
      "y": 2,
      "z": -1,
      "name": "Rock_Slate"
    },
    {
      "x": -2,
      "y": 3,
      "z": -1,
      "name": "Furniture_Human_Ruins_Bench",
      "filler": 1,
      "rotation": 2
    },
    {
      "x": -2,
      "y": 4,
      "z": -1,
      "name": "Furniture_Human_Ruins_Bench",
      "filler": 1025,
      "rotation": 2
    },
    {
      "x": -2,
      "y": -1,
      "z": 0,
      "name": "Rock_Basalt_Cobble"
    },
    {
      "x": -2,
      "y": 2,
      "z": 0,
      "name": "Rock_Slate"
    },
    {
      "x": -2,
      "y": -1,
      "z": 1,
      "name": "Rock_Basalt_Cobble"
    },
    {
      "x": -2,
      "y": 2,
      "z": 1,
      "name": "Rock_Slate"
    },
    {
      "x": -2,
      "y": -1,
      "z": 2,
      "name": "Rock_Basalt_Cobble"
    },
    {
      "x": -2,
      "y": 2,
      "z": 2,
      "name": "Ore_Cobalt_Slate_Cracked"
    },
    {
      "x": -2,
      "y": 3,
      "z": 2,
      "name": "Furniture_Human_Ruins_Bench",
      "filler": 1,
      "rotation": 2
    },
    {
      "x": -2,
      "y": 4,
      "z": 2,
      "name": "Furniture_Human_Ruins_Bench",
      "filler": 1025,
      "rotation": 2
    },
    {
      "x": -2,
      "y": -1,
      "z": 3,
      "name": "Rock_Basalt_Cobble"
    },
    {
      "x": -2,
      "y": 2,
      "z": 3,
      "name": "Ore_Cobalt_Slate_Cracked"
    },
    {
      "x": -2,
      "y": -1,
      "z": 4,
      "name": "Rock_Basalt_Cobble"
    },
    {
      "x": -2,
      "y": 2,
      "z": 4,
      "name": "Rock_Slate"
    },
    {
      "x": -2,
      "y": -1,
      "z": 5,
      "name": "Rock_Basalt_Cobble"
    },
    {
      "x": -2,
      "y": 2,
      "z": 5,
      "name": "Rock_Slate_Cobble"
    },
    {
      "x": -2,
      "y": 3,
      "z": 5,
      "name": "Furniture_Human_Ruins_Bench",
      "filler": 1,
      "rotation": 2
    },
    {
      "x": -2,
      "y": 4,
      "z": 5,
      "name": "Furniture_Human_Ruins_Bench",
      "filler": 1025,
      "rotation": 2
    },
    {
      "x": -2,
      "y": -1,
      "z": 6,
      "name": "Rock_Basalt_Cobble"
    },
    {
      "x": -2,
      "y": 2,
      "z": 6,
      "name": "Rock_Slate_Cobble"
    },
    {
      "x": -2,
      "y": -1,
      "z": 7,
      "name": "Rock_Basalt_Cobble"
    },
    {
      "x": -2,
      "y": 2,
      "z": 7,
      "name": "Rock_Slate_Cobble"
    },
    {
      "x": -2,
      "y": -1,
      "z": 8,
      "name": "Rock_Basalt_Cobble"
    },
    {
      "x": -2,
      "y": 2,
      "z": 8,
      "name": "Rock_Slate"
    },
    {
      "x": -2,
      "y": -1,
      "z": 9,
      "name": "Rock_Basalt_Cobble"
    },
    {
      "x": -2,
      "y": 2,
      "z": 9,
      "name": "Soil_Clay_Black"
    },
    {
      "x": -2,
      "y": -1,
      "z": 10,
      "name": "Rock_Basalt_Cobble"
    },
    {
      "x": -2,
      "y": 2,
      "z": 10,
      "name": "Soil_Clay_Black"
    },
    {
      "x": -2,
      "y": -1,
      "z": 11,
      "name": "Soil_Clay_Black"
    },
    {
      "x": -2,
      "y": 0,
      "z": 11,
      "name": "Soil_Clay_Black"
    },
    {
      "x": -2,
      "y": 1,
      "z": 11,
      "name": "Soil_Clay_Black"
    },
    {
      "x": -2,
      "y": -1,
      "z": 12,
      "name": "Soil_Clay_Black"
    },
    {
      "x": -2,
      "y": 0,
      "z": 12,
      "name": "Soil_Clay_Black"
    },
    {
      "x": -2,
      "y": 1,
      "z": 12,
      "name": "Soil_Clay_Black"
    },
    {
      "x": -2,
      "y": -1,
      "z": 13,
      "name": "Soil_Clay_Black"
    },
    {
      "x": -2,
      "y": 0,
      "z": 13,
      "name": "Soil_Clay_Black"
    },
    {
      "x": -2,
      "y": -1,
      "z": 14,
      "name": "Soil_Clay_Black"
    },
    {
      "x": -2,
      "y": 0,
      "z": 14,
      "name": "Soil_Clay_Black"
    },
    {
      "x": -2,
      "y": -1,
      "z": 15,
      "name": "Soil_Clay_Black"
    },
    {
      "x": -2,
      "y": -1,
      "z": 16,
      "name": "Soil_Clay_Black"
    },
    {
      "x": -2,
      "y": -1,
      "z": 17,
      "name": "Soil_Clay_Black"
    },
    {
      "x": -1,
      "y": -1,
      "z": -1,
      "name": "Rock_Basalt_Cobble"
    },
    {
      "x": -1,
      "y": 2,
      "z": -1,
      "name": "Rock_Slate"
    },
    {
      "x": -1,
      "y": -1,
      "z": 0,
      "name": "Rock_Basalt_Cobble"
    },
    {
      "x": -1,
      "y": 2,
      "z": 0,
      "name": "Rock_Slate"
    },
    {
      "x": -1,
      "y": -1,
      "z": 1,
      "name": "Rock_Basalt_Cobble"
    },
    {
      "x": -1,
      "y": 2,
      "z": 1,
      "name": "Ore_Cobalt_Slate_Cracked"
    },
    {
      "x": -1,
      "y": -1,
      "z": 2,
      "name": "Rock_Basalt_Cobble"
    },
    {
      "x": -1,
      "y": 2,
      "z": 2,
      "name": "Rock_Slate"
    },
    {
      "x": -1,
      "y": -1,
      "z": 3,
      "name": "Rock_Basalt_Cobble"
    },
    {
      "x": -1,
      "y": -1,
      "z": 4,
      "name": "Rock_Basalt_Cobble"
    },
    {
      "x": -1,
      "y": 2,
      "z": 4,
      "name": "Rock_Slate"
    },
    {
      "x": -1,
      "y": -1,
      "z": 5,
      "name": "Rock_Basalt_Cobble"
    },
    {
      "x": -1,
      "y": 2,
      "z": 5,
      "name": "Rock_Slate"
    },
    {
      "x": -1,
      "y": -1,
      "z": 6,
      "name": "Rock_Basalt_Cobble"
    },
    {
      "x": -1,
      "y": 2,
      "z": 6,
      "name": "Rock_Slate"
    },
    {
      "x": -1,
      "y": -1,
      "z": 7,
      "name": "Rock_Basalt_Cobble"
    },
    {
      "x": -1,
      "y": 2,
      "z": 7,
      "name": "Rock_Slate_Cobble"
    },
    {
      "x": -1,
      "y": -1,
      "z": 8,
      "name": "Rock_Basalt_Cobble"
    },
    {
      "x": -1,
      "y": 2,
      "z": 8,
      "name": "Rock_Slate"
    },
    {
      "x": -1,
      "y": -1,
      "z": 9,
      "name": "Rock_Basalt_Cobble"
    },
    {
      "x": -1,
      "y": 2,
      "z": 9,
      "name": "Rock_Slate"
    },
    {
      "x": -1,
      "y": -1,
      "z": 10,
      "name": "Rock_Basalt_Cobble"
    },
    {
      "x": -1,
      "y": 2,
      "z": 10,
      "name": "Rock_Slate_Cobble_Half"
    },
    {
      "x": -1,
      "y": 1,
      "z": 11,
      "name": "Rock_Slate"
    },
    {
      "x": -1,
      "y": 1,
      "z": 12,
      "name": "Rock_Slate_Cobble_Half"
    },
    {
      "x": -1,
      "y": 0,
      "z": 13,
      "name": "Rock_Slate"
    },
    {
      "x": -1,
      "y": -1,
      "z": 14,
      "name": "Rock_Slate"
    },
    {
      "x": -1,
      "y": 0,
      "z": 14,
      "name": "Rock_Slate_Cobble_Half"
    },
    {
      "x": -1,
      "y": -1,
      "z": 15,
      "name": "Rock_Slate"
    },
    {
      "x": -1,
      "y": 0,
      "z": 15,
      "name": "Rock_Slate_Cobble_Half"
    },
    {
      "x": -1,
      "y": -1,
      "z": 16,
      "name": "Rock_Slate"
    },
    {
      "x": -1,
      "y": -1,
      "z": 17,
      "name": "Rock_Slate"
    },
    {
      "x": -1,
      "y": -1,
      "z": 18,
      "name": "Rock_Slate"
    },
    {
      "x": -1,
      "y": -1,
      "z": 19,
      "name": "Rock_Slate_Cobble_Half"
    },
    {
      "x": -1,
      "y": -1,
      "z": 20,
      "name": "Rock_Slate"
    },
    {
      "x": 0,
      "y": -1,
      "z": -1,
      "name": "Rock_Basalt_Cobble"
    },
    {
      "x": 0,
      "y": 2,
      "z": -1,
      "name": "Rock_Slate"
    },
    {
      "x": 0,
      "y": -1,
      "z": 0,
      "name": "Rock_Basalt_Cobble"
    },
    {
      "x": 0,
      "y": 2,
      "z": 0,
      "name": "Rock_Slate"
    },
    {
      "x": 0,
      "y": -1,
      "z": 1,
      "name": "Rock_Basalt_Cobble"
    },
    {
      "x": 0,
      "y": -1,
      "z": 2,
      "name": "Rock_Basalt_Cobble"
    },
    {
      "x": 0,
      "y": -1,
      "z": 3,
      "name": "Rock_Basalt_Cobble"
    },
    {
      "x": 0,
      "y": -1,
      "z": 4,
      "name": "Rock_Basalt_Cobble"
    },
    {
      "x": 0,
      "y": 2,
      "z": 4,
      "name": "Rock_Slate"
    },
    {
      "x": 0,
      "y": -1,
      "z": 5,
      "name": "Rock_Basalt_Cobble"
    },
    {
      "x": 0,
      "y": 2,
      "z": 5,
      "name": "Rock_Slate"
    },
    {
      "x": 0,
      "y": -1,
      "z": 6,
      "name": "Rock_Basalt_Cobble"
    },
    {
      "x": 0,
      "y": 2,
      "z": 6,
      "name": "Rock_Slate"
    },
    {
      "x": 0,
      "y": -1,
      "z": 7,
      "name": "Rock_Basalt_Cobble"
    },
    {
      "x": 0,
      "y": 2,
      "z": 7,
      "name": "Rock_Slate"
    },
    {
      "x": 0,
      "y": -1,
      "z": 8,
      "name": "Rock_Basalt_Cobble"
    },
    {
      "x": 0,
      "y": 2,
      "z": 8,
      "name": "Rock_Slate"
    },
    {
      "x": 0,
      "y": -1,
      "z": 9,
      "name": "Rock_Basalt_Cobble"
    },
    {
      "x": 0,
      "y": 2,
      "z": 9,
      "name": "Rock_Slate"
    },
    {
      "x": 0,
      "y": -1,
      "z": 10,
      "name": "Rock_Basalt_Cobble"
    },
    {
      "x": 0,
      "y": 2,
      "z": 10,
      "name": "Rock_Slate"
    },
    {
      "x": 0,
      "y": 1,
      "z": 11,
      "name": "Rock_Slate"
    },
    {
      "x": 0,
      "y": 1,
      "z": 12,
      "name": "Rock_Slate_Cobble_Half"
    },
    {
      "x": 0,
      "y": 0,
      "z": 13,
      "name": "Rock_Slate"
    },
    {
      "x": 0,
      "y": -1,
      "z": 14,
      "name": "Rock_Slate"
    },
    {
      "x": 0,
      "y": 0,
      "z": 14,
      "name": "Rock_Slate_Cobble_Half"
    },
    {
      "x": 0,
      "y": -1,
      "z": 15,
      "name": "Rock_Slate"
    },
    {
      "x": 0,
      "y": 0,
      "z": 15,
      "name": "Rock_Slate_Cobble_Half"
    },
    {
      "x": 0,
      "y": -1,
      "z": 16,
      "name": "Rock_Slate"
    },
    {
      "x": 0,
      "y": -1,
      "z": 17,
      "name": "Rock_Slate"
    },
    {
      "x": 0,
      "y": -1,
      "z": 18,
      "name": "Rock_Slate"
    },
    {
      "x": 0,
      "y": 0,
      "z": 18,
      "name": "Soil_Clay_Black"
    },
    {
      "x": 0,
      "y": 1,
      "z": 18,
      "name": "Furniture_Human_Ruins_Statue_Broken"
    },
    {
      "x": 0,
      "y": 2,
      "z": 18,
      "name": "Furniture_Human_Ruins_Statue_Broken",
      "filler": 1024
    },
    {
      "x": 0,
      "y": 3,
      "z": 18,
      "name": "Furniture_Human_Ruins_Statue_Broken",
      "filler": 2048
    },
    {
      "x": 0,
      "y": -1,
      "z": 19,
      "name": "Rock_Slate"
    },
    {
      "x": 0,
      "y": -1,
      "z": 20,
      "name": "Rock_Slate"
    },
    {
      "x": 0,
      "y": 0,
      "z": 20,
      "name": "Furniture_Human_Ruins_Brazier"
    },
    {
      "x": 0,
      "y": -1,
      "z": 21,
      "name": "Rock_Slate_Cobble_Half"
    },
    {
      "x": 1,
      "y": -1,
      "z": -1,
      "name": "Rock_Basalt_Cobble"
    },
    {
      "x": 1,
      "y": 2,
      "z": -1,
      "name": "Rock_Slate"
    },
    {
      "x": 1,
      "y": -1,
      "z": 0,
      "name": "Rock_Basalt_Cobble"
    },
    {
      "x": 1,
      "y": 2,
      "z": 0,
      "name": "Rock_Slate"
    },
    {
      "x": 1,
      "y": -1,
      "z": 1,
      "name": "Rock_Basalt_Cobble"
    },
    {
      "x": 1,
      "y": 2,
      "z": 1,
      "name": "Rock_Slate"
    },
    {
      "x": 1,
      "y": -1,
      "z": 2,
      "name": "Rock_Basalt_Cobble"
    },
    {
      "x": 1,
      "y": -1,
      "z": 3,
      "name": "Rock_Basalt_Cobble"
    },
    {
      "x": 1,
      "y": 2,
      "z": 3,
      "name": "Rock_Slate_Cobble"
    },
    {
      "x": 1,
      "y": -1,
      "z": 4,
      "name": "Rock_Basalt_Cobble"
    },
    {
      "x": 1,
      "y": 0,
      "z": 4,
      "name": "Rock_Slate"
    },
    {
      "x": 1,
      "y": 2,
      "z": 4,
      "name": "Rock_Slate_Cobble"
    },
    {
      "x": 1,
      "y": -1,
      "z": 5,
      "name": "Rock_Basalt_Cobble"
    },
    {
      "x": 1,
      "y": 2,
      "z": 5,
      "name": "Rock_Slate"
    },
    {
      "x": 1,
      "y": -1,
      "z": 6,
      "name": "Rock_Basalt_Cobble"
    },
    {
      "x": 1,
      "y": 2,
      "z": 6,
      "name": "Rock_Slate"
    },
    {
      "x": 1,
      "y": -1,
      "z": 7,
      "name": "Rock_Basalt_Cobble"
    },
    {
      "x": 1,
      "y": 2,
      "z": 7,
      "name": "Rock_Slate"
    },
    {
      "x": 1,
      "y": -1,
      "z": 8,
      "name": "Rock_Basalt_Cobble"
    },
    {
      "x": 1,
      "y": 2,
      "z": 8,
      "name": "Ore_Cobalt_Slate_Cracked"
    },
    {
      "x": 1,
      "y": -1,
      "z": 9,
      "name": "Rock_Basalt_Cobble"
    },
    {
      "x": 1,
      "y": 2,
      "z": 9,
      "name": "Rock_Slate"
    },
    {
      "x": 1,
      "y": -1,
      "z": 10,
      "name": "Rock_Basalt_Cobble"
    },
    {
      "x": 1,
      "y": 2,
      "z": 10,
      "name": "Rock_Slate_Cobble_Half"
    },
    {
      "x": 1,
      "y": 1,
      "z": 11,
      "name": "Rock_Slate"
    },
    {
      "x": 1,
      "y": 1,
      "z": 12,
      "name": "Rock_Slate_Cobble_Half"
    },
    {
      "x": 1,
      "y": 0,
      "z": 13,
      "name": "Rock_Slate"
    },
    {
      "x": 1,
      "y": -1,
      "z": 14,
      "name": "Rock_Slate"
    },
    {
      "x": 1,
      "y": 0,
      "z": 14,
      "name": "Rock_Slate_Cobble_Half"
    },
    {
      "x": 1,
      "y": -1,
      "z": 15,
      "name": "Rock_Slate"
    },
    {
      "x": 1,
      "y": 0,
      "z": 15,
      "name": "Rock_Slate_Cobble_Half"
    },
    {
      "x": 1,
      "y": -1,
      "z": 16,
      "name": "Rock_Slate"
    },
    {
      "x": 1,
      "y": 0,
      "z": 16,
      "name": "Rock_Slate_Cobble_Half"
    },
    {
      "x": 1,
      "y": -1,
      "z": 17,
      "name": "Rock_Slate"
    },
    {
      "x": 1,
      "y": -1,
      "z": 18,
      "name": "Rock_Slate"
    },
    {
      "x": 1,
      "y": -1,
      "z": 19,
      "name": "Rock_Slate"
    },
    {
      "x": 1,
      "y": -1,
      "z": 20,
      "name": "Rock_Slate"
    },
    {
      "x": 2,
      "y": -1,
      "z": -1,
      "name": "Rock_Basalt_Cobble"
    },
    {
      "x": 2,
      "y": 2,
      "z": -1,
      "name": "Rock_Slate"
    },
    {
      "x": 2,
      "y": 3,
      "z": -1,
      "name": "Furniture_Human_Ruins_Bench",
      "rotation": 2
    },
    {
      "x": 2,
      "y": 4,
      "z": -1,
      "name": "Furniture_Human_Ruins_Bench",
      "filler": 1024,
      "rotation": 2
    },
    {
      "x": 2,
      "y": -1,
      "z": 0,
      "name": "Rock_Basalt_Cobble"
    },
    {
      "x": 2,
      "y": 2,
      "z": 0,
      "name": "Rock_Slate"
    },
    {
      "x": 2,
      "y": -1,
      "z": 1,
      "name": "Rock_Basalt_Cobble"
    },
    {
      "x": 2,
      "y": 2,
      "z": 1,
      "name": "Rock_Slate"
    },
    {
      "x": 2,
      "y": -1,
      "z": 2,
      "name": "Rock_Basalt_Cobble"
    },
    {
      "x": 2,
      "y": 2,
      "z": 2,
      "name": "Rock_Slate"
    },
    {
      "x": 2,
      "y": 3,
      "z": 2,
      "name": "Furniture_Human_Ruins_Bench",
      "rotation": 2
    },
    {
      "x": 2,
      "y": 4,
      "z": 2,
      "name": "Furniture_Human_Ruins_Bench",
      "filler": 1024,
      "rotation": 2
    },
    {
      "x": 2,
      "y": -1,
      "z": 3,
      "name": "Rock_Basalt_Cobble"
    },
    {
      "x": 2,
      "y": 2,
      "z": 3,
      "name": "Rock_Slate"
    },
    {
      "x": 2,
      "y": -1,
      "z": 4,
      "name": "Rock_Basalt_Cobble"
    },
    {
      "x": 2,
      "y": 2,
      "z": 4,
      "name": "Rock_Slate_Cobble"
    },
    {
      "x": 2,
      "y": -1,
      "z": 5,
      "name": "Rock_Basalt_Cobble"
    },
    {
      "x": 2,
      "y": 2,
      "z": 5,
      "name": "Rock_Slate_Cobble"
    },
    {
      "x": 2,
      "y": 3,
      "z": 5,
      "name": "Furniture_Human_Ruins_Bench",
      "rotation": 2
    },
    {
      "x": 2,
      "y": 4,
      "z": 5,
      "name": "Furniture_Human_Ruins_Bench",
      "filler": 1024,
      "rotation": 2
    },
    {
      "x": 2,
      "y": -1,
      "z": 6,
      "name": "Rock_Basalt_Cobble"
    },
    {
      "x": 2,
      "y": 2,
      "z": 6,
      "name": "Rock_Slate"
    },
    {
      "x": 2,
      "y": -1,
      "z": 7,
      "name": "Rock_Basalt_Cobble"
    },
    {
      "x": 2,
      "y": 2,
      "z": 7,
      "name": "Ore_Cobalt_Slate_Cracked"
    },
    {
      "x": 2,
      "y": -1,
      "z": 8,
      "name": "Rock_Basalt_Cobble"
    },
    {
      "x": 2,
      "y": 0,
      "z": 8,
      "name": "Rock_Slate_Cobble"
    },
    {
      "x": 2,
      "y": 1,
      "z": 8,
      "name": "Rock_Slate_Cobble"
    },
    {
      "x": 2,
      "y": 2,
      "z": 8,
      "name": "Rock_Slate_Cobble"
    },
    {
      "x": 2,
      "y": -1,
      "z": 9,
      "name": "Rock_Basalt_Cobble"
    },
    {
      "x": 2,
      "y": 0,
      "z": 9,
      "name": "Rock_Slate_Cobble"
    },
    {
      "x": 2,
      "y": 1,
      "z": 9,
      "name": "Rock_Slate_Cobble"
    },
    {
      "x": 2,
      "y": 2,
      "z": 9,
      "name": "Soil_Clay_Black"
    },
    {
      "x": 2,
      "y": -1,
      "z": 10,
      "name": "Rock_Basalt_Cobble"
    },
    {
      "x": 2,
      "y": 2,
      "z": 10,
      "name": "Soil_Clay_Black"
    },
    {
      "x": 2,
      "y": -1,
      "z": 11,
      "name": "Soil_Clay_Black"
    },
    {
      "x": 2,
      "y": 0,
      "z": 11,
      "name": "Soil_Clay_Black"
    },
    {
      "x": 2,
      "y": 1,
      "z": 11,
      "name": "Soil_Clay_Black"
    },
    {
      "x": 2,
      "y": -1,
      "z": 12,
      "name": "Soil_Clay_Black"
    },
    {
      "x": 2,
      "y": 0,
      "z": 12,
      "name": "Soil_Clay_Black"
    },
    {
      "x": 2,
      "y": 1,
      "z": 12,
      "name": "Soil_Clay_Black"
    },
    {
      "x": 2,
      "y": -1,
      "z": 13,
      "name": "Soil_Clay_Black"
    },
    {
      "x": 2,
      "y": 0,
      "z": 13,
      "name": "Soil_Clay_Black"
    },
    {
      "x": 2,
      "y": -1,
      "z": 14,
      "name": "Soil_Clay_Black"
    },
    {
      "x": 2,
      "y": 0,
      "z": 14,
      "name": "Soil_Clay_Black"
    },
    {
      "x": 2,
      "y": -1,
      "z": 15,
      "name": "Soil_Clay_Black"
    },
    {
      "x": 2,
      "y": -1,
      "z": 16,
      "name": "Soil_Clay_Black"
    },
    {
      "x": 2,
      "y": -1,
      "z": 17,
      "name": "Soil_Clay_Black"
    },
    {
      "x": 2,
      "y": -1,
      "z": 18,
      "name": "Soil_Clay_Black"
    },
    {
      "x": 2,
      "y": -1,
      "z": 19,
      "name": "Soil_Clay_Black"
    },
    {
      "x": 2,
      "y": -1,
      "z": 20,
      "name": "Rock_Slate_Cobble_Half"
    },
    {
      "x": 3,
      "y": -1,
      "z": -1,
      "name": "Rock_Basalt_Cobble"
    },
    {
      "x": 3,
      "y": 2,
      "z": -1,
      "name": "Rock_Slate"
    },
    {
      "x": 3,
      "y": 3,
      "z": -1,
      "name": "Furniture_Human_Ruins_Bench",
      "filler": 1,
      "rotation": 2
    },
    {
      "x": 3,
      "y": 4,
      "z": -1,
      "name": "Furniture_Human_Ruins_Bench",
      "filler": 1025,
      "rotation": 2
    },
    {
      "x": 3,
      "y": -1,
      "z": 0,
      "name": "Rock_Basalt_Cobble"
    },
    {
      "x": 3,
      "y": 2,
      "z": 0,
      "name": "Rock_Slate"
    },
    {
      "x": 3,
      "y": -1,
      "z": 1,
      "name": "Rock_Basalt_Cobble"
    },
    {
      "x": 3,
      "y": 2,
      "z": 1,
      "name": "Rock_Slate"
    },
    {
      "x": 3,
      "y": -1,
      "z": 2,
      "name": "Rock_Basalt_Cobble"
    },
    {
      "x": 3,
      "y": 2,
      "z": 2,
      "name": "Rock_Slate"
    },
    {
      "x": 3,
      "y": 3,
      "z": 2,
      "name": "Furniture_Human_Ruins_Bench",
      "filler": 1,
      "rotation": 2
    },
    {
      "x": 3,
      "y": 4,
      "z": 2,
      "name": "Furniture_Human_Ruins_Bench",
      "filler": 1025,
      "rotation": 2
    },
    {
      "x": 3,
      "y": -1,
      "z": 3,
      "name": "Rock_Basalt_Cobble"
    },
    {
      "x": 3,
      "y": 2,
      "z": 3,
      "name": "Rock_Slate_Cobble"
    },
    {
      "x": 3,
      "y": -1,
      "z": 4,
      "name": "Rock_Basalt_Cobble"
    },
    {
      "x": 3,
      "y": 2,
      "z": 4,
      "name": "Rock_Slate_Cobble"
    },
    {
      "x": 3,
      "y": -1,
      "z": 5,
      "name": "Rock_Basalt_Cobble"
    },
    {
      "x": 3,
      "y": 2,
      "z": 5,
      "name": "Rock_Slate_Cobble"
    },
    {
      "x": 3,
      "y": 3,
      "z": 5,
      "name": "Furniture_Human_Ruins_Bench",
      "filler": 1,
      "rotation": 2
    },
    {
      "x": 3,
      "y": 4,
      "z": 5,
      "name": "Furniture_Human_Ruins_Bench",
      "filler": 1025,
      "rotation": 2
    },
    {
      "x": 3,
      "y": -1,
      "z": 6,
      "name": "Rock_Basalt_Cobble"
    },
    {
      "x": 3,
      "y": 2,
      "z": 6,
      "name": "Ore_Cobalt_Slate_Cracked"
    },
    {
      "x": 3,
      "y": -1,
      "z": 7,
      "name": "Rock_Basalt_Cobble"
    },
    {
      "x": 3,
      "y": 2,
      "z": 7,
      "name": "Ore_Cobalt_Slate_Cracked"
    },
    {
      "x": 3,
      "y": -1,
      "z": 8,
      "name": "Rock_Basalt_Cobble"
    },
    {
      "x": 3,
      "y": 0,
      "z": 8,
      "name": "Rock_Slate_Cobble"
    },
    {
      "x": 3,
      "y": 1,
      "z": 8,
      "name": "Rock_Slate_Cobble"
    },
    {
      "x": 3,
      "y": 2,
      "z": 8,
      "name": "Rock_Slate_Cobble"
    },
    {
      "x": 3,
      "y": 3,
      "z": 8,
      "name": "Rock_Slate_Cobble"
    },
    {
      "x": 3,
      "y": 4,
      "z": 8,
      "name": "Rock_Slate_Cobble"
    },
    {
      "x": 3,
      "y": 5,
      "z": 8,
      "name": "Rock_Slate_Cobble"
    },
    {
      "x": 3,
      "y": -1,
      "z": 9,
      "name": "Rock_Basalt_Cobble"
    },
    {
      "x": 3,
      "y": 0,
      "z": 9,
      "name": "Rock_Slate_Cobble"
    },
    {
      "x": 3,
      "y": 1,
      "z": 9,
      "name": "Rock_Slate_Cobble"
    },
    {
      "x": 3,
      "y": 2,
      "z": 9,
      "name": "Rock_Slate"
    },
    {
      "x": 3,
      "y": 3,
      "z": 9,
      "name": "Rock_Basalt_Brick_Smooth"
    },
    {
      "x": 3,
      "y": 4,
      "z": 9,
      "name": "Rock_Basalt_Brick_Smooth"
    },
    {
      "x": 3,
      "y": 5,
      "z": 9,
      "name": "Rock_Basalt_Brick_Smooth"
    },
    {
      "x": 3,
      "y": -1,
      "z": 10,
      "name": "Soil_Clay_Black"
    },
    {
      "x": 3,
      "y": 0,
      "z": 10,
      "name": "Soil_Clay_Black"
    },
    {
      "x": 3,
      "y": 1,
      "z": 10,
      "name": "Soil_Clay_Black"
    },
    {
      "x": 3,
      "y": 2,
      "z": 10,
      "name": "Rock_Basalt_Brick_Pillar_Base"
    },
    {
      "x": 3,
      "y": 3,
      "z": 10,
      "name": "Rock_Basalt_Brick_Pillar_Middle"
    },
    {
      "x": 3,
      "y": 4,
      "z": 10,
      "name": "Rock_Basalt_Brick_Pillar_Middle"
    },
    {
      "x": 3,
      "y": 5,
      "z": 10,
      "name": "Rock_Basalt_Brick_Pillar_Middle"
    },
    {
      "x": 3,
      "y": -1,
      "z": 11,
      "name": "Rock_Stone_Mossy"
    },
    {
      "x": 3,
      "y": 0,
      "z": 11,
      "name": "Plant_Moss_Block_Green",
      "support": 15
    },
    {
      "x": 4,
      "y": -1,
      "z": -1,
      "name": "Rock_Basalt_Cobble"
    },
    {
      "x": 4,
      "y": 2,
      "z": -1,
      "name": "Rock_Slate"
    },
    {
      "x": 4,
      "y": -1,
      "z": 0,
      "name": "Rock_Basalt_Cobble"
    },
    {
      "x": 4,
      "y": 2,
      "z": 0,
      "name": "Rock_Slate"
    },
    {
      "x": 4,
      "y": -1,
      "z": 1,
      "name": "Rock_Basalt_Cobble"
    },
    {
      "x": 4,
      "y": 2,
      "z": 1,
      "name": "Rock_Slate"
    },
    {
      "x": 4,
      "y": -1,
      "z": 2,
      "name": "Rock_Basalt_Cobble"
    },
    {
      "x": 4,
      "y": 2,
      "z": 2,
      "name": "Rock_Slate_Cobble"
    },
    {
      "x": 4,
      "y": -1,
      "z": 3,
      "name": "Rock_Basalt_Cobble"
    },
    {
      "x": 4,
      "y": 2,
      "z": 3,
      "name": "Rock_Slate_Cobble"
    },
    {
      "x": 4,
      "y": -1,
      "z": 4,
      "name": "Rock_Basalt_Cobble"
    },
    {
      "x": 4,
      "y": 2,
      "z": 4,
      "name": "Rock_Slate_Cobble"
    },
    {
      "x": 4,
      "y": -1,
      "z": 5,
      "name": "Rock_Basalt_Cobble"
    },
    {
      "x": 4,
      "y": 2,
      "z": 5,
      "name": "Ore_Cobalt_Slate_Cracked"
    },
    {
      "x": 4,
      "y": -1,
      "z": 6,
      "name": "Rock_Basalt_Cobble"
    },
    {
      "x": 4,
      "y": 2,
      "z": 6,
      "name": "Ore_Cobalt_Slate_Cracked"
    },
    {
      "x": 4,
      "y": -1,
      "z": 7,
      "name": "Rock_Basalt_Cobble"
    },
    {
      "x": 4,
      "y": 0,
      "z": 7,
      "name": "Rock_Slate_Cobble"
    },
    {
      "x": 4,
      "y": 2,
      "z": 7,
      "name": "Ore_Cobalt_Slate_Cracked"
    },
    {
      "x": 4,
      "y": -1,
      "z": 8,
      "name": "Rock_Basalt_Cobble"
    },
    {
      "x": 4,
      "y": 0,
      "z": 8,
      "name": "Rock_Slate_Cobble"
    },
    {
      "x": 4,
      "y": 1,
      "z": 8,
      "name": "Rock_Slate_Cobble"
    },
    {
      "x": 4,
      "y": 2,
      "z": 8,
      "name": "Rock_Slate_Cobble"
    },
    {
      "x": 4,
      "y": 3,
      "z": 8,
      "name": "Rock_Slate_Cobble"
    },
    {
      "x": 4,
      "y": 4,
      "z": 8,
      "name": "Ore_Cobalt_Slate_Cracked"
    },
    {
      "x": 4,
      "y": 5,
      "z": 8,
      "name": "Ore_Cobalt_Slate_Cracked"
    },
    {
      "x": 4,
      "y": -1,
      "z": 9,
      "name": "Rock_Basalt_Cobble"
    },
    {
      "x": 4,
      "y": 0,
      "z": 9,
      "name": "Rock_Basalt_Brick_Decorative"
    },
    {
      "x": 4,
      "y": 1,
      "z": 9,
      "name": "Soil_Clay_Black"
    },
    {
      "x": 4,
      "y": 2,
      "z": 9,
      "name": "Rock_Sandstone_Red_Brick_Pillar_Middle"
    },
    {
      "x": 4,
      "y": 3,
      "z": 9,
      "name": "Rock_Sandstone_Red_Brick_Pillar_Middle"
    },
    {
      "x": 4,
      "y": 4,
      "z": 9,
      "name": "Rock_Sandstone_Red_Brick_Pillar_Base",
      "rotation": 8
    },
    {
      "x": 4,
      "y": -1,
      "z": 10,
      "name": "Rock_Stone_Mossy"
    },
    {
      "x": 4,
      "y": 0,
      "z": 10,
      "name": "Rock_Stone_Mossy"
    },
    {
      "x": 4,
      "y": 1,
      "z": 10,
      "name": "Plant_Moss_Block_Green",
      "support": 15
    },
    {
      "x": 4,
      "y": -1,
      "z": 11,
      "name": "Plant_Moss_Block_Green",
      "support": 15
    },
    {
      "x": 5,
      "y": -1,
      "z": -1,
      "name": "Rock_Basalt_Cobble"
    },
    {
      "x": 5,
      "y": 2,
      "z": -1,
      "name": "Rock_Slate"
    },
    {
      "x": 5,
      "y": -1,
      "z": 0,
      "name": "Rock_Basalt_Cobble"
    },
    {
      "x": 5,
      "y": 2,
      "z": 0,
      "name": "Rock_Slate"
    },
    {
      "x": 5,
      "y": -1,
      "z": 1,
      "name": "Rock_Basalt_Cobble"
    },
    {
      "x": 5,
      "y": 2,
      "z": 1,
      "name": "Rock_Slate_Cobble"
    },
    {
      "x": 5,
      "y": -1,
      "z": 2,
      "name": "Rock_Basalt_Cobble"
    },
    {
      "x": 5,
      "y": 2,
      "z": 2,
      "name": "Rock_Slate_Cobble"
    },
    {
      "x": 5,
      "y": -1,
      "z": 3,
      "name": "Rock_Basalt_Cobble"
    },
    {
      "x": 5,
      "y": 2,
      "z": 3,
      "name": "Rock_Slate_Cobble"
    },
    {
      "x": 5,
      "y": -1,
      "z": 4,
      "name": "Rock_Basalt_Cobble"
    },
    {
      "x": 5,
      "y": 2,
      "z": 4,
      "name": "Ore_Cobalt_Slate_Cracked"
    },
    {
      "x": 5,
      "y": -1,
      "z": 5,
      "name": "Rock_Basalt_Cobble"
    },
    {
      "x": 5,
      "y": 2,
      "z": 5,
      "name": "Ore_Cobalt_Slate_Cracked"
    },
    {
      "x": 5,
      "y": -1,
      "z": 6,
      "name": "Rock_Basalt_Cobble"
    },
    {
      "x": 5,
      "y": 2,
      "z": 6,
      "name": "Ore_Cobalt_Slate_Cracked"
    },
    {
      "x": 5,
      "y": -1,
      "z": 7,
      "name": "Rock_Basalt_Cobble"
    },
    {
      "x": 5,
      "y": 2,
      "z": 7,
      "name": "Ore_Cobalt_Slate_Cracked"
    },
    {
      "x": 5,
      "y": -1,
      "z": 8,
      "name": "Rock_Basalt_Cobble"
    },
    {
      "x": 5,
      "y": 0,
      "z": 8,
      "name": "Rock_Slate_Cobble"
    },
    {
      "x": 5,
      "y": 1,
      "z": 8,
      "name": "Ore_Cobalt_Slate_Cracked"
    },
    {
      "x": 5,
      "y": 2,
      "z": 8,
      "name": "Rock_Slate"
    },
    {
      "x": 5,
      "y": 3,
      "z": 8,
      "name": "Ore_Cobalt_Slate_Cracked"
    },
    {
      "x": 5,
      "y": 4,
      "z": 8,
      "name": "Ore_Cobalt_Slate_Cracked"
    },
    {
      "x": 5,
      "y": 5,
      "z": 8,
      "name": "Ore_Cobalt_Slate_Cracked"
    },
    {
      "x": 5,
      "y": -1,
      "z": 9,
      "name": "Rock_Basalt_Cobble"
    },
    {
      "x": 5,
      "y": 0,
      "z": 9,
      "name": "Rock_Basalt_Brick_Decorative"
    },
    {
      "x": 5,
      "y": 1,
      "z": 9,
      "name": "Soil_Clay_Black"
    },
    {
      "x": 5,
      "y": 2,
      "z": 9,
      "name": "Rock_Sandstone_Red_Brick_Pillar_Base"
    },
    {
      "x": 5,
      "y": 3,
      "z": 9,
      "name": "Rock_Sandstone_Red_Brick_Pillar_Middle"
    },
    {
      "x": 5,
      "y": 4,
      "z": 9,
      "name": "Rock_Sandstone_Red_Brick_Pillar_Middle"
    },
    {
      "x": 5,
      "y": 5,
      "z": 9,
      "name": "Rock_Sandstone_Red_Brick_Pillar_Middle"
    },
    {
      "x": 5,
      "y": -1,
      "z": 10,
      "name": "Rock_Stone_Mossy"
    },
    {
      "x": 5,
      "y": 0,
      "z": 10,
      "name": "Rock_Stone_Mossy"
    },
    {
      "x": 6,
      "y": -1,
      "z": -1,
      "name": "Rock_Basalt_Cobble"
    },
    {
      "x": 6,
      "y": 2,
      "z": -1,
      "name": "Rock_Slate"
    },
    {
      "x": 6,
      "y": -1,
      "z": 0,
      "name": "Rock_Basalt_Cobble"
    },
    {
      "x": 6,
      "y": 2,
      "z": 0,
      "name": "Rock_Slate_Cobble"
    },
    {
      "x": 6,
      "y": -1,
      "z": 1,
      "name": "Rock_Basalt_Cobble"
    },
    {
      "x": 6,
      "y": 2,
      "z": 1,
      "name": "Rock_Slate_Cobble"
    },
    {
      "x": 6,
      "y": -1,
      "z": 2,
      "name": "Rock_Basalt_Cobble"
    },
    {
      "x": 6,
      "y": 2,
      "z": 2,
      "name": "Rock_Slate_Cobble"
    },
    {
      "x": 6,
      "y": -1,
      "z": 3,
      "name": "Rock_Basalt_Cobble"
    },
    {
      "x": 6,
      "y": 2,
      "z": 3,
      "name": "Rock_Slate_Cobble"
    },
    {
      "x": 6,
      "y": -1,
      "z": 4,
      "name": "Rock_Basalt_Cobble"
    },
    {
      "x": 6,
      "y": 2,
      "z": 4,
      "name": "Ore_Cobalt_Slate_Cracked"
    },
    {
      "x": 6,
      "y": -1,
      "z": 5,
      "name": "Rock_Basalt_Cobble"
    },
    {
      "x": 6,
      "y": 2,
      "z": 5,
      "name": "Ore_Cobalt_Slate_Cracked"
    },
    {
      "x": 6,
      "y": -1,
      "z": 6,
      "name": "Rock_Basalt_Cobble"
    },
    {
      "x": 6,
      "y": 2,
      "z": 6,
      "name": "Ore_Cobalt_Slate_Cracked"
    },
    {
      "x": 6,
      "y": -1,
      "z": 7,
      "name": "Rock_Basalt_Cobble"
    },
    {
      "x": 6,
      "y": 0,
      "z": 7,
      "name": "Rock_Slate_Cobble"
    },
    {
      "x": 6,
      "y": 2,
      "z": 7,
      "name": "Ore_Cobalt_Slate_Cracked"
    },
    {
      "x": 6,
      "y": 3,
      "z": 7,
      "name": "Rock_Crystal_Yellow_Medium"
    },
    {
      "x": 6,
      "y": -1,
      "z": 8,
      "name": "Rock_Basalt_Cobble"
    },
    {
      "x": 6,
      "y": 0,
      "z": 8,
      "name": "Rock_Basalt_Brick_Decorative"
    },
    {
      "x": 6,
      "y": 1,
      "z": 8,
      "name": "Soil_Clay_Black"
    },
    {
      "x": 6,
      "y": 2,
      "z": 8,
      "name": "Rock_Slate"
    },
    {
      "x": 6,
      "y": 3,
      "z": 8,
      "name": "Ore_Cobalt_Slate_Cracked"
    },
    {
      "x": 6,
      "y": 4,
      "z": 8,
      "name": "Ore_Cobalt_Slate_Cracked"
    },
    {
      "x": 6,
      "y": 5,
      "z": 8,
      "name": "Rock_Slate"
    },
    {
      "x": 6,
      "y": -1,
      "z": 9,
      "name": "Rock_Stone_Mossy"
    },
    {
      "x": 6,
      "y": 0,
      "z": 9,
      "name": "Plant_Moss_Block_Green",
      "support": 15
    },
    {
      "x": 7,
      "y": -1,
      "z": -1,
      "name": "Rock_Basalt_Cobble"
    },
    {
      "x": 7,
      "y": 2,
      "z": -1,
      "name": "Rock_Slate_Cobble"
    },
    {
      "x": 7,
      "y": -1,
      "z": 0,
      "name": "Rock_Basalt_Cobble"
    },
    {
      "x": 7,
      "y": 2,
      "z": 0,
      "name": "Rock_Slate_Cobble"
    },
    {
      "x": 7,
      "y": -1,
      "z": 1,
      "name": "Rock_Basalt_Cobble"
    },
    {
      "x": 7,
      "y": 2,
      "z": 1,
      "name": "Rock_Slate_Cobble"
    },
    {
      "x": 7,
      "y": -1,
      "z": 2,
      "name": "Rock_Basalt_Cobble"
    },
    {
      "x": 7,
      "y": 2,
      "z": 2,
      "name": "Ore_Cobalt_Slate_Cracked"
    },
    {
      "x": 7,
      "y": -1,
      "z": 3,
      "name": "Rock_Basalt_Cobble"
    },
    {
      "x": 7,
      "y": 2,
      "z": 3,
      "name": "Ore_Cobalt_Slate_Cracked"
    },
    {
      "x": 7,
      "y": -1,
      "z": 4,
      "name": "Rock_Basalt_Cobble"
    },
    {
      "x": 7,
      "y": 2,
      "z": 4,
      "name": "Ore_Cobalt_Slate_Cracked"
    },
    {
      "x": 7,
      "y": -1,
      "z": 5,
      "name": "Rock_Basalt_Cobble"
    },
    {
      "x": 7,
      "y": 2,
      "z": 5,
      "name": "Ore_Cobalt_Slate_Cracked"
    },
    {
      "x": 7,
      "y": -1,
      "z": 6,
      "name": "Rock_Basalt_Cobble"
    },
    {
      "x": 7,
      "y": 2,
      "z": 6,
      "name": "Ore_Cobalt_Slate_Cracked"
    },
    {
      "x": 7,
      "y": 3,
      "z": 6,
      "name": "Plant_Moss_Block_Green_Dark",
      "support": 15
    },
    {
      "x": 7,
      "y": 4,
      "z": 6,
      "name": "Plant_Moss_Block_Green_Dark",
      "support": 15
    },
    {
      "x": 7,
      "y": -1,
      "z": 7,
      "name": "Rock_Basalt_Cobble"
    },
    {
      "x": 7,
      "y": 0,
      "z": 7,
      "name": "Rock_Basalt_Brick_Decorative"
    },
    {
      "x": 7,
      "y": 1,
      "z": 7,
      "name": "Plant_Moss_Block_Green_Dark",
      "support": 15
    },
    {
      "x": 7,
      "y": 2,
      "z": 7,
      "name": "Plant_Moss_Block_Green_Dark",
      "support": 15
    },
    {
      "x": 7,
      "y": -1,
      "z": 8,
      "name": "Rock_Stone_Mossy"
    },
    {
      "x": 7,
      "y": 0,
      "z": 8,
      "name": "Plant_Moss_Block_Green",
      "support": 15
    },
    {
      "x": 7,
      "y": -1,
      "z": 9,
      "name": "Plant_Moss_Block_Green",
      "support": 15
    },
    {
      "x": 8,
      "y": -1,
      "z": -1,
      "name": "Rock_Basalt_Cobble"
    },
    {
      "x": 8,
      "y": 2,
      "z": -1,
      "name": "Rock_Slate_Cobble"
    },
    {
      "x": 8,
      "y": -1,
      "z": 0,
      "name": "Rock_Basalt_Cobble"
    },
    {
      "x": 8,
      "y": 2,
      "z": 0,
      "name": "Ore_Cobalt_Slate_Cracked"
    },
    {
      "x": 8,
      "y": -1,
      "z": 1,
      "name": "Rock_Basalt_Cobble"
    },
    {
      "x": 8,
      "y": 2,
      "z": 1,
      "name": "Plant_Moss_Block_Green_Dark",
      "support": 15
    },
    {
      "x": 8,
      "y": -1,
      "z": 2,
      "name": "Rock_Basalt_Cobble"
    },
    {
      "x": 8,
      "y": 2,
      "z": 2,
      "name": "Ore_Cobalt_Slate_Cracked"
    },
    {
      "x": 8,
      "y": -1,
      "z": 3,
      "name": "Rock_Basalt_Cobble"
    },
    {
      "x": 8,
      "y": 2,
      "z": 3,
      "name": "Ore_Cobalt_Slate_Cracked"
    },
    {
      "x": 8,
      "y": 3,
      "z": 3,
      "name": "Plant_Crop_Mushroom_Glowing_Orange"
    },
    {
      "x": 8,
      "y": -1,
      "z": 4,
      "name": "Rock_Basalt_Cobble"
    },
    {
      "x": 8,
      "y": 2,
      "z": 4,
      "name": "Ore_Cobalt_Slate_Cracked"
    },
    {
      "x": 8,
      "y": -1,
      "z": 5,
      "name": "Rock_Basalt_Cobble"
    },
    {
      "x": 8,
      "y": 2,
      "z": 5,
      "name": "Ore_Cobalt_Slate_Cracked"
    },
    {
      "x": 8,
      "y": 3,
      "z": 5,
      "name": "Plant_Moss_Block_Green_Dark",
      "support": 15
    },
    {
      "x": 8,
      "y": -1,
      "z": 6,
      "name": "Rock_Basalt_Cobble"
    },
    {
      "x": 8,
      "y": 0,
      "z": 6,
      "name": "Rock_Basalt_Brick_Decorative"
    },
    {
      "x": 8,
      "y": 1,
      "z": 6,
      "name": "Soil_Clay_Black"
    },
    {
      "x": 8,
      "y": 2,
      "z": 6,
      "name": "Rock_Slate"
    },
    {
      "x": 8,
      "y": 3,
      "z": 6,
      "name": "Ore_Cobalt_Slate_Cracked"
    },
    {
      "x": 8,
      "y": 4,
      "z": 6,
      "name": "Rock_Slate"
    },
    {
      "x": 8,
      "y": 5,
      "z": 6,
      "name": "Rock_Slate"
    },
    {
      "x": 8,
      "y": -1,
      "z": 7,
      "name": "Plant_Moss_Block_Green",
      "support": 15
    },
    {
      "x": 9,
      "y": -1,
      "z": -1,
      "name": "Rock_Basalt_Cobble"
    },
    {
      "x": 9,
      "y": 2,
      "z": -1,
      "name": "Rock_Slate_Cobble"
    },
    {
      "x": 9,
      "y": 3,
      "z": -1,
      "name": "Plant_Crop_Mushroom_Glowing_Orange"
    },
    {
      "x": 9,
      "y": -1,
      "z": 0,
      "name": "Rock_Basalt_Cobble"
    },
    {
      "x": 9,
      "y": 2,
      "z": 0,
      "name": "Plant_Moss_Block_Green_Dark",
      "support": 15
    },
    {
      "x": 9,
      "y": -1,
      "z": 1,
      "name": "Rock_Basalt_Cobble"
    },
    {
      "x": 9,
      "y": 2,
      "z": 1,
      "name": "Plant_Moss_Block_Green_Dark",
      "support": 15
    },
    {
      "x": 9,
      "y": -1,
      "z": 2,
      "name": "Rock_Basalt_Cobble"
    },
    {
      "x": 9,
      "y": 2,
      "z": 2,
      "name": "Ore_Cobalt_Slate_Cracked"
    },
    {
      "x": 9,
      "y": 3,
      "z": 2,
      "name": "Plant_Crop_Mushroom_Glowing_Orange"
    },
    {
      "x": 9,
      "y": -1,
      "z": 3,
      "name": "Rock_Basalt_Cobble"
    },
    {
      "x": 9,
      "y": 0,
      "z": 3,
      "name": "Rock_Basalt_Brick_Decorative"
    },
    {
      "x": 9,
      "y": 1,
      "z": 3,
      "name": "Soil_Clay_Black"
    },
    {
      "x": 9,
      "y": 2,
      "z": 3,
      "name": "Rock_Slate"
    },
    {
      "x": 9,
      "y": 3,
      "z": 3,
      "name": "Rock_Slate"
    },
    {
      "x": 9,
      "y": 4,
      "z": 3,
      "name": "Rock_Slate"
    },
    {
      "x": 9,
      "y": 5,
      "z": 3,
      "name": "Ore_Cobalt_Slate_Cracked"
    },
    {
      "x": 9,
      "y": -1,
      "z": 4,
      "name": "Rock_Basalt_Cobble"
    },
    {
      "x": 9,
      "y": 0,
      "z": 4,
      "name": "Rock_Basalt_Brick_Decorative"
    },
    {
      "x": 9,
      "y": 1,
      "z": 4,
      "name": "Soil_Clay_Black"
    },
    {
      "x": 9,
      "y": 2,
      "z": 4,
      "name": "Rock_Slate"
    },
    {
      "x": 9,
      "y": 3,
      "z": 4,
      "name": "Rock_Slate"
    },
    {
      "x": 9,
      "y": 4,
      "z": 4,
      "name": "Rock_Slate"
    },
    {
      "x": 9,
      "y": 5,
      "z": 4,
      "name": "Rock_Slate"
    },
    {
      "x": 9,
      "y": -1,
      "z": 5,
      "name": "Rock_Basalt_Cobble"
    },
    {
      "x": 9,
      "y": 0,
      "z": 5,
      "name": "Rock_Basalt_Brick_Decorative"
    },
    {
      "x": 9,
      "y": 1,
      "z": 5,
      "name": "Soil_Clay_Black"
    },
    {
      "x": 9,
      "y": 2,
      "z": 5,
      "name": "Rock_Slate"
    },
    {
      "x": 9,
      "y": 3,
      "z": 5,
      "name": "Rock_Slate"
    },
    {
      "x": 9,
      "y": 4,
      "z": 5,
      "name": "Rock_Slate"
    },
    {
      "x": 9,
      "y": 5,
      "z": 5,
      "name": "Rock_Slate"
    },
    {
      "x": 10,
      "y": -1,
      "z": -1,
      "name": "Rock_Basalt_Cobble"
    },
    {
      "x": 10,
      "y": 0,
      "z": -1,
      "name": "Rock_Basalt_Brick_Decorative"
    },
    {
      "x": 10,
      "y": 1,
      "z": -1,
      "name": "Soil_Clay_Black"
    },
    {
      "x": 10,
      "y": 2,
      "z": -1,
      "name": "Ore_Cobalt_Slate_Cracked"
    },
    {
      "x": 10,
      "y": 3,
      "z": -1,
      "name": "Ore_Cobalt_Slate_Cracked"
    },
    {
      "x": 10,
      "y": 4,
      "z": -1,
      "name": "Rock_Slate_Cobble"
    },
    {
      "x": 10,
      "y": 5,
      "z": -1,
      "name": "Ore_Cobalt_Slate_Cracked"
    },
    {
      "x": 10,
      "y": -1,
      "z": 0,
      "name": "Rock_Basalt_Cobble"
    },
    {
      "x": 10,
      "y": 0,
      "z": 0,
      "name": "Rock_Basalt_Brick_Decorative"
    },
    {
      "x": 10,
      "y": 1,
      "z": 0,
      "name": "Soil_Clay_Black"
    },
    {
      "x": 10,
      "y": 2,
      "z": 0,
      "name": "Rock_Slate"
    },
    {
      "x": 10,
      "y": 3,
      "z": 0,
      "name": "Ore_Cobalt_Slate_Cracked"
    },
    {
      "x": 10,
      "y": 4,
      "z": 0,
      "name": "Rock_Slate_Cobble"
    },
    {
      "x": 10,
      "y": 5,
      "z": 0,
      "name": "Ore_Cobalt_Slate_Cracked"
    },
    {
      "x": 10,
      "y": -1,
      "z": 1,
      "name": "Rock_Basalt_Cobble"
    },
    {
      "x": 10,
      "y": 0,
      "z": 1,
      "name": "Rock_Basalt_Brick_Decorative"
    },
    {
      "x": 10,
      "y": 1,
      "z": 1,
      "name": "Soil_Clay_Black"
    },
    {
      "x": 10,
      "y": 2,
      "z": 1,
      "name": "Rock_Slate"
    },
    {
      "x": 10,
      "y": 3,
      "z": 1,
      "name": "Rock_Slate_Cobble"
    },
    {
      "x": 10,
      "y": 4,
      "z": 1,
      "name": "Rock_Slate_Cobble"
    },
    {
      "x": 10,
      "y": 5,
      "z": 1,
      "name": "Ore_Cobalt_Slate_Cracked"
    },
    {
      "x": 10,
      "y": -1,
      "z": 2,
      "name": "Rock_Basalt_Cobble"
    },
    {
      "x": 10,
      "y": 0,
      "z": 2,
      "name": "Rock_Basalt_Brick_Decorative"
    },
    {
      "x": 10,
      "y": 1,
      "z": 2,
      "name": "Soil_Clay_Black"
    },
    {
      "x": 10,
      "y": 2,
      "z": 2,
      "name": "Rock_Slate"
    },
    {
      "x": 10,
      "y": 3,
      "z": 2,
      "name": "Rock_Slate_Cobble"
    },
    {
      "x": 10,
      "y": 4,
      "z": 2,
      "name": "Ore_Cobalt_Slate_Cracked"
    },
    {
      "x": 10,
      "y": 5,
      "z": 2,
      "name": "Ore_Cobalt_Slate_Cracked"
    },
    {
      "x": 10,
      "y": -1,
      "z": 3,
      "name": "Soil_Clay_Black"
    },
    {
      "x": 10,
      "y": 0,
      "z": 3,
      "name": "Soil_Clay_Black"
    },
    {
      "x": 10,
      "y": 1,
      "z": 3,
      "name": "Soil_Clay_Black"
    },
    {
      "x": 10,
      "y": 2,
      "z": 3,
      "name": "Soil_Clay_Black"
    },
    {
      "x": 10,
      "y": 3,
      "z": 3,
      "name": "Soil_Clay_Black"
    },
    {
      "x": 10,
      "y": 4,
      "z": 3,
      "name": "Soil_Clay_Black"
    },
    {
      "x": 10,
      "y": 5,
      "z": 3,
      "name": "Soil_Clay_Black"
    },
    {
      "x": 10,
      "y": -1,
      "z": 4,
      "name": "Soil_Clay_Black"
    },
    {
      "x": 10,
      "y": 0,
      "z": 4,
      "name": "Soil_Clay_Black"
    },
    {
      "x": 10,
      "y": 1,
      "z": 4,
      "name": "Soil_Clay_Black"
    },
    {
      "x": 10,
      "y": 2,
      "z": 4,
      "name": "Soil_Clay_Black"
    },
    {
      "x": 10,
      "y": 3,
      "z": 4,
      "name": "Soil_Clay_Black"
    },
    {
      "x": 10,
      "y": 4,
      "z": 4,
      "name": "Soil_Clay_Black"
    },
    {
      "x": 10,
      "y": 5,
      "z": 4,
      "name": "Soil_Clay_Black"
    },
    {
      "x": 10,
      "y": -1,
      "z": 5,
      "name": "Plant_Moss_Block_Green",
      "support": 15
    },
    {
      "x": 10,
      "y": 0,
      "z": 5,
      "name": "Plant_Moss_Block_Green",
      "support": 15
    },
    {
      "x": 11,
      "y": -1,
      "z": -1,
      "name": "Rock_Stone_Mossy"
    },
    {
      "x": 11,
      "y": 0,
      "z": -1,
      "name": "Rock_Stone_Mossy"
    },
    {
      "x": 11,
      "y": 1,
      "z": -1,
      "name": "Rock_Stone_Mossy"
    },
    {
      "x": 11,
      "y": 2,
      "z": -1,
      "name": "Soil_Clay_Black"
    },
    {
      "x": 11,
      "y": 5,
      "z": -1,
      "name": "Soil_Clay_Black"
    },
    {
      "x": 11,
      "y": -1,
      "z": 0,
      "name": "Rock_Stone_Mossy"
    },
    {
      "x": 11,
      "y": 0,
      "z": 0,
      "name": "Plant_Moss_Block_Green",
      "support": 15
    },
    {
      "x": 11,
      "y": 1,
      "z": 0,
      "name": "Soil_Clay_Black"
    },
    {
      "x": 11,
      "y": -1,
      "z": 1,
      "name": "Rock_Stone_Mossy"
    },
    {
      "x": 11,
      "y": 0,
      "z": 1,
      "name": "Rock_Stone_Mossy"
    },
    {
      "x": 11,
      "y": 1,
      "z": 1,
      "name": "Soil_Clay_Black"
    },
    {
      "x": 11,
      "y": -1,
      "z": 3,
      "name": "Rock_Basalt_Brick_Smooth"
    },
    {
      "x": 11,
      "y": 0,
      "z": 3,
      "name": "Rock_Basalt_Brick_Smooth"
    },
    {
      "x": 11,
      "y": 1,
      "z": 3,
      "name": "Rock_Sandstone_Red_Brick_Pillar_Middle"
    },
    {
      "x": 11,
      "y": -1,
      "z": 4,
      "name": "Rock_Basalt_Brick_Smooth"
    },
    {
      "x": 11,
      "y": 0,
      "z": 4,
      "name": "Rock_Basalt_Brick_Smooth"
    },
    {
      "x": 11,
      "y": 1,
      "z": 4,
      "name": "Rock_Sandstone_Red_Brick_Pillar_Base"
    },
    {
      "x": 11,
      "y": 2,
      "z": 4,
      "name": "Rock_Sandstone_Red_Brick_Pillar_Middle"
    },
    {
      "x": 11,
      "y": 3,
      "z": 4,
      "name": "Rock_Sandstone_Red_Brick_Pillar_Middle"
    },
    {
      "x": 12,
      "y": -1,
      "z": -1,
      "name": "Plant_Moss_Block_Green",
      "support": 15
    },
    {
      "x": 12,
      "y": -1,
      "z": 0,
      "name": "Plant_Moss_Block_Green",
      "support": 15
    }
  ]
}