{
  "version": 8,
  "blockIdVersion": 11,
  "anchorX": 6,
  "anchorY": 4,
  "anchorZ": 3,
  "blocks": [
    {
      "x": -7,
      "y": 7,
      "z": -6,
      "name": "Wood_Hardwood_Roof_Hollow",
      "rotation": 2
    },
    {
      "x": -7,
      "y": 8,
      "z": -5,
      "name": "Wood_Hardwood_Roof_Hollow",
      "rotation": 2
    },
    {
      "x": -7,
      "y": 9,
      "z": -4,
      "name": "Wood_Hardwood_Roof_Hollow",
      "rotation": 2
    },
    {
      "x": -7,
      "y": 10,
      "z": -3,
      "name": "Wood_Hardwood_Roof_Hollow",
      "rotation": 2
    },
    {
      "x": -7,
      "y": -1,
      "z": -2,
      "name": "Rock_Basalt_Cobble"
    },
    {
      "x": -7,
      "y": 11,
      "z": -2,
      "name": "Wood_Hardwood_Roof_Hollow",
      "rotation": 2
    },
    {
      "x": -7,
      "y": -1,
      "z": -1,
      "name": "Rock_Basalt_Cobble"
    },
    {
      "x": -7,
      "y": 0,
      "z": -1,
      "name": "Rock_Basalt_Cobble"
    },
    {
      "x": -7,
      "y": 11,
      "z": -1,
      "name": "Wood_Hardwood_Roof_Hollow"
    },
    {
      "x": -7,
      "y": 11,
      "z": 0,
      "name": "Wood_Hardwood_Roof_Flat",
      "rotation": 2
    },
    {
      "x": -7,
      "y": 10,
      "z": 1,
      "name": "Wood_Hardwood_Roof_Hollow"
    },
    {
      "x": -7,
      "y": 9,
      "z": 2,
      "name": "Wood_Hardwood_Roof_Hollow"
    },
    {
      "x": -7,
      "y": 8,
      "z": 3,
      "name": "Wood_Hardwood_Roof_Hollow"
    },
    {
      "x": -6,
      "y": 7,
      "z": -6,
      "name": "Wood_Hardwood_Roof_Hollow",
      "rotation": 2
    },
    {
      "x": -6,
      "y": -3,
      "z": -5,
      "name": "Rock_Basalt_Brick"
    },
    {
      "x": -6,
      "y": -2,
      "z": -5,
      "name": "Rock_Basalt_Brick"
    },
    {
      "x": -6,
      "y": -1,
      "z": -5,
      "name": "Rock_Basalt_Brick"
    },
    {
      "x": -6,
      "y": 0,
      "z": -5,
      "name": "Rock_Basalt_Brick"
    },
    {
      "x": -6,
      "y": 1,
      "z": -5,
      "name": "Rock_Basalt_Brick"
    },
    {
      "x": -6,
      "y": 2,
      "z": -5,
      "name": "Rock_Basalt_Brick"
    },
    {
      "x": -6,
      "y": 3,
      "z": -5,
      "name": "Wood_Sallow_Trunk",
      "support": 15
    },
    {
      "x": -6,
      "y": 4,
      "z": -5,
      "name": "Wood_Sallow_Trunk",
      "support": 15
    },
    {
      "x": -6,
      "y": 5,
      "z": -5,
      "name": "Wood_Sallow_Trunk",
      "support": 15
    },
    {
      "x": -6,
      "y": 6,
      "z": -5,
      "name": "Wood_Sallow_Trunk",
      "support": 15
    },
    {
      "x": -6,
      "y": 7,
      "z": -5,
      "name": "Wood_Hardwood_Planks"
    },
    {
      "x": -6,
      "y": 8,
      "z": -5,
      "name": "Wood_Hardwood_Planks"
    },
    {
      "x": -6,
      "y": -3,
      "z": -4,
      "name": "Rock_Basalt_Brick"
    },
    {
      "x": -6,
      "y": -2,
      "z": -4,
      "name": "Rock_Basalt_Brick"
    },
    {
      "x": -6,
      "y": -1,
      "z": -4,
      "name": "Rock_Basalt_Brick"
    },
    {
      "x": -6,
      "y": 0,
      "z": -4,
      "name": "Rock_Basalt_Brick"
    },
    {
      "x": -6,
      "y": 1,
      "z": -4,
      "name": "Rock_Basalt_Brick"
    },
    {
      "x": -6,
      "y": 2,
      "z": -4,
      "name": "Rock_Basalt_Brick"
    },
    {
      "x": -6,
      "y": 3,
      "z": -4,
      "name": "Wood_Goldenwood_Planks"
    },
    {
      "x": -6,
      "y": 4,
      "z": -4,
      "name": "Wood_Goldenwood_Planks"
    },
    {
      "x": -6,
      "y": 5,
      "z": -4,
      "name": "Wood_Goldenwood_Planks"
    },
    {
      "x": -6,
      "y": 6,
      "z": -4,
      "name": "Wood_Sallow_Trunk",
      "support": 15,
      "rotation": 4
    },
    {
      "x": -6,
      "y": 7,
      "z": -4,
      "name": "Wood_Hardwood_Planks"
    },
    {
      "x": -6,
      "y": 8,
      "z": -4,
      "name": "Wood_Hardwood_Planks"
    },
    {
      "x": -6,
      "y": 9,
      "z": -4,
      "name": "Wood_Hardwood_Roof",
      "rotation": 2
    },
    {
      "x": -6,
      "y": -3,
      "z": -3,
      "name": "Rock_Basalt_Brick"
    },
    {
      "x": -6,
      "y": -2,
      "z": -3,
      "name": "Rock_Basalt_Brick"
    },
    {
      "x": -6,
      "y": -1,
      "z": -3,
      "name": "Rock_Basalt_Brick"
    },
    {
      "x": -6,
      "y": 0,
      "z": -3,
      "name": "Rock_Basalt_Brick"
    },
    {
      "x": -6,
      "y": 1,
      "z": -3,
      "name": "Rock_Basalt_Brick"
    },
    {
      "x": -6,
      "y": 2,
      "z": -3,
      "name": "Rock_Basalt_Brick"
    },
    {
      "x": -6,
      "y": 3,
      "z": -3,
      "name": "Wood_Goldenwood_Planks"
    },
    {
      "x": -6,
      "y": 4,
      "z": -3,
      "name": "Wood_Goldenwood_Planks"
    },
    {
      "x": -6,
      "y": 5,
      "z": -3,
      "name": "Wood_Goldenwood_Planks"
    },
    {
      "x": -6,
      "y": 6,
      "z": -3,
      "name": "Wood_Sallow_Trunk",
      "support": 15,
      "rotation": 4
    },
    {
      "x": -6,
      "y": 7,
      "z": -3,
      "name": "Wood_Hardwood_Planks"
    },
    {
      "x": -6,
      "y": 8,
      "z": -3,
      "name": "Wood_Hardwood_Planks"
    },
    {
      "x": -6,
      "y": 9,
      "z": -3,
      "name": "Wood_Hardwood_Planks"
    },
    {
      "x": -6,
      "y": 10,
      "z": -3,
      "name": "Wood_Hardwood_Roof",
      "rotation": 2
    },
    {
      "x": -6,
      "y": -3,
      "z": -2,
      "name": "Rock_Basalt_Brick"
    },
    {
      "x": -6,
      "y": -2,
      "z": -2,
      "name": "Rock_Basalt_Cobble"
    },
    {
      "x": -6,
      "y": -1,
      "z": -2,
      "name": "Rock_Basalt_Cobble"
    },
    {
      "x": -6,
      "y": 0,
      "z": -2,
      "name": "Rock_Basalt_Brick"
    },
    {
      "x": -6,
      "y": 1,
      "z": -2,
      "name": "Rock_Basalt_Brick"
    },
    {
      "x": -6,
      "y": 2,
      "z": -2,
      "name": "Rock_Basalt_Brick"
    },
    {
      "x": -6,
      "y": 3,
      "z": -2,
      "name": "Wood_Goldenwood_Planks"
    },
    {
      "x": -6,
      "y": 4,
      "z": -2,
      "name": "Wood_Goldenwood_Planks"
    },
    {
      "x": -6,
      "y": 5,
      "z": -2,
      "name": "Wood_Goldenwood_Planks"
    },
    {
      "x": -6,
      "y": 6,
      "z": -2,
      "name": "Wood_Sallow_Trunk",
      "support": 15,
      "rotation": 4
    },
    {
      "x": -6,
      "y": 7,
      "z": -2,
      "name": "Wood_Hardwood_Planks"
    },
    {
      "x": -6,
      "y": 8,
      "z": -2,
      "name": "Wood_Hardwood_Planks"
    },
    {
      "x": -6,
      "y": 10,
      "z": -2,
      "name": "Wood_Hardwood_Planks"
    },
    {
      "x": -6,
      "y": 11,
      "z": -2,
      "name": "Wood_Hardwood_Roof",
      "rotation": 2
    },
    {
      "x": -6,
      "y": -3,
      "z": -1,
      "name": "Rock_Basalt_Brick"
    },
    {
      "x": -6,
      "y": -2,
      "z": -1,
      "name": "Rock_Basalt_Brick"
    },
    {
      "x": -6,
      "y": -1,
      "z": -1,
      "name": "Furniture_Human_Ruins_Pot"
    },
    {
      "x": -6,
      "y": 1,
      "z": -1,
      "name": "Rock_Basalt_Brick"
    },
    {
      "x": -6,
      "y": 2,
      "z": -1,
      "name": "Rock_Basalt_Brick"
    },
    {
      "x": -6,
      "y": 3,
      "z": -1,
      "name": "Wood_Goldenwood_Planks"
    },
    {
      "x": -6,
      "y": 4,
      "z": -1,
      "name": "Wood_Goldenwood_Planks"
    },
    {
      "x": -6,
      "y": 7,
      "z": -1,
      "name": "Wood_Hardwood_Planks"
    },
    {
      "x": -6,
      "y": 8,
      "z": -1,
      "name": "Wood_Hardwood_Planks"
    },
    {
      "x": -6,
      "y": 9,
      "z": -1,
      "name": "Wood_Hardwood_Beam"
    },
    {
      "x": -6,
      "y": 10,
      "z": -1,
      "name": "Wood_Hardwood_Beam"
    },
    {
      "x": -6,
      "y": 11,
      "z": -1,
      "name": "Wood_Hardwood_Roof"
    },
    {
      "x": -6,
      "y": -3,
      "z": 0,
      "name": "Rock_Basalt_Brick"
    },
    {
      "x": -6,
      "y": -2,
      "z": 0,
      "name": "Rock_Basalt_Brick"
    },
    {
      "x": -6,
      "y": -1,
      "z": 0,
      "name": "Rock_Basalt_Brick"
    },
    {
      "x": -6,
      "y": 0,
      "z": 0,
      "name": "Rock_Basalt_Brick"
    },
    {
      "x": -6,
      "y": 1,
      "z": 0,
      "name": "Rock_Basalt_Brick"
    },
    {
      "x": -6,
      "y": 2,
      "z": 0,
      "name": "Rock_Basalt_Brick"
    },
    {
      "x": -6,
      "y": 3,
      "z": 0,
      "name": "Wood_Goldenwood_Planks"
    },
    {
      "x": -6,
      "y": 4,
      "z": 0,
      "name": "Wood_Goldenwood_Planks"
    },
    {
      "x": -6,
      "y": 5,
      "z": 0,
      "name": "Wood_Goldenwood_Planks"
    },
    {
      "x": -6,
      "y": 6,
      "z": 0,
      "name": "Wood_Sallow_Trunk",
      "support": 15,
      "rotation": 4
    },
    {
      "x": -6,
      "y": 7,
      "z": 0,
      "name": "Wood_Hardwood_Planks"
    },
    {
      "x": -6,
      "y": 8,
      "z": 0,
      "name": "Wood_Hardwood_Planks"
    },
    {
      "x": -6,
      "y": 9,
      "z": 0,
      "name": "Wood_Hardwood_Planks"
    },
    {
      "x": -6,
      "y": 10,
      "z": 0,
      "name": "Wood_Hardwood_Planks"
    },
    {
      "x": -6,
      "y": 11,
      "z": 0,
      "name": "Wood_Hardwood_Roof_Flat",
      "rotation": 2
    },
    {
      "x": -6,
      "y": -3,
      "z": 1,
      "name": "Rock_Basalt_Brick"
    },
    {
      "x": -6,
      "y": -2,
      "z": 1,
      "name": "Rock_Basalt_Brick"
    },
    {
      "x": -6,
      "y": -1,
      "z": 1,
      "name": "Rock_Basalt_Brick"
    },
    {
      "x": -6,
      "y": 0,
      "z": 1,
      "name": "Rock_Basalt_Brick"
    },
    {
      "x": -6,
      "y": 1,
      "z": 1,
      "name": "Rock_Basalt_Brick"
    },
    {
      "x": -6,
      "y": 2,
      "z": 1,
      "name": "Rock_Basalt_Brick"
    },
    {
      "x": -6,
      "y": 3,
      "z": 1,
      "name": "Wood_Goldenwood_Planks"
    },
    {
      "x": -6,
      "y": 4,
      "z": 1,
      "name": "Wood_Hardwood_Beam",
      "rotation": 4
    },
    {
      "x": -6,
      "y": 5,
      "z": 1,
      "name": "Wood_Goldenwood_Planks"
    },
    {
      "x": -6,
      "y": 6,
      "z": 1,
      "name": "Wood_Sallow_Trunk",
      "support": 15,
      "rotation": 4
    },
    {
      "x": -6,
      "y": 7,
      "z": 1,
      "name": "Wood_Hardwood_Planks"
    },
    {
      "x": -6,
      "y": 8,
      "z": 1,
      "name": "Wood_Hardwood_Planks"
    },
    {
      "x": -6,
      "y": 9,
      "z": 1,
      "name": "Wood_Hardwood_Planks"
    },
    {
      "x": -6,
      "y": 10,
      "z": 1,
      "name": "Wood_Hardwood_Roof"
    },
    {
      "x": -6,
      "y": -3,
      "z": 2,
      "name": "Rock_Basalt_Brick"
    },
    {
      "x": -6,
      "y": -2,
      "z": 2,
      "name": "Rock_Basalt_Brick"
    },
    {
      "x": -6,
      "y": -1,
      "z": 2,
      "name": "Rock_Basalt_Brick"
    },
    {
      "x": -6,
      "y": 0,
      "z": 2,
      "name": "Rock_Basalt_Brick"
    },
    {
      "x": -6,
      "y": 1,
      "z": 2,
      "name": "Rock_Basalt_Brick"
    },
    {
      "x": -6,
      "y": 2,
      "z": 2,
      "name": "Rock_Basalt_Brick"
    },
    {
      "x": -6,
      "y": 3,
      "z": 2,
      "name": "Wood_Goldenwood_Planks"
    },
    {
      "x": -6,
      "y": 4,
      "z": 2,
      "name": "Wood_Hardwood_Beam",
      "rotation": 4
    },
    {
      "x": -6,
      "y": 5,
      "z": 2,
      "name": "Wood_Goldenwood_Planks"
    },
    {
      "x": -6,
      "y": 6,
      "z": 2,
      "name": "Wood_Sallow_Trunk",
      "support": 15,
      "rotation": 4
    },
    {
      "x": -6,
      "y": 7,
      "z": 2,
      "name": "Wood_Hardwood_Planks"
    },
    {
      "x": -6,
      "y": 8,
      "z": 2,
      "name": "Wood_Hardwood_Planks"
    },
    {
      "x": -6,
      "y": 9,
      "z": 2,
      "name": "Wood_Hardwood_Roof"
    },
    {
      "x": -6,
      "y": -1,
      "z": 3,
      "name": "Rock_Basalt_Brick"
    },
    {
      "x": -6,
      "y": 0,
      "z": 3,
      "name": "Rock_Basalt_Brick"
    },
    {
      "x": -6,
      "y": 1,
      "z": 3,
      "name": "Rock_Basalt_Brick"
    },
    {
      "x": -6,
      "y": 2,
      "z": 3,
      "name": "Rock_Basalt_Brick"
    },
    {
      "x": -6,
      "y": 3,
      "z": 3,
      "name": "Wood_Sallow_Trunk",
      "support": 15
    },
    {
      "x": -6,
      "y": 4,
      "z": 3,
      "name": "Wood_Sallow_Trunk",
      "support": 15
    },
    {
      "x": -6,
      "y": 5,
      "z": 3,
      "name": "Wood_Sallow_Trunk",
      "support": 15
    },
    {
      "x": -6,
      "y": 6,
      "z": 3,
      "name": "Wood_Sallow_Trunk",
      "support": 15
    },
    {
      "x": -6,
      "y": 7,
      "z": 3,
      "name": "Wood_Hardwood_Planks"
    },
    {
      "x": -6,
      "y": 8,
      "z": 3,
      "name": "Wood_Hardwood_Planks"
    },
    {
      "x": -6,
      "y": 7,
      "z": 4,
      "name": "Wood_Hardwood_Roof_Hollow"
    },
    {
      "x": -5,
      "y": 7,
      "z": -6,
      "name": "Wood_Hardwood_Roof_Hollow",
      "rotation": 2
    },
    {
      "x": -5,
      "y": -3,
      "z": -5,
      "name": "Rock_Basalt_Brick"
    },
    {
      "x": -5,
      "y": -2,
      "z": -5,
      "name": "Rock_Basalt_Brick"
    },
    {
      "x": -5,
      "y": -1,
      "z": -5,
      "name": "Rock_Basalt_Brick"
    },
    {
      "x": -5,
      "y": 0,
      "z": -5,
      "name": "Rock_Basalt_Brick"
    },
    {
      "x": -5,
      "y": 1,
      "z": -5,
      "name": "Rock_Basalt_Brick"
    },
    {
      "x": -5,
      "y": 2,
      "z": -5,
      "name": "Rock_Basalt_Brick"
    },
    {
      "x": -5,
      "y": 3,
      "z": -5,
      "name": "Wood_Goldenwood_Planks"
    },
    {
      "x": -5,
      "y": 4,
      "z": -5,
      "name": "Wood_Goldenwood_Planks"
    },
    {
      "x": -5,
      "y": 5,
      "z": -5,
      "name": "Wood_Goldenwood_Planks"
    },
    {
      "x": -5,
      "y": 6,
      "z": -5,
      "name": "Wood_Sallow_Trunk",
      "support": 15,
      "rotation": 5
    },
    {
      "x": -5,
      "y": 7,
      "z": -5,
      "name": "Wood_Hardwood_Planks"
    },
    {
      "x": -5,
      "y": 8,
      "z": -5,
      "name": "Wood_Hardwood_Roof",
      "rotation": 2
    },
    {
      "x": -5,
      "y": -3,
      "z": -4,
      "name": "Rock_Basalt_Brick"
    },
    {
      "x": -5,
      "y": -2,
      "z": -4,
      "name": "Rock_Basalt"
    },
    {
      "x": -5,
      "y": -1,
      "z": -4,
      "name": "Furniture_Human_Ruins_Bookshelf",
      "rotation": 1
    },
    {
      "x": -5,
      "y": 0,
      "z": -4,
      "name": "Furniture_Human_Ruins_Bookshelf",
      "rotation": 1
    },
    {
      "x": -5,
      "y": 1,
      "z": -4,
      "name": "Furniture_Human_Ruins_Bookshelf",
      "rotation": 1
    },
    {
      "x": -5,
      "y": 2,
      "z": -4,
      "name": "Empty"
    },
    {
      "x": -5,
      "y": 3,
      "z": -4,
      "name": "Wood_Goldenwood_Planks"
    },
    {
      "x": -5,
      "y": 4,
      "z": -4,
      "name": "Furniture_Human_Ruins_Bookshelf",
      "rotation": 1
    },
    {
      "x": -5,
      "y": 5,
      "z": -4,
      "name": "Furniture_Human_Ruins_Bookshelf",
      "rotation": 1
    },
    {
      "x": -5,
      "y": 6,
      "z": -4,
      "name": "Furniture_Human_Ruins_Bookshelf",
      "rotation": 1
    },
    {
      "x": -5,
      "y": 7,
      "z": -4,
      "name": "Wood_Goldenwood_Planks"
    },
    {
      "x": -5,
      "y": 8,
      "z": -4,
      "name": "Wood_Hardwood_Planks"
    },
    {
      "x": -5,
      "y": 9,
      "z": -4,
      "name": "Wood_Hardwood_Roof",
      "rotation": 2
    },
    {
      "x": -5,
      "y": -3,
      "z": -3,
      "name": "Empty"
    },
    {
      "x": -5,
      "y": -2,
      "z": -3,
      "name": "Rock_Basalt"
    },
    {
      "x": -5,
      "y": -1,
      "z": -3,
      "name": "Furniture_Human_Ruins_Bookshelf",
      "rotation": 1
    },
    {
      "x": -5,
      "y": 0,
      "z": -3,
      "name": "Furniture_Human_Ruins_Bookshelf",
      "rotation": 1
    },
    {
      "x": -5,
      "y": 1,
      "z": -3,
      "name": "Empty"
    },
    {
      "x": -5,
      "y": 2,
      "z": -3,
      "name": "Empty"
    },
    {
      "x": -5,
      "y": 3,
      "z": -3,
      "name": "Wood_Goldenwood_Planks"
    },
    {
      "x": -5,
      "y": 4,
      "z": -3,
      "name": "Furniture_Human_Ruins_Bookshelf",
      "rotation": 1
    },
    {
      "x": -5,
      "y": 5,
      "z": -3,
      "name": "Furniture_Human_Ruins_Bookshelf",
      "rotation": 1
    },
    {
      "x": -5,
      "y": 7,
      "z": -3,
      "name": "Wood_Goldenwood_Planks_Half",
      "rotation": 5
    },
    {
      "x": -5,
      "y": 8,
      "z": -3,
      "name": "Wood_Hardwood_Planks"
    },
    {
      "x": -5,
      "y": 10,
      "z": -3,
      "name": "Wood_Hardwood_Roof_Hollow",
      "rotation": 2
    },
    {
      "x": -5,
      "y": -3,
      "z": -2,
      "name": "Empty"
    },
    {
      "x": -5,
      "y": -2,
      "z": -2,
      "name": "Rock_Basalt_Cobble"
    },
    {
      "x": -5,
      "y": -1,
      "z": -2,
      "name": "Empty"
    },
    {
      "x": -5,
      "y": 0,
      "z": -2,
      "name": "Empty"
    },
    {
      "x": -5,
      "y": 3,
      "z": -2,
      "name": "Wood_Goldenwood_Planks"
    },
    {
      "x": -5,
      "y": 4,
      "z": -2,
      "name": "Block_Spawner_Block",
      "components": {
        "Components": {
          "PlacedByInteraction": {
            "WhoPlacedUuid": {
              "$binary": "5RPZJ2uQSJ2g+KZxfjqR+g==",
              "$type": "04"
            }
          },
          "BlockSpawner": {
            "BlockSpawnerId": "Thunderstorm_Tier1"
          }
        }
      },
      "rotation": 1
    },
    {
      "x": -5,
      "y": 5,
      "z": -2,
      "name": "Furniture_Human_Ruins_Shelf",
      "rotation": 1
    },
    {
      "x": -5,
      "y": 7,
      "z": -2,
      "name": "Wood_Goldenwood_Planks_Half",
      "rotation": 5
    },
    {
      "x": -5,
      "y": 8,
      "z": -2,
      "name": "Wood_Hardwood_Planks"
    },
    {
      "x": -5,
      "y": 11,
      "z": -2,
      "name": "Wood_Hardwood_Roof_Hollow",
      "rotation": 2
    },
    {
      "x": -5,
      "y": -3,
      "z": -1,
      "name": "Rock_Basalt_Brick"
    },
    {
      "x": -5,
      "y": -2,
      "z": -1,
      "name": "Rock_Basalt"
    },
    {
      "x": -5,
      "y": -1,
      "z": -1,
      "name": "Empty"
    },
    {
      "x": -5,
      "y": 0,
      "z": -1,
      "name": "Empty"
    },
    {
      "x": -5,
      "y": 1,
      "z": -1,
      "name": "Empty"
    },
    {
      "x": -5,
      "y": 2,
      "z": -1,
      "name": "Empty"
    },
    {
      "x": -5,
      "y": 3,
      "z": -1,
      "name": "Wood_Goldenwood_Planks"
    },
    {
      "x": -5,
      "y": 7,
      "z": -1,
      "name": "Wood_Goldenwood_Planks_Half",
      "rotation": 5
    },
    {
      "x": -5,
      "y": 8,
      "z": -1,
      "name": "Wood_Hardwood_Planks"
    },
    {
      "x": -5,
      "y": 11,
      "z": -1,
      "name": "Wood_Hardwood_Roof_Hollow"
    },
    {
      "x": -5,
      "y": -3,
      "z": 0,
      "name": "Rock_Basalt_Brick"
    },
    {
      "x": -5,
      "y": -2,
      "z": 0,
      "name": "Rock_Basalt"
    },
    {
      "x": -5,
      "y": -1,
      "z": 0,
      "name": "Furniture_Human_Ruins_Pot"
    },
    {
      "x": -5,
      "y": 0,
      "z": 0,
      "name": "Empty"
    },
    {
      "x": -5,
      "y": 1,
      "z": 0,
      "name": "Empty"
    },
    {
      "x": -5,
      "y": 2,
      "z": 0,
      "name": "Empty"
    },
    {
      "x": -5,
      "y": 3,
      "z": 0,
      "name": "Wood_Goldenwood_Planks"
    },
    {
      "x": -5,
      "y": 7,
      "z": 0,
      "name": "Wood_Goldenwood_Planks_Half",
      "rotation": 5
    },
    {
      "x": -5,
      "y": 8,
      "z": 0,
      "name": "Wood_Hardwood_Planks"
    },
    {
      "x": -5,
      "y": 11,
      "z": 0,
      "name": "Wood_Hardwood_Roof_Flat",
      "rotation": 2
    },
    {
      "x": -5,
      "y": -3,
      "z": 1,
      "name": "Rock_Basalt_Brick"
    },
    {
      "x": -5,
      "y": -2,
      "z": 1,
      "name": "Rock_Basalt"
    },
    {
      "x": -5,
      "y": -1,
      "z": 1,
      "name": "Furniture_Human_Ruins_Desk",
      "rotation": 1
    },
    {
      "x": -5,
      "y": 0,
      "z": 1,
      "name": "Furniture_Human_Ruins_Candle"
    },
    {
      "x": -5,
      "y": 1,
      "z": 1,
      "name": "Furniture_Human_Ruins_Candle",
      "filler": 1024
    },
    {
      "x": -5,
      "y": 2,
      "z": 1,
      "name": "Empty"
    },
    {
      "x": -5,
      "y": 3,
      "z": 1,
      "name": "Wood_Goldenwood_Planks"
    },
    {
      "x": -5,
      "y": 7,
      "z": 1,
      "name": "Wood_Goldenwood_Planks_Half",
      "rotation": 5
    },
    {
      "x": -5,
      "y": 8,
      "z": 1,
      "name": "Wood_Hardwood_Planks"
    },
    {
      "x": -5,
      "y": 10,
      "z": 1,
      "name": "Wood_Hardwood_Roof_Hollow"
    },
    {
      "x": -5,
      "y": -3,
      "z": 2,
      "name": "Rock_Basalt_Brick"
    },
    {
      "x": -5,
      "y": -2,
      "z": 2,
      "name": "Rock_Basalt"
    },
    {
      "x": -5,
      "y": -1,
      "z": 2,
      "name": "Furniture_Human_Ruins_Desk",
      "filler": 32,
      "rotation": 1
    },
    {
      "x": -5,
      "y": 0,
      "z": 2,
      "name": "Potion_Poison"
    },
    {
      "x": -5,
      "y": 1,
      "z": 2,
      "name": "Empty"
    },
    {
      "x": -5,
      "y": 2,
      "z": 2,
      "name": "Empty"
    },
    {
      "x": -5,
      "y": 3,
      "z": 2,
      "name": "Wood_Goldenwood_Planks"
    },
    {
      "x": -5,
      "y": 7,
      "z": 2,
      "name": "Wood_Goldenwood_Planks"
    },
    {
      "x": -5,
      "y": 8,
      "z": 2,
      "name": "Wood_Hardwood_Planks"
    },
    {
      "x": -5,
      "y": 9,
      "z": 2,
      "name": "Wood_Hardwood_Planks"
    },
    {
      "x": -5,
      "y": -1,
      "z": 3,
      "name": "Rock_Basalt_Brick"
    },
    {
      "x": -5,
      "y": 0,
      "z": 3,
      "name": "Rock_Basalt_Brick"
    },
    {
      "x": -5,
      "y": 1,
      "z": 3,
      "name": "Rock_Basalt_Brick"
    },
    {
      "x": -5,
      "y": 2,
      "z": 3,
      "name": "Rock_Basalt_Brick"
    },
    {
      "x": -5,
      "y": 3,
      "z": 3,
      "name": "Wood_Goldenwood_Planks"
    },
    {
      "x": -5,
      "y": 4,
      "z": 3,
      "name": "Wood_Goldenwood_Planks"
    },
    {
      "x": -5,
      "y": 5,
      "z": 3,
      "name": "Wood_Goldenwood_Planks"
    },
    {
      "x": -5,
      "y": 6,
      "z": 3,
      "name": "Wood_Sallow_Trunk",
      "support": 15,
      "rotation": 5
    },
    {
      "x": -5,
      "y": 7,
      "z": 3,
      "name": "Wood_Hardwood_Planks"
    },
    {
      "x": -5,
      "y": 8,
      "z": 3,
      "name": "Wood_Hardwood_Planks"
    },
    {
      "x": -5,
      "y": 7,
      "z": 4,
      "name": "Wood_Hardwood_Roof_Hollow"
    },
    {
      "x": -4,
      "y": 7,
      "z": -6,
      "name": "Wood_Hardwood_Roof_Hollow",
      "rotation": 2
    },
    {
      "x": -4,
      "y": -3,
      "z": -5,
      "name": "Rock_Basalt_Brick"
    },
    {
      "x": -4,
      "y": -2,
      "z": -5,
      "name": "Rock_Basalt_Brick"
    },
    {
      "x": -4,
      "y": -1,
      "z": -5,
      "name": "Rock_Basalt_Brick"
    },
    {
      "x": -4,
      "y": 0,
      "z": -5,
      "name": "Rock_Basalt_Brick"
    },
    {
      "x": -4,
      "y": 1,
      "z": -5,
      "name": "Rock_Basalt_Brick"
    },
    {
      "x": -4,
      "y": 2,
      "z": -5,
      "name": "Rock_Basalt_Brick"
    },
    {
      "x": -4,
      "y": 3,
      "z": -5,
      "name": "Wood_Goldenwood_Planks"
    },
    {
      "x": -4,
      "y": 4,
      "z": -5,
      "name": "Wood_Goldenwood_Planks"
    },
    {
      "x": -4,
      "y": 5,
      "z": -5,
      "name": "Furniture_Human_Ruins_Window"
    },
    {
      "x": -4,
      "y": 6,
      "z": -5,
      "name": "Furniture_Human_Ruins_Window"
    },
    {
      "x": -4,
      "y": 7,
      "z": -5,
      "name": "Wood_Hardwood_Planks"
    },
    {
      "x": -4,
      "y": 8,
      "z": -5,
      "name": "Wood_Hardwood_Roof",
      "rotation": 2
    },
    {
      "x": -4,
      "y": -3,
      "z": -4,
      "name": "Rock_Basalt_Brick"
    },
    {
      "x": -4,
      "y": -2,
      "z": -4,
      "name": "Rock_Basalt"
    },
    {
      "x": -4,
      "y": -1,
      "z": -4,
      "name": "Furniture_Human_Ruins_Pot_Small"
    },
    {
      "x": -4,
      "y": 0,
      "z": -4,
      "name": "Empty"
    },
    {
      "x": -4,
      "y": 1,
      "z": -4,
      "name": "Empty"
    },
    {
      "x": -4,
      "y": 2,
      "z": -4,
      "name": "Empty"
    },
    {
      "x": -4,
      "y": 3,
      "z": -4,
      "name": "Wood_Goldenwood_Planks"
    },
    {
      "x": -4,
      "y": 7,
      "z": -4,
      "name": "Wood_Goldenwood_Planks_Half",
      "rotation": 4
    },
    {
      "x": -4,
      "y": 8,
      "z": -4,
      "name": "Wood_Hardwood_Planks"
    },
    {
      "x": -4,
      "y": 9,
      "z": -4,
      "name": "Wood_Hardwood_Roof",
      "rotation": 2
    },
    {
      "x": -4,
      "y": -3,
      "z": -3,
      "name": "Rock_Basalt_Brick"
    },
    {
      "x": -4,
      "y": -2,
      "z": -3,
      "name": "Rock_Basalt_Cobble"
    },
    {
      "x": -4,
      "y": -1,
      "z": -3,
      "name": "Empty"
    },
    {
      "x": -4,
      "y": 0,
      "z": -3,
      "name": "Empty"
    },
    {
      "x": -4,
      "y": 1,
      "z": -3,
      "name": "Empty"
    },
    {
      "x": -4,
      "y": 2,
      "z": -3,
      "name": "Empty"
    },
    {
      "x": -4,
      "y": 3,
      "z": -3,
      "name": "Wood_Goldenwood_Planks"
    },
    {
      "x": -4,
      "y": 8,
      "z": -3,
      "name": "Wood_Hardwood_Planks"
    },
    {
      "x": -4,
      "y": 10,
      "z": -3,
      "name": "Wood_Hardwood_Roof_Hollow",
      "rotation": 2
    },
    {
      "x": -4,
      "y": -3,
      "z": -2,
      "name": "Rock_Basalt_Brick"
    },
    {
      "x": -4,
      "y": -2,
      "z": -2,
      "name": "Rock_Basalt"
    },
    {
      "x": -4,
      "y": -1,
      "z": -2,
      "name": "Empty"
    },
    {
      "x": -4,
      "y": 0,
      "z": -2,
      "name": "Empty"
    },
    {
      "x": -4,
      "y": 2,
      "z": -2,
      "name": "Empty"
    },
    {
      "x": -4,
      "y": 3,
      "z": -2,
      "name": "Wood_Goldenwood_Planks"
    },
    {
      "x": -4,
      "y": 8,
      "z": -2,
      "name": "Wood_Hardwood_Planks"
    },
    {
      "x": -4,
      "y": 11,
      "z": -2,
      "name": "Wood_Hardwood_Roof_Hollow",
      "rotation": 2
    },
    {
      "x": -4,
      "y": -3,
      "z": -1,
      "name": "Rock_Basalt_Brick"
    },
    {
      "x": -4,
      "y": -2,
      "z": -1,
      "name": "Rock_Basalt"
    },
    {
      "x": -4,
      "y": -1,
      "z": -1,
      "name": "Empty"
    },
    {
      "x": -4,
      "y": 0,
      "z": -1,
      "name": "Empty"
    },
    {
      "x": -4,
      "y": 3,
      "z": -1,
      "name": "Wood_Goldenwood_Planks"
    },
    {
      "x": -4,
      "y": 8,
      "z": -1,
      "name": "Wood_Hardwood_Planks"
    },
    {
      "x": -4,
      "y": 11,
      "z": -1,
      "name": "Wood_Hardwood_Roof_Hollow"
    },
    {
      "x": -4,
      "y": -3,
      "z": 0,
      "name": "Rock_Basalt_Brick"
    },
    {
      "x": -4,
      "y": -2,
      "z": 0,
      "name": "Rock_Basalt"
    },
    {
      "x": -4,
      "y": -1,
      "z": 0,
      "name": "Empty"
    },
    {
      "x": -4,
      "y": 0,
      "z": 0,
      "name": "Empty"
    },
    {
      "x": -4,
      "y": 1,
      "z": 0,
      "name": "Empty"
    },
    {
      "x": -4,
      "y": 2,
      "z": 0,
      "name": "Empty"
    },
    {
      "x": -4,
      "y": 3,
      "z": 0,
      "name": "Wood_Goldenwood_Planks"
    },
    {
      "x": -4,
      "y": 4,
      "z": 0,
      "name": "Furniture_Human_Ruins_Bed",
      "filler": 991,
      "rotation": 2
    },
    {
      "x": -4,
      "y": 5,
      "z": 0,
      "name": "Furniture_Human_Ruins_Bed",
      "filler": 2015,
      "rotation": 2
    },
    {
      "x": -4,
      "y": 8,
      "z": 0,
      "name": "Wood_Hardwood_Planks"
    },
    {
      "x": -4,
      "y": 11,
      "z": 0,
      "name": "Wood_Hardwood_Roof_Flat",
      "rotation": 3
    },
    {
      "x": -4,
      "y": -3,
      "z": 1,
      "name": "Rock_Basalt_Brick"
    },
    {
      "x": -4,
      "y": -2,
      "z": 1,
      "name": "Rock_Basalt"
    },
    {
      "x": -4,
      "y": -1,
      "z": 1,
      "name": "Empty"
    },
    {
      "x": -4,
      "y": 0,
      "z": 1,
      "name": "Empty"
    },
    {
      "x": -4,
      "y": 1,
      "z": 1,
      "name": "Empty"
    },
    {
      "x": -4,
      "y": 2,
      "z": 1,
      "name": "Empty"
    },
    {
      "x": -4,
      "y": 3,
      "z": 1,
      "name": "Wood_Goldenwood_Planks"
    },
    {
      "x": -4,
      "y": 4,
      "z": 1,
      "name": "Furniture_Human_Ruins_Bed",
      "filler": 1023,
      "rotation": 2
    },
    {
      "x": -4,
      "y": 5,
      "z": 1,
      "name": "Furniture_Human_Ruins_Bed",
      "filler": 2047,
      "rotation": 2
    },
    {
      "x": -4,
      "y": 8,
      "z": 1,
      "name": "Wood_Hardwood_Planks"
    },
    {
      "x": -4,
      "y": 10,
      "z": 1,
      "name": "Wood_Hardwood_Roof_Hollow"
    },
    {
      "x": -4,
      "y": -3,
      "z": 2,
      "name": "Rock_Basalt_Brick"
    },
    {
      "x": -4,
      "y": -2,
      "z": 2,
      "name": "Rock_Basalt"
    },
    {
      "x": -4,
      "y": -1,
      "z": 2,
      "name": "Empty"
    },
    {
      "x": -4,
      "y": 0,
      "z": 2,
      "name": "Empty"
    },
    {
      "x": -4,
      "y": 1,
      "z": 2,
      "name": "Empty"
    },
    {
      "x": -4,
      "y": 2,
      "z": 2,
      "name": "Empty"
    },
    {
      "x": -4,
      "y": 3,
      "z": 2,
      "name": "Wood_Goldenwood_Planks"
    },
    {
      "x": -4,
      "y": 4,
      "z": 2,
      "name": "Furniture_Human_Ruins_Bed",
      "filler": 31,
      "rotation": 2
    },
    {
      "x": -4,
      "y": 5,
      "z": 2,
      "name": "Furniture_Human_Ruins_Bed",
      "filler": 1055,
      "rotation": 2
    },
    {
      "x": -4,
      "y": 7,
      "z": 2,
      "name": "Wood_Goldenwood_Planks_Half",
      "rotation": 6
    },
    {
      "x": -4,
      "y": 8,
      "z": 2,
      "name": "Wood_Hardwood_Planks"
    },
    {
      "x": -4,
      "y": 9,
      "z": 2,
      "name": "Wood_Hardwood_Roof"
    },
    {
      "x": -4,
      "y": -1,
      "z": 3,
      "name": "Rock_Basalt_Brick"
    },
    {
      "x": -4,
      "y": 0,
      "z": 3,
      "name": "Rock_Basalt_Brick"
    },
    {
      "x": -4,
      "y": 1,
      "z": 3,
      "name": "Rock_Basalt_Brick"
    },
    {
      "x": -4,
      "y": 2,
      "z": 3,
      "name": "Rock_Basalt_Brick"
    },
    {
      "x": -4,
      "y": 3,
      "z": 3,
      "name": "Wood_Goldenwood_Planks"
    },
    {
      "x": -4,
      "y": 4,
      "z": 3,
      "name": "Wood_Goldenwood_Planks"
    },
    {
      "x": -4,
      "y": 5,
      "z": 3,
      "name": "Wood_Goldenwood_Planks"
    },
    {
      "x": -4,
      "y": 6,
      "z": 3,
      "name": "Wood_Sallow_Trunk",
      "support": 15,
      "rotation": 5
    },
    {
      "x": -4,
      "y": 7,
      "z": 3,
      "name": "Wood_Hardwood_Planks"
    },
    {
      "x": -4,
      "y": 8,
      "z": 3,
      "name": "Wood_Hardwood_Roof"
    },
    {
      "x": -4,
      "y": 7,
      "z": 4,
      "name": "Wood_Hardwood_Roof_Hollow"
    },
    {
      "x": -3,
      "y": 7,
      "z": -6,
      "name": "Wood_Hardwood_Roof_Hollow",
      "rotation": 2
    },
    {
      "x": -3,
      "y": -3,
      "z": -5,
      "name": "Rock_Basalt_Brick"
    },
    {
      "x": -3,
      "y": -2,
      "z": -5,
      "name": "Rock_Basalt_Brick"
    },
    {
      "x": -3,
      "y": -1,
      "z": -5,
      "name": "Rock_Basalt_Brick"
    },
    {
      "x": -3,
      "y": 0,
      "z": -5,
      "name": "Rock_Basalt_Brick"
    },
    {
      "x": -3,
      "y": 1,
      "z": -5,
      "name": "Rock_Basalt_Brick"
    },
    {
      "x": -3,
      "y": 2,
      "z": -5,
      "name": "Rock_Basalt_Brick"
    },
    {
      "x": -3,
      "y": 3,
      "z": -5,
      "name": "Wood_Goldenwood_Planks"
    },
    {
      "x": -3,
      "y": 4,
      "z": -5,
      "name": "Wood_Goldenwood_Planks"
    },
    {
      "x": -3,
      "y": 5,
      "z": -5,
      "name": "Wood_Hardwood_Fence",
      "rotation": 2
    },
    {
      "x": -3,
      "y": 6,
      "z": -5,
      "name": "Wood_Sallow_Trunk",
      "support": 15,
      "rotation": 5
    },
    {
      "x": -3,
      "y": 7,
      "z": -5,
      "name": "Wood_Hardwood_Planks"
    },
    {
      "x": -3,
      "y": 8,
      "z": -5,
      "name": "Wood_Hardwood_Roof",
      "rotation": 2
    },
    {
      "x": -3,
      "y": -3,
      "z": -4,
      "name": "Rock_Basalt_Brick"
    },
    {
      "x": -3,
      "y": -2,
      "z": -4,
      "name": "Rock_Basalt"
    },
    {
      "x": -3,
      "y": -1,
      "z": -4,
      "name": "Furniture_Human_Ruins_Pot_Small"
    },
    {
      "x": -3,
      "y": 0,
      "z": -4,
      "name": "Empty"
    },
    {
      "x": -3,
      "y": 1,
      "z": -4,
      "name": "Empty"
    },
    {
      "x": -3,
      "y": 2,
      "z": -4,
      "name": "Empty"
    },
    {
      "x": -3,
      "y": 3,
      "z": -4,
      "name": "Wood_Goldenwood_Planks"
    },
    {
      "x": -3,
      "y": 7,
      "z": -4,
      "name": "Wood_Goldenwood_Planks_Half",
      "rotation": 4
    },
    {
      "x": -3,
      "y": 8,
      "z": -4,
      "name": "Wood_Hardwood_Planks"
    },
    {
      "x": -3,
      "y": 9,
      "z": -4,
      "name": "Wood_Hardwood_Beam",
      "rotation": 5
    },
    {
      "x": -3,
      "y": -3,
      "z": -3,
      "name": "Rock_Basalt_Brick"
    },
    {
      "x": -3,
      "y": -2,
      "z": -3,
      "name": "Rock_Basalt_Cobble"
    },
    {
      "x": -3,
      "y": -1,
      "z": -3,
      "name": "Empty"
    },
    {
      "x": -3,
      "y": 0,
      "z": -3,
      "name": "Empty"
    },
    {
      "x": -3,
      "y": 1,
      "z": -3,
      "name": "Empty"
    },
    {
      "x": -3,
      "y": 2,
      "z": -3,
      "name": "Empty"
    },
    {
      "x": -3,
      "y": 3,
      "z": -3,
      "name": "Wood_Goldenwood_Planks"
    },
    {
      "x": -3,
      "y": 8,
      "z": -3,
      "name": "Wood_Hardwood_Planks"
    },
    {
      "x": -3,
      "y": 10,
      "z": -3,
      "name": "Wood_Hardwood_Roof_Hollow",
      "rotation": 2
    },
    {
      "x": -3,
      "y": -3,
      "z": -2,
      "name": "Rock_Basalt_Brick"
    },
    {
      "x": -3,
      "y": -2,
      "z": -2,
      "name": "Rock_Basalt"
    },
    {
      "x": -3,
      "y": -1,
      "z": -2,
      "name": "Empty"
    },
    {
      "x": -3,
      "y": 0,
      "z": -2,
      "name": "Empty"
    },
    {
      "x": -3,
      "y": 1,
      "z": -2,
      "name": "Empty"
    },
    {
      "x": -3,
      "y": 3,
      "z": -2,
      "name": "Wood_Goldenwood_Planks"
    },
    {
      "x": -3,
      "y": 8,
      "z": -2,
      "name": "Wood_Hardwood_Planks"
    },
    {
      "x": -3,
      "y": 11,
      "z": -2,
      "name": "Wood_Hardwood_Roof_Hollow",
      "rotation": 2
    },
    {
      "x": -3,
      "y": -3,
      "z": -1,
      "name": "Rock_Basalt_Brick"
    },
    {
      "x": -3,
      "y": -2,
      "z": -1,
      "name": "Rock_Basalt"
    },
    {
      "x": -3,
      "y": -1,
      "z": -1,
      "name": "Empty"
    },
    {
      "x": -3,
      "y": 0,
      "z": -1,
      "name": "Empty"
    },
    {
      "x": -3,
      "y": 1,
      "z": -1,
      "name": "Empty"
    },
    {
      "x": -3,
      "y": 3,
      "z": -1,
      "name": "Empty"
    },
    {
      "x": -3,
      "y": 8,
      "z": -1,
      "name": "Wood_Hardwood_Planks"
    },
    {
      "x": -3,
      "y": 11,
      "z": -1,
      "name": "Wood_Hardwood_Roof_Hollow"
    },
    {
      "x": -3,
      "y": -3,
      "z": 0,
      "name": "Rock_Basalt_Brick"
    },
    {
      "x": -3,
      "y": -2,
      "z": 0,
      "name": "Rock_Basalt"
    },
    {
      "x": -3,
      "y": -1,
      "z": 0,
      "name": "Empty"
    },
    {
      "x": -3,
      "y": 0,
      "z": 0,
      "name": "Empty"
    },
    {
      "x": -3,
      "y": 1,
      "z": 0,
      "name": "Empty"
    },
    {
      "x": -3,
      "y": 2,
      "z": 0,
      "name": "Empty"
    },
    {
      "x": -3,
      "y": 3,
      "z": 0,
      "name": "Wood_Goldenwood_Planks"
    },
    {
      "x": -3,
      "y": 4,
      "z": 0,
      "name": "Furniture_Human_Ruins_Bed",
      "filler": 960,
      "rotation": 2
    },
    {
      "x": -3,
      "y": 5,
      "z": 0,
      "name": "Furniture_Human_Ruins_Bed",
      "filler": 1984,
      "rotation": 2
    },
    {
      "x": -3,
      "y": 8,
      "z": 0,
      "name": "Wood_Hardwood_Planks"
    },
    {
      "x": -3,
      "y": 11,
      "z": 0,
      "name": "Wood_Hardwood_Roof_Flat",
      "rotation": 3
    },
    {
      "x": -3,
      "y": -3,
      "z": 1,
      "name": "Rock_Basalt_Brick"
    },
    {
      "x": -3,
      "y": -2,
      "z": 1,
      "name": "Rock_Basalt"
    },
    {
      "x": -3,
      "y": -1,
      "z": 1,
      "name": "Empty"
    },
    {
      "x": -3,
      "y": 0,
      "z": 1,
      "name": "Empty"
    },
    {
      "x": -3,
      "y": 1,
      "z": 1,
      "name": "Empty"
    },
    {
      "x": -3,
      "y": 2,
      "z": 1,
      "name": "Empty"
    },
    {
      "x": -3,
      "y": 3,
      "z": 1,
      "name": "Wood_Goldenwood_Planks"
    },
    {
      "x": -3,
      "y": 4,
      "z": 1,
      "name": "Furniture_Human_Ruins_Bed",
      "filler": 992,
      "rotation": 2
    },
    {
      "x": -3,
      "y": 5,
      "z": 1,
      "name": "Furniture_Human_Ruins_Bed",
      "filler": 2016,
      "rotation": 2
    },
    {
      "x": -3,
      "y": 8,
      "z": 1,
      "name": "Wood_Hardwood_Planks"
    },
    {
      "x": -3,
      "y": 10,
      "z": 1,
      "name": "Wood_Hardwood_Roof_Hollow"
    },
    {
      "x": -3,
      "y": -3,
      "z": 2,
      "name": "Rock_Basalt_Brick"
    },
    {
      "x": -3,
      "y": -2,
      "z": 2,
      "name": "Rock_Basalt"
    },
    {
      "x": -3,
      "y": -1,
      "z": 2,
      "name": "Empty"
    },
    {
      "x": -3,
      "y": 0,
      "z": 2,
      "name": "Empty"
    },
    {
      "x": -3,
      "y": 1,
      "z": 2,
      "name": "Empty"
    },
    {
      "x": -3,
      "y": 2,
      "z": 2,
      "name": "Empty"
    },
    {
      "x": -3,
      "y": 3,
      "z": 2,
      "name": "Wood_Goldenwood_Planks"
    },
    {
      "x": -3,
      "y": 4,
      "z": 2,
      "name": "Furniture_Human_Ruins_Bed",
      "components": {
        "Components": {
          "PlacedByInteraction": {
            "WhoPlacedUuid": {
              "$binary": "5RPZJ2uQSJ2g+KZxfjqR+g==",
              "$type": "04"
            }
          },
          "RespawnBlock": {}
        }
      },
      "rotation": 2
    },
    {
      "x": -3,
      "y": 5,
      "z": 2,
      "name": "Furniture_Human_Ruins_Bed",
      "filler": 1024,
      "rotation": 2
    },
    {
      "x": -3,
      "y": 7,
      "z": 2,
      "name": "Wood_Goldenwood_Planks_Half",
      "rotation": 6
    },
    {
      "x": -3,
      "y": 8,
      "z": 2,
      "name": "Wood_Hardwood_Planks"
    },
    {
      "x": -3,
      "y": 9,
      "z": 2,
      "name": "Wood_Hardwood_Roof"
    },
    {
      "x": -3,
      "y": -1,
      "z": 3,
      "name": "Rock_Basalt_Brick"
    },
    {
      "x": -3,
      "y": 0,
      "z": 3,
      "name": "Rock_Basalt_Brick"
    },
    {
      "x": -3,
      "y": 1,
      "z": 3,
      "name": "Rock_Basalt_Brick"
    },
    {
      "x": -3,
      "y": 2,
      "z": 3,
      "name": "Rock_Basalt_Brick"
    },
    {
      "x": -3,
      "y": 3,
      "z": 3,
      "name": "Wood_Goldenwood_Planks"
    },
    {
      "x": -3,
      "y": 4,
      "z": 3,
      "name": "Wood_Goldenwood_Planks"
    },
    {
      "x": -3,
      "y": 5,
      "z": 3,
      "name": "Wood_Goldenwood_Planks"
    },
    {
      "x": -3,
      "y": 6,
      "z": 3,
      "name": "Wood_Sallow_Trunk",
      "support": 15,
      "rotation": 5
    },
    {
      "x": -3,
      "y": 7,
      "z": 3,
      "name": "Wood_Hardwood_Planks"
    },
    {
      "x": -3,
      "y": 8,
      "z": 3,
      "name": "Wood_Hardwood_Roof"
    },
    {
      "x": -3,
      "y": 7,
      "z": 4,
      "name": "Wood_Hardwood_Roof_Hollow"
    },
    {
      "x": -2,
      "y": 7,
      "z": -6,
      "name": "Wood_Hardwood_Roof_Hollow",
      "rotation": 2
    },
    {
      "x": -2,
      "y": -3,
      "z": -5,
      "name": "Rock_Basalt_Brick"
    },
    {
      "x": -2,
      "y": -2,
      "z": -5,
      "name": "Rock_Basalt_Brick"
    },
    {
      "x": -2,
      "y": -1,
      "z": -5,
      "name": "Rock_Basalt_Brick"
    },
    {
      "x": -2,
      "y": 0,
      "z": -5,
      "name": "Rock_Basalt_Cobble"
    },
    {
      "x": -2,
      "y": 1,
      "z": -5,
      "name": "Rock_Basalt_Brick"
    },
    {
      "x": -2,
      "y": 2,
      "z": -5,
      "name": "Rock_Basalt_Brick"
    },
    {
      "x": -2,
      "y": 3,
      "z": -5,
      "name": "Wood_Goldenwood_Planks"
    },
    {
      "x": -2,
      "y": 4,
      "z": -5,
      "name": "Wood_Goldenwood_Planks"
    },
    {
      "x": -2,
      "y": 5,
      "z": -5,
      "name": "Wood_Hardwood_Fence",
      "rotation": 2
    },
    {
      "x": -2,
      "y": 6,
      "z": -5,
      "name": "Wood_Sallow_Trunk",
      "support": 15,
      "rotation": 5
    },
    {
      "x": -2,
      "y": 7,
      "z": -5,
      "name": "Wood_Hardwood_Planks"
    },
    {
      "x": -2,
      "y": 8,
      "z": -5,
      "name": "Wood_Hardwood_Roof",
      "rotation": 2
    },
    {
      "x": -2,
      "y": -3,
      "z": -4,
      "name": "Rock_Basalt_Brick"
    },
    {
      "x": -2,
      "y": -2,
      "z": -4,
      "name": "Rock_Basalt"
    },
    {
      "x": -2,
      "y": -1,
      "z": -4,
      "name": "Furniture_Human_Ruins_Bookshelf"
    },
    {
      "x": -2,
      "y": 0,
      "z": -4,
      "name": "Empty"
    },
    {
      "x": -2,
      "y": 1,
      "z": -4,
      "name": "Empty"
    },
    {
      "x": -2,
      "y": 2,
      "z": -4,
      "name": "Empty"
    },
    {
      "x": -2,
      "y": 3,
      "z": -4,
      "name": "Wood_Goldenwood_Planks"
    },
    {
      "x": -2,
      "y": 7,
      "z": -4,
      "name": "Wood_Goldenwood_Planks"
    },
    {
      "x": -2,
      "y": 8,
      "z": -4,
      "name": "Wood_Hardwood_Planks"
    },
    {
      "x": -2,
      "y": 9,
      "z": -4,
      "name": "Wood_Hardwood_Roof",
      "rotation": 2
    },
    {
      "x": -2,
      "y": -3,
      "z": -3,
      "name": "Rock_Basalt_Brick"
    },
    {
      "x": -2,
      "y": -2,
      "z": -3,
      "name": "Rock_Basalt"
    },
    {
      "x": -2,
      "y": -1,
      "z": -3,
      "name": "Empty"
    },
    {
      "x": -2,
      "y": 0,
      "z": -3,
      "name": "Empty"
    },
    {
      "x": -2,
      "y": 1,
      "z": -3,
      "name": "Empty"
    },
    {
      "x": -2,
      "y": 2,
      "z": -3,
      "name": "Empty"
    },
    {
      "x": -2,
      "y": 3,
      "z": -3,
      "name": "Wood_Goldenwood_Planks"
    },
    {
      "x": -2,
      "y": 7,
      "z": -3,
      "name": "Wood_Goldenwood_Planks_Half",
      "rotation": 7
    },
    {
      "x": -2,
      "y": 8,
      "z": -3,
      "name": "Wood_Hardwood_Planks"
    },
    {
      "x": -2,
      "y": 10,
      "z": -3,
      "name": "Wood_Hardwood_Roof_Hollow",
      "rotation": 2
    },
    {
      "x": -2,
      "y": -3,
      "z": -2,
      "name": "Rock_Basalt_Brick"
    },
    {
      "x": -2,
      "y": -2,
      "z": -2,
      "name": "Rock_Basalt"
    },
    {
      "x": -2,
      "y": -1,
      "z": -2,
      "name": "Empty"
    },
    {
      "x": -2,
      "y": 0,
      "z": -2,
      "name": "Empty"
    },
    {
      "x": -2,
      "y": 1,
      "z": -2,
      "name": "Empty"
    },
    {
      "x": -2,
      "y": 2,
      "z": -2,
      "name": "Empty"
    },
    {
      "x": -2,
      "y": 3,
      "z": -2,
      "name": "Wood_Goldenwood_Planks"
    },
    {
      "x": -2,
      "y": 7,
      "z": -2,
      "name": "Wood_Goldenwood_Planks_Half",
      "rotation": 7
    },
    {
      "x": -2,
      "y": 8,
      "z": -2,
      "name": "Wood_Hardwood_Planks"
    },
    {
      "x": -2,
      "y": 11,
      "z": -2,
      "name": "Wood_Hardwood_Roof_Hollow",
      "rotation": 2
    },
    {
      "x": -2,
      "y": -3,
      "z": -1,
      "name": "Rock_Basalt_Brick"
    },
    {
      "x": -2,
      "y": -2,
      "z": -1,
      "name": "Rock_Basalt"
    },
    {
      "x": -2,
      "y": -1,
      "z": -1,
      "name": "Empty"
    },
    {
      "x": -2,
      "y": 0,
      "z": -1,
      "name": "Empty"
    },
    {
      "x": -2,
      "y": 1,
      "z": -1,
      "name": "Empty"
    },
    {
      "x": -2,
      "y": 2,
      "z": -1,
      "name": "Empty"
    },
    {
      "x": -2,
      "y": 3,
      "z": -1,
      "name": "Empty"
    },
    {
      "x": -2,
      "y": 7,
      "z": -1,
      "name": "Wood_Goldenwood_Planks_Half",
      "rotation": 7
    },
    {
      "x": -2,
      "y": 8,
      "z": -1,
      "name": "Wood_Hardwood_Planks"
    },
    {
      "x": -2,
      "y": 11,
      "z": -1,
      "name": "Wood_Hardwood_Roof_Hollow"
    },
    {
      "x": -2,
      "y": -3,
      "z": 0,
      "name": "Rock_Basalt_Brick"
    },
    {
      "x": -2,
      "y": -2,
      "z": 0,
      "name": "Rock_Basalt_Cobble"
    },
    {
      "x": -2,
      "y": -1,
      "z": 0,
      "name": "Empty"
    },
    {
      "x": -2,
      "y": 0,
      "z": 0,
      "name": "Empty"
    },
    {
      "x": -2,
      "y": 1,
      "z": 0,
      "name": "Empty"
    },
    {
      "x": -2,
      "y": 2,
      "z": 0,
      "name": "Empty"
    },
    {
      "x": -2,
      "y": 3,
      "z": 0,
      "name": "Empty"
    },
    {
      "x": -2,
      "y": 7,
      "z": 0,
      "name": "Wood_Goldenwood_Planks_Half",
      "rotation": 7
    },
    {
      "x": -2,
      "y": 8,
      "z": 0,
      "name": "Wood_Hardwood_Planks"
    },
    {
      "x": -2,
      "y": 11,
      "z": 0,
      "name": "Wood_Hardwood_Roof_Flat",
      "rotation": 3
    },
    {
      "x": -2,
      "y": -3,
      "z": 1,
      "name": "Rock_Basalt_Brick"
    },
    {
      "x": -2,
      "y": -2,
      "z": 1,
      "name": "Rock_Basalt_Cobble"
    },
    {
      "x": -2,
      "y": -1,
      "z": 1,
      "name": "Empty"
    },
    {
      "x": -2,
      "y": 0,
      "z": 1,
      "name": "Empty"
    },
    {
      "x": -2,
      "y": 1,
      "z": 1,
      "name": "Empty"
    },
    {
      "x": -2,
      "y": 2,
      "z": 1,
      "name": "Empty"
    },
    {
      "x": -2,
      "y": 3,
      "z": 1,
      "name": "Wood_Goldenwood_Planks"
    },
    {
      "x": -2,
      "y": 7,
      "z": 1,
      "name": "Wood_Goldenwood_Planks_Half",
      "rotation": 7
    },
    {
      "x": -2,
      "y": 8,
      "z": 1,
      "name": "Wood_Hardwood_Planks"
    },
    {
      "x": -2,
      "y": 10,
      "z": 1,
      "name": "Wood_Hardwood_Roof_Hollow"
    },
    {
      "x": -2,
      "y": -3,
      "z": 2,
      "name": "Rock_Basalt_Brick"
    },
    {
      "x": -2,
      "y": -2,
      "z": 2,
      "name": "Rock_Basalt_Cobble"
    },
    {
      "x": -2,
      "y": -1,
      "z": 2,
      "name": "Rock_Basalt_Cobble"
    },
    {
      "x": -2,
      "y": 0,
      "z": 2,
      "name": "Empty"
    },
    {
      "x": -2,
      "y": 1,
      "z": 2,
      "name": "Empty"
    },
    {
      "x": -2,
      "y": 2,
      "z": 2,
      "name": "Empty"
    },
    {
      "x": -2,
      "y": 3,
      "z": 2,
      "name": "Wood_Goldenwood_Planks"
    },
    {
      "x": -2,
      "y": 4,
      "z": 2,
      "name": "Furniture_Human_Ruins_Bookshelf",
      "rotation": 2
    },
    {
      "x": -2,
      "y": 5,
      "z": 2,
      "name": "Furniture_Human_Ruins_Bookshelf",
      "rotation": 2
    },
    {
      "x": -2,
      "y": 6,
      "z": 2,
      "name": "Furniture_Human_Ruins_Bookshelf",
      "rotation": 2
    },
    {
      "x": -2,
      "y": 7,
      "z": 2,
      "name": "Wood_Goldenwood_Planks"
    },
    {
      "x": -2,
      "y": 8,
      "z": 2,
      "name": "Wood_Hardwood_Planks"
    },
    {
      "x": -2,
      "y": 9,
      "z": 2,
      "name": "Wood_Hardwood_Roof"
    },
    {
      "x": -2,
      "y": -2,
      "z": 3,
      "name": "Rock_Basalt_Cobble"
    },
    {
      "x": -2,
      "y": -1,
      "z": 3,
      "name": "Rock_Basalt_Cobble"
    },
    {
      "x": -2,
      "y": 0,
      "z": 3,
      "name": "Rock_Basalt_Brick"
    },
    {
      "x": -2,
      "y": 1,
      "z": 3,
      "name": "Rock_Basalt_Brick"
    },
    {
      "x": -2,
      "y": 2,
      "z": 3,
      "name": "Rock_Basalt_Brick"
    },
    {
      "x": -2,
      "y": 3,
      "z": 3,
      "name": "Wood_Goldenwood_Planks"
    },
    {
      "x": -2,
      "y": 4,
      "z": 3,
      "name": "Wood_Goldenwood_Planks"
    },
    {
      "x": -2,
      "y": 5,
      "z": 3,
      "name": "Wood_Goldenwood_Planks"
    },
    {
      "x": -2,
      "y": 6,
      "z": 3,
      "name": "Wood_Sallow_Trunk",
      "support": 15,
      "rotation": 5
    },
    {
      "x": -2,
      "y": 7,
      "z": 3,
      "name": "Wood_Hardwood_Planks"
    },
    {
      "x": -2,
      "y": 8,
      "z": 3,
      "name": "Wood_Hardwood_Roof"
    },
    {
      "x": -2,
      "y": 7,
      "z": 4,
      "name": "*Wood_Hardwood_Roof_Hollow_State_Definitions_Inverted_Corner_Left",
      "rotation": 3
    },
    {
      "x": -2,
      "y": 7,
      "z": 5,
      "name": "Wood_Hardwood_Roof_Hollow",
      "rotation": 3
    },
    {
      "x": -2,
      "y": 7,
      "z": 6,
      "name": "Wood_Hardwood_Roof_Hollow",
      "rotation": 3
    },
    {
      "x": -2,
      "y": 7,
      "z": 7,
      "name": "Wood_Hardwood_Roof_Hollow",
      "rotation": 3
    },
    {
      "x": -2,
      "y": 7,
      "z": 8,
      "name": "Wood_Hardwood_Roof_Hollow",
      "rotation": 3
    },
    {
      "x": -1,
      "y": 7,
      "z": -6,
      "name": "Wood_Hardwood_Roof_Hollow",
      "rotation": 2
    },
    {
      "x": -1,
      "y": -3,
      "z": -5,
      "name": "Rock_Basalt_Brick"
    },
    {
      "x": -1,
      "y": -2,
      "z": -5,
      "name": "Rock_Basalt_Brick"
    },
    {
      "x": -1,
      "y": -1,
      "z": -5,
      "name": "Rock_Basalt_Brick"
    },
    {
      "x": -1,
      "y": 0,
      "z": -5,
      "name": "Rock_Basalt_Cobble"
    },
    {
      "x": -1,
      "y": 1,
      "z": -5,
      "name": "Rock_Basalt_Cobble"
    },
    {
      "x": -1,
      "y": 2,
      "z": -5,
      "name": "Rock_Basalt_Brick"
    },
    {
      "x": -1,
      "y": 3,
      "z": -5,
      "name": "Wood_Goldenwood_Planks"
    },
    {
      "x": -1,
      "y": 4,
      "z": -5,
      "name": "Wood_Goldenwood_Planks"
    },
    {
      "x": -1,
      "y": 5,
      "z": -5,
      "name": "Wood_Goldenwood_Planks"
    },
    {
      "x": -1,
      "y": 6,
      "z": -5,
      "name": "Wood_Sallow_Trunk",
      "support": 15,
      "rotation": 5
    },
    {
      "x": -1,
      "y": 7,
      "z": -5,
      "name": "Wood_Hardwood_Planks"
    },
    {
      "x": -1,
      "y": 8,
      "z": -5,
      "name": "Wood_Hardwood_Roof",
      "rotation": 2
    },
    {
      "x": -1,
      "y": -3,
      "z": -4,
      "name": "Rock_Basalt_Brick"
    },
    {
      "x": -1,
      "y": -2,
      "z": -4,
      "name": "Rock_Basalt"
    },
    {
      "x": -1,
      "y": -1,
      "z": -4,
      "name": "Furniture_Human_Ruins_Bookshelf"
    },
    {
      "x": -1,
      "y": 0,
      "z": -4,
      "name": "Furniture_Human_Ruins_Bookshelf"
    },
    {
      "x": -1,
      "y": 1,
      "z": -4,
      "name": "Empty"
    },
    {
      "x": -1,
      "y": 2,
      "z": -4,
      "name": "Empty"
    },
    {
      "x": -1,
      "y": 3,
      "z": -4,
      "name": "Wood_Goldenwood_Planks"
    },
    {
      "x": -1,
      "y": 4,
      "z": -4,
      "name": "*Furniture_Ancient_Door_State_Definitions_CloseDoorOut",
      "rotation": 3
    },
    {
      "x": -1,
      "y": 5,
      "z": -4,
      "name": "*Furniture_Ancient_Door_State_Definitions_CloseDoorOut",
      "filler": 1024,
      "rotation": 3
    },
    {
      "x": -1,
      "y": 6,
      "z": -4,
      "name": "Wood_Goldenwood_Planks"
    },
    {
      "x": -1,
      "y": 7,
      "z": -4,
      "name": "Wood_Hardwood_Planks"
    },
    {
      "x": -1,
      "y": 8,
      "z": -4,
      "name": "Wood_Hardwood_Planks"
    },
    {
      "x": -1,
      "y": 9,
      "z": -4,
      "name": "Wood_Hardwood_Roof",
      "rotation": 2
    },
    {
      "x": -1,
      "y": -3,
      "z": -3,
      "name": "Rock_Basalt_Brick"
    },
    {
      "x": -1,
      "y": -2,
      "z": -3,
      "name": "Rock_Basalt"
    },
    {
      "x": -1,
      "y": -1,
      "z": -3,
      "name": "Empty"
    },
    {
      "x": -1,
      "y": 0,
      "z": -3,
      "name": "Empty"
    },
    {
      "x": -1,
      "y": 1,
      "z": -3,
      "name": "Empty"
    },
    {
      "x": -1,
      "y": 2,
      "z": -3,
      "name": "Empty"
    },
    {
      "x": -1,
      "y": 3,
      "z": -3,
      "name": "Wood_Goldenwood_Planks"
    },
    {
      "x": -1,
      "y": 4,
      "z": -3,
      "name": "Wood_Goldenwood_Planks"
    },
    {
      "x": -1,
      "y": 5,
      "z": -3,
      "name": "Wood_Goldenwood_Planks"
    },
    {
      "x": -1,
      "y": 6,
      "z": -3,
      "name": "Wood_Goldenwood_Planks"
    },
    {
      "x": -1,
      "y": 7,
      "z": -3,
      "name": "Wood_Hardwood_Planks"
    },
    {
      "x": -1,
      "y": 8,
      "z": -3,
      "name": "Wood_Hardwood_Planks"
    },
    {
      "x": -1,
      "y": 10,
      "z": -3,
      "name": "Wood_Hardwood_Roof_Hollow",
      "rotation": 2
    },
    {
      "x": -1,
      "y": -3,
      "z": -2,
      "name": "Rock_Basalt_Brick"
    },
    {
      "x": -1,
      "y": -2,
      "z": -2,
      "name": "Rock_Basalt"
    },
    {
      "x": -1,
      "y": -1,
      "z": -2,
      "name": "Empty"
    },
    {
      "x": -1,
      "y": 0,
      "z": -2,
      "name": "Empty"
    },
    {
      "x": -1,
      "y": 1,
      "z": -2,
      "name": "Empty"
    },
    {
      "x": -1,
      "y": 2,
      "z": -2,
      "name": "Empty"
    },
    {
      "x": -1,
      "y": 3,
      "z": -2,
      "name": "Wood_Goldenwood_Planks"
    },
    {
      "x": -1,
      "y": 4,
      "z": -2,
      "name": "Wood_Goldenwood_Planks"
    },
    {
      "x": -1,
      "y": 5,
      "z": -2,
      "name": "Wood_Goldenwood_Planks"
    },
    {
      "x": -1,
      "y": 6,
      "z": -2,
      "name": "Wood_Goldenwood_Planks"
    },
    {
      "x": -1,
      "y": 7,
      "z": -2,
      "name": "Wood_Hardwood_Planks"
    },
    {
      "x": -1,
      "y": 8,
      "z": -2,
      "name": "Wood_Hardwood_Planks"
    },
    {
      "x": -1,
      "y": 11,
      "z": -2,
      "name": "Wood_Hardwood_Roof_Hollow",
      "rotation": 2
    },
    {
      "x": -1,
      "y": -3,
      "z": -1,
      "name": "Rock_Basalt_Brick"
    },
    {
      "x": -1,
      "y": -2,
      "z": -1,
      "name": "Rock_Basalt"
    },
    {
      "x": -1,
      "y": -1,
      "z": -1,
      "name": "Empty"
    },
    {
      "x": -1,
      "y": 0,
      "z": -1,
      "name": "Empty"
    },
    {
      "x": -1,
      "y": 1,
      "z": -1,
      "name": "Empty"
    },
    {
      "x": -1,
      "y": 2,
      "z": -1,
      "name": "Empty"
    },
    {
      "x": -1,
      "y": 3,
      "z": -1,
      "name": "Wood_Goldenwood_Planks"
    },
    {
      "x": -1,
      "y": 4,
      "z": -1,
      "name": "Wood_Goldenwood_Planks"
    },
    {
      "x": -1,
      "y": 5,
      "z": -1,
      "name": "Wood_Goldenwood_Planks"
    },
    {
      "x": -1,
      "y": 6,
      "z": -1,
      "name": "Wood_Goldenwood_Planks"
    },
    {
      "x": -1,
      "y": 7,
      "z": -1,
      "name": "Wood_Hardwood_Planks"
    },
    {
      "x": -1,
      "y": 8,
      "z": -1,
      "name": "Wood_Hardwood_Planks"
    },
    {
      "x": -1,
      "y": 11,
      "z": -1,
      "name": "Wood_Hardwood_Roof_Hollow"
    },
    {
      "x": -1,
      "y": -3,
      "z": 0,
      "name": "Rock_Basalt_Cobble"
    },
    {
      "x": -1,
      "y": -2,
      "z": 0,
      "name": "Rock_Basalt_Cobble"
    },
    {
      "x": -1,
      "y": -1,
      "z": 0,
      "name": "Empty"
    },
    {
      "x": -1,
      "y": 0,
      "z": 0,
      "name": "Empty"
    },
    {
      "x": -1,
      "y": 1,
      "z": 0,
      "name": "Empty"
    },
    {
      "x": -1,
      "y": 2,
      "z": 0,
      "name": "Empty"
    },
    {
      "x": -1,
      "y": 3,
      "z": 0,
      "name": "Empty"
    },
    {
      "x": -1,
      "y": 5,
      "z": 0,
      "name": "Wood_Goldenwood_Planks"
    },
    {
      "x": -1,
      "y": 6,
      "z": 0,
      "name": "Wood_Goldenwood_Planks"
    },
    {
      "x": -1,
      "y": 7,
      "z": 0,
      "name": "Wood_Hardwood_Planks"
    },
    {
      "x": -1,
      "y": 8,
      "z": 0,
      "name": "Wood_Hardwood_Planks"
    },
    {
      "x": -1,
      "y": 11,
      "z": 0,
      "name": "Wood_Hardwood_Roof_Flat",
      "rotation": 2
    },
    {
      "x": -1,
      "y": -3,
      "z": 1,
      "name": "Rock_Basalt_Cobble"
    },
    {
      "x": -1,
      "y": -2,
      "z": 1,
      "name": "Rock_Basalt_Cobble"
    },
    {
      "x": -1,
      "y": -1,
      "z": 1,
      "name": "Empty"
    },
    {
      "x": -1,
      "y": 0,
      "z": 1,
      "name": "Empty"
    },
    {
      "x": -1,
      "y": 1,
      "z": 1,
      "name": "Empty"
    },
    {
      "x": -1,
      "y": 2,
      "z": 1,
      "name": "Empty"
    },
    {
      "x": -1,
      "y": 3,
      "z": 1,
      "name": "Wood_Goldenwood_Planks"
    },
    {
      "x": -1,
      "y": 4,
      "z": 1,
      "name": "Wood_Goldenwood_Planks"
    },
    {
      "x": -1,
      "y": 5,
      "z": 1,
      "name": "Wood_Goldenwood_Planks"
    },
    {
      "x": -1,
      "y": 6,
      "z": 1,
      "name": "Wood_Goldenwood_Planks"
    },
    {
      "x": -1,
      "y": 7,
      "z": 1,
      "name": "Wood_Hardwood_Planks"
    },
    {
      "x": -1,
      "y": 8,
      "z": 1,
      "name": "Wood_Hardwood_Planks"
    },
    {
      "x": -1,
      "y": 10,
      "z": 1,
      "name": "Wood_Hardwood_Roof_Hollow"
    },
    {
      "x": -1,
      "y": -3,
      "z": 2,
      "name": "Rock_Basalt_Brick"
    },
    {
      "x": -1,
      "y": -2,
      "z": 2,
      "name": "Rock_Basalt"
    },
    {
      "x": -1,
      "y": -1,
      "z": 2,
      "name": "Bench_Alchemy",
      "components": {
        "Components": {
          "PlacedByInteraction": {
            "WhoPlacedUuid": {
              "$binary": "5RPZJ2uQSJ2g+KZxfjqR+g==",
              "$type": "04"
            }
          },
          "crafting": {
            "TierLevel": 1,
            "UpgradeItems": []
          }
        }
      },
      "rotation": 2
    },
    {
      "x": -1,
      "y": 0,
      "z": 2,
      "name": "Bench_Alchemy",
      "filler": 1024,
      "rotation": 2
    },
    {
      "x": -1,
      "y": 1,
      "z": 2,
      "name": "Empty"
    },
    {
      "x": -1,
      "y": 2,
      "z": 2,
      "name": "Empty"
    },
    {
      "x": -1,
      "y": 3,
      "z": 2,
      "name": "Wood_Goldenwood_Planks"
    },
    {
      "x": -1,
      "y": 4,
      "z": 2,
      "name": "Wood_Goldenwood_Planks"
    },
    {
      "x": -1,
      "y": 5,
      "z": 2,
      "name": "Wood_Goldenwood_Planks"
    },
    {
      "x": -1,
      "y": 6,
      "z": 2,
      "name": "Wood_Goldenwood_Planks"
    },
    {
      "x": -1,
      "y": 7,
      "z": 2,
      "name": "Wood_Hardwood_Planks"
    },
    {
      "x": -1,
      "y": 8,
      "z": 2,
      "name": "Wood_Hardwood_Planks"
    },
    {
      "x": -1,
      "y": 9,
      "z": 2,
      "name": "Wood_Hardwood_Roof"
    },
    {
      "x": -1,
      "y": -3,
      "z": 3,
      "name": "Rock_Basalt_Brick"
    },
    {
      "x": -1,
      "y": -2,
      "z": 3,
      "name": "Rock_Basalt_Brick"
    },
    {
      "x": -1,
      "y": -1,
      "z": 3,
      "name": "Rock_Basalt_Cobble"
    },
    {
      "x": -1,
      "y": 0,
      "z": 3,
      "name": "Rock_Basalt_Brick"
    },
    {
      "x": -1,
      "y": 1,
      "z": 3,
      "name": "Rock_Basalt_Brick"
    },
    {
      "x": -1,
      "y": 2,
      "z": 3,
      "name": "Rock_Basalt_Brick"
    },
    {
      "x": -1,
      "y": 3,
      "z": 3,
      "name": "Wood_Goldenwood_Planks"
    },
    {
      "x": -1,
      "y": 4,
      "z": 3,
      "name": "Wood_Goldenwood_Planks"
    },
    {
      "x": -1,
      "y": 5,
      "z": 3,
      "name": "Wood_Goldenwood_Planks"
    },
    {
      "x": -1,
      "y": 6,
      "z": 3,
      "name": "Wood_Goldenwood_Planks"
    },
    {
      "x": -1,
      "y": 7,
      "z": 3,
      "name": "Wood_Hardwood_Planks"
    },
    {
      "x": -1,
      "y": 8,
      "z": 3,
      "name": "*Wood_Hardwood_Roof_State_Definitions_Inverted_Corner_Left",
      "rotation": 3
    },
    {
      "x": -1,
      "y": -3,
      "z": 4,
      "name": "Rock_Basalt_Brick"
    },
    {
      "x": -1,
      "y": -2,
      "z": 4,
      "name": "Rock_Basalt_Brick"
    },
    {
      "x": -1,
      "y": -1,
      "z": 4,
      "name": "Rock_Basalt_Brick"
    },
    {
      "x": -1,
      "y": 0,
      "z": 4,
      "name": "Rock_Basalt_Brick"
    },
    {
      "x": -1,
      "y": 1,
      "z": 4,
      "name": "Rock_Basalt_Brick"
    },
    {
      "x": -1,
      "y": 2,
      "z": 4,
      "name": "Rock_Basalt_Brick"
    },
    {
      "x": -1,
      "y": 3,
      "z": 4,
      "name": "Wood_Goldenwood_Planks"
    },
    {
      "x": -1,
      "y": 4,
      "z": 4,
      "name": "Wood_Goldenwood_Planks"
    },
    {
      "x": -1,
      "y": 5,
      "z": 4,
      "name": "Wood_Goldenwood_Planks"
    },
    {
      "x": -1,
      "y": 6,
      "z": 4,
      "name": "Wood_Sallow_Trunk",
      "support": 15,
      "rotation": 4
    },
    {
      "x": -1,
      "y": 7,
      "z": 4,
      "name": "Wood_Hardwood_Planks"
    },
    {
      "x": -1,
      "y": 8,
      "z": 4,
      "name": "Wood_Hardwood_Roof",
      "rotation": 3
    },
    {
      "x": -1,
      "y": -3,
      "z": 5,
      "name": "Rock_Basalt_Brick"
    },
    {
      "x": -1,
      "y": -2,
      "z": 5,
      "name": "Rock_Basalt_Brick"
    },
    {
      "x": -1,
      "y": -1,
      "z": 5,
      "name": "Rock_Basalt_Brick"
    },
    {
      "x": -1,
      "y": 0,
      "z": 5,
      "name": "Rock_Basalt_Brick"
    },
    {
      "x": -1,
      "y": 1,
      "z": 5,
      "name": "Rock_Basalt_Brick"
    },
    {
      "x": -1,
      "y": 2,
      "z": 5,
      "name": "Rock_Basalt_Brick"
    },
    {
      "x": -1,
      "y": 3,
      "z": 5,
      "name": "Wood_Goldenwood_Planks"
    },
    {
      "x": -1,
      "y": 4,
      "z": 5,
      "name": "Wood_Goldenwood_Planks"
    },
    {
      "x": -1,
      "y": 5,
      "z": 5,
      "name": "Wood_Goldenwood_Planks"
    },
    {
      "x": -1,
      "y": 6,
      "z": 5,
      "name": "Wood_Sallow_Trunk",
      "support": 15,
      "rotation": 4
    },
    {
      "x": -1,
      "y": 7,
      "z": 5,
      "name": "Wood_Hardwood_Planks"
    },
    {
      "x": -1,
      "y": 8,
      "z": 5,
      "name": "Wood_Hardwood_Roof",
      "rotation": 3
    },
    {
      "x": -1,
      "y": -3,
      "z": 6,
      "name": "Rock_Basalt_Brick"
    },
    {
      "x": -1,
      "y": -2,
      "z": 6,
      "name": "Rock_Basalt_Brick"
    },
    {
      "x": -1,
      "y": -1,
      "z": 6,
      "name": "Rock_Basalt_Brick"
    },
    {
      "x": -1,
      "y": 0,
      "z": 6,
      "name": "Rock_Basalt_Brick"
    },
    {
      "x": -1,
      "y": 1,
      "z": 6,
      "name": "Rock_Basalt_Brick"
    },
    {
      "x": -1,
      "y": 2,
      "z": 6,
      "name": "Rock_Basalt_Brick"
    },
    {
      "x": -1,
      "y": 3,
      "z": 6,
      "name": "Wood_Goldenwood_Planks"
    },
    {
      "x": -1,
      "y": 4,
      "z": 6,
      "name": "Wood_Goldenwood_Planks"
    },
    {
      "x": -1,
      "y": 5,
      "z": 6,
      "name": "Wood_Goldenwood_Planks"
    },
    {
      "x": -1,
      "y": 7,
      "z": 6,
      "name": "Wood_Hardwood_Planks"
    },
    {
      "x": -1,
      "y": 8,
      "z": 6,
      "name": "Wood_Hardwood_Roof",
      "rotation": 3
    },
    {
      "x": -1,
      "y": -3,
      "z": 7,
      "name": "Rock_Basalt_Brick"
    },
    {
      "x": -1,
      "y": -2,
      "z": 7,
      "name": "Rock_Basalt_Brick"
    },
    {
      "x": -1,
      "y": -1,
      "z": 7,
      "name": "Rock_Basalt_Brick"
    },
    {
      "x": -1,
      "y": 0,
      "z": 7,
      "name": "Rock_Basalt_Brick"
    },
    {
      "x": -1,
      "y": 1,
      "z": 7,
      "name": "Rock_Basalt_Brick"
    },
    {
      "x": -1,
      "y": 2,
      "z": 7,
      "name": "Rock_Basalt_Brick"
    },
    {
      "x": -1,
      "y": 3,
      "z": 7,
      "name": "Wood_Sallow_Trunk",
      "support": 15
    },
    {
      "x": -1,
      "y": 4,
      "z": 7,
      "name": "Wood_Sallow_Trunk",
      "support": 15
    },
    {
      "x": -1,
      "y": 5,
      "z": 7,
      "name": "Wood_Sallow_Trunk",
      "support": 15
    },
    {
      "x": -1,
      "y": 6,
      "z": 7,
      "name": "Wood_Sallow_Trunk",
      "support": 15
    },
    {
      "x": -1,
      "y": 7,
      "z": 7,
      "name": "Wood_Hardwood_Planks"
    },
    {
      "x": -1,
      "y": 8,
      "z": 7,
      "name": "Wood_Hardwood_Roof",
      "rotation": 3
    },
    {
      "x": -1,
      "y": 8,
      "z": 8,
      "name": "Wood_Hardwood_Roof_Hollow",
      "rotation": 3
    },
    {
      "x": 0,
      "y": 7,
      "z": -6,
      "name": "Wood_Hardwood_Roof_Hollow",
      "rotation": 2
    },
    {
      "x": 0,
      "y": -3,
      "z": -5,
      "name": "Rock_Basalt_Brick"
    },
    {
      "x": 0,
      "y": -2,
      "z": -5,
      "name": "Rock_Basalt_Brick"
    },
    {
      "x": 0,
      "y": -1,
      "z": -5,
      "name": "Rock_Basalt_Cobble"
    },
    {
      "x": 0,
      "y": 0,
      "z": -5,
      "name": "Rock_Basalt_Brick"
    },
    {
      "x": 0,
      "y": 1,
      "z": -5,
      "name": "Rock_Basalt_Brick"
    },
    {
      "x": 0,
      "y": 2,
      "z": -5,
      "name": "Rock_Basalt_Brick"
    },
    {
      "x": 0,
      "y": 3,
      "z": -5,
      "name": "Wood_Goldenwood_Planks"
    },
    {
      "x": 0,
      "y": 4,
      "z": -5,
      "name": "Wood_Goldenwood_Planks"
    },
    {
      "x": 0,
      "y": 5,
      "z": -5,
      "name": "Wood_Goldenwood_Planks"
    },
    {
      "x": 0,
      "y": 6,
      "z": -5,
      "name": "Wood_Sallow_Trunk",
      "support": 15,
      "rotation": 5
    },
    {
      "x": 0,
      "y": 7,
      "z": -5,
      "name": "Wood_Hardwood_Planks"
    },
    {
      "x": 0,
      "y": 8,
      "z": -5,
      "name": "Wood_Hardwood_Roof",
      "rotation": 2
    },
    {
      "x": 0,
      "y": -3,
      "z": -4,
      "name": "Rock_Basalt_Brick"
    },
    {
      "x": 0,
      "y": -2,
      "z": -4,
      "name": "Rock_Basalt"
    },
    {
      "x": 0,
      "y": -1,
      "z": -4,
      "name": "Furniture_Human_Ruins_Bookshelf"
    },
    {
      "x": 0,
      "y": 0,
      "z": -4,
      "name": "Furniture_Human_Ruins_Bookshelf"
    },
    {
      "x": 0,
      "y": 1,
      "z": -4,
      "name": "Furniture_Human_Ruins_Bookshelf"
    },
    {
      "x": 0,
      "y": 2,
      "z": -4,
      "name": "Furniture_Human_Ruins_Bookshelf"
    },
    {
      "x": 0,
      "y": 3,
      "z": -4,
      "name": "Wood_Goldenwood_Planks"
    },
    {
      "x": 0,
      "y": 7,
      "z": -4,
      "name": "Wood_Goldenwood_Planks"
    },
    {
      "x": 0,
      "y": 8,
      "z": -4,
      "name": "Wood_Hardwood_Planks"
    },
    {
      "x": 0,
      "y": 9,
      "z": -4,
      "name": "Wood_Hardwood_Roof",
      "rotation": 2
    },
    {
      "x": 0,
      "y": -3,
      "z": -3,
      "name": "Rock_Basalt_Brick"
    },
    {
      "x": 0,
      "y": -2,
      "z": -3,
      "name": "Rock_Basalt_Cobble"
    },
    {
      "x": 0,
      "y": -1,
      "z": -3,
      "name": "Empty"
    },
    {
      "x": 0,
      "y": 0,
      "z": -3,
      "name": "Empty"
    },
    {
      "x": 0,
      "y": 1,
      "z": -3,
      "name": "Empty"
    },
    {
      "x": 0,
      "y": 2,
      "z": -3,
      "name": "Empty"
    },
    {
      "x": 0,
      "y": 3,
      "z": -3,
      "name": "Wood_Goldenwood_Planks"
    },
    {
      "x": 0,
      "y": 7,
      "z": -3,
      "name": "Wood_Goldenwood_Planks_Half",
      "rotation": 5
    },
    {
      "x": 0,
      "y": 8,
      "z": -3,
      "name": "Wood_Hardwood_Planks"
    },
    {
      "x": 0,
      "y": 10,
      "z": -3,
      "name": "Wood_Hardwood_Roof_Hollow",
      "rotation": 2
    },
    {
      "x": 0,
      "y": -3,
      "z": -2,
      "name": "Rock_Basalt_Brick"
    },
    {
      "x": 0,
      "y": -2,
      "z": -2,
      "name": "Rock_Basalt"
    },
    {
      "x": 0,
      "y": -1,
      "z": -2,
      "name": "Empty"
    },
    {
      "x": 0,
      "y": 0,
      "z": -2,
      "name": "Empty"
    },
    {
      "x": 0,
      "y": 1,
      "z": -2,
      "name": "Empty"
    },
    {
      "x": 0,
      "y": 2,
      "z": -2,
      "name": "Empty"
    },
    {
      "x": 0,
      "y": 3,
      "z": -2,
      "name": "Wood_Goldenwood_Planks"
    },
    {
      "x": 0,
      "y": 7,
      "z": -2,
      "name": "Wood_Goldenwood_Planks_Half",
      "rotation": 5
    },
    {
      "x": 0,
      "y": 8,
      "z": -2,
      "name": "Wood_Hardwood_Planks"
    },
    {
      "x": 0,
      "y": 11,
      "z": -2,
      "name": "Wood_Hardwood_Roof_Hollow",
      "rotation": 2
    },
    {
      "x": 0,
      "y": -3,
      "z": -1,
      "name": "Rock_Basalt_Brick"
    },
    {
      "x": 0,
      "y": -2,
      "z": -1,
      "name": "Rock_Basalt"
    },
    {
      "x": 0,
      "y": -1,
      "z": -1,
      "name": "Empty"
    },
    {
      "x": 0,
      "y": 0,
      "z": -1,
      "name": "Empty"
    },
    {
      "x": 0,
      "y": 1,
      "z": -1,
      "name": "Empty"
    },
    {
      "x": 0,
      "y": 2,
      "z": -1,
      "name": "Empty"
    },
    {
      "x": 0,
      "y": 3,
      "z": -1,
      "name": "Wood_Hardwood_Beam",
      "rotation": 5
    },
    {
      "x": 0,
      "y": 7,
      "z": -1,
      "name": "Wood_Goldenwood_Planks_Half",
      "rotation": 5
    },
    {
      "x": 0,
      "y": 8,
      "z": -1,
      "name": "Wood_Hardwood_Planks"
    },
    {
      "x": 0,
      "y": 11,
      "z": -1,
      "name": "Wood_Hardwood_Roof_Hollow"
    },
    {
      "x": 0,
      "y": -3,
      "z": 0,
      "name": "Rock_Basalt_Brick"
    },
    {
      "x": 0,
      "y": -2,
      "z": 0,
      "name": "Rock_Basalt"
    },
    {
      "x": 0,
      "y": -1,
      "z": 0,
      "name": "Empty"
    },
    {
      "x": 0,
      "y": 0,
      "z": 0,
      "name": "Empty"
    },
    {
      "x": 0,
      "y": 1,
      "z": 0,
      "name": "Empty"
    },
    {
      "x": 0,
      "y": 2,
      "z": 0,
      "name": "Empty"
    },
    {
      "x": 0,
      "y": 3,
      "z": 0,
      "name": "Wood_Goldenwood_Stairs",
      "rotation": 11
    },
    {
      "x": 0,
      "y": 7,
      "z": 0,
      "name": "Wood_Goldenwood_Planks_Half",
      "rotation": 5
    },
    {
      "x": 0,
      "y": 8,
      "z": 0,
      "name": "Wood_Hardwood_Planks"
    },
    {
      "x": 0,
      "y": 11,
      "z": 0,
      "name": "Wood_Hardwood_Roof_Flat",
      "rotation": 3
    },
    {
      "x": 0,
      "y": -3,
      "z": 1,
      "name": "Rock_Basalt_Brick"
    },
    {
      "x": 0,
      "y": -2,
      "z": 1,
      "name": "Rock_Basalt"
    },
    {
      "x": 0,
      "y": -1,
      "z": 1,
      "name": "Empty"
    },
    {
      "x": 0,
      "y": 0,
      "z": 1,
      "name": "Empty"
    },
    {
      "x": 0,
      "y": 1,
      "z": 1,
      "name": "Empty"
    },
    {
      "x": 0,
      "y": 2,
      "z": 1,
      "name": "Empty"
    },
    {
      "x": 0,
      "y": 3,
      "z": 1,
      "name": "Wood_Hardwood_Beam",
      "rotation": 5
    },
    {
      "x": 0,
      "y": 7,
      "z": 1,
      "name": "Wood_Goldenwood_Planks_Half",
      "rotation": 5
    },
    {
      "x": 0,
      "y": 8,
      "z": 1,
      "name": "Wood_Hardwood_Planks"
    },
    {
      "x": 0,
      "y": 10,
      "z": 1,
      "name": "Wood_Hardwood_Roof_Hollow"
    },
    {
      "x": 0,
      "y": -3,
      "z": 2,
      "name": "Rock_Basalt_Brick"
    },
    {
      "x": 0,
      "y": -2,
      "z": 2,
      "name": "Rock_Basalt"
    },
    {
      "x": 0,
      "y": -1,
      "z": 2,
      "name": "Bench_Alchemy",
      "filler": 1,
      "rotation": 2
    },
    {
      "x": 0,
      "y": 0,
      "z": 2,
      "name": "Bench_Alchemy",
      "filler": 1025,
      "rotation": 2
    },
    {
      "x": 0,
      "y": 1,
      "z": 2,
      "name": "Empty"
    },
    {
      "x": 0,
      "y": 2,
      "z": 2,
      "name": "Empty"
    },
    {
      "x": 0,
      "y": 3,
      "z": 2,
      "name": "Wood_Goldenwood_Planks"
    },
    {
      "x": 0,
      "y": 4,
      "z": 2,
      "name": "Furniture_Human_Ruins_Shelf",
      "rotation": 2
    },
    {
      "x": 0,
      "y": 5,
      "z": 2,
      "name": "Furniture_Human_Ruins_Candle"
    },
    {
      "x": 0,
      "y": 6,
      "z": 2,
      "name": "Furniture_Human_Ruins_Candle",
      "filler": 1024
    },
    {
      "x": 0,
      "y": 7,
      "z": 2,
      "name": "Wood_Goldenwood_Planks_Half",
      "rotation": 5
    },
    {
      "x": 0,
      "y": 8,
      "z": 2,
      "name": "Wood_Hardwood_Planks"
    },
    {
      "x": 0,
      "y": 9,
      "z": 2,
      "name": "Wood_Hardwood_Roof"
    },
    {
      "x": 0,
      "y": -3,
      "z": 3,
      "name": "Rock_Basalt_Brick"
    },
    {
      "x": 0,
      "y": -2,
      "z": 3,
      "name": "Rock_Basalt_Brick"
    },
    {
      "x": 0,
      "y": -1,
      "z": 3,
      "name": "Rock_Basalt_Cobble"
    },
    {
      "x": 0,
      "y": 0,
      "z": 3,
      "name": "Rock_Basalt_Brick"
    },
    {
      "x": 0,
      "y": 1,
      "z": 3,
      "name": "Rock_Basalt_Brick"
    },
    {
      "x": 0,
      "y": 2,
      "z": 3,
      "name": "Rock_Basalt_Brick"
    },
    {
      "x": 0,
      "y": 3,
      "z": 3,
      "name": "Wood_Goldenwood_Planks"
    },
    {
      "x": 0,
      "y": 4,
      "z": 3,
      "name": "Wood_Goldenwood_Planks"
    },
    {
      "x": 0,
      "y": 5,
      "z": 3,
      "name": "Wood_Goldenwood_Planks"
    },
    {
      "x": 0,
      "y": 6,
      "z": 3,
      "name": "Wood_Goldenwood_Planks"
    },
    {
      "x": 0,
      "y": 7,
      "z": 3,
      "name": "Wood_Goldenwood_Planks"
    },
    {
      "x": 0,
      "y": 8,
      "z": 3,
      "name": "Wood_Hardwood_Planks"
    },
    {
      "x": 0,
      "y": 9,
      "z": 3,
      "name": "Wood_Hardwood_Beam",
      "rotation": 4
    },
    {
      "x": 0,
      "y": -3,
      "z": 4,
      "name": "Rock_Basalt_Brick"
    },
    {
      "x": 0,
      "y": -2,
      "z": 4,
      "name": "Rock_Basalt_Brick"
    },
    {
      "x": 0,
      "y": -1,
      "z": 4,
      "name": "Rock_Basalt_Brick"
    },
    {
      "x": 0,
      "y": 0,
      "z": 4,
      "name": "Rock_Basalt_Brick"
    },
    {
      "x": 0,
      "y": 1,
      "z": 4,
      "name": "Rock_Basalt_Brick"
    },
    {
      "x": 0,
      "y": 2,
      "z": 4,
      "name": "Rock_Basalt_Brick"
    },
    {
      "x": 0,
      "y": 3,
      "z": 4,
      "name": "Wood_Goldenwood_Planks"
    },
    {
      "x": 0,
      "y": 4,
      "z": 4,
      "name": "Furniture_Human_Ruins_Shelf",
      "rotation": 1
    },
    {
      "x": 0,
      "y": 5,
      "z": 4,
      "name": "Potion_Health_Large"
    },
    {
      "x": 0,
      "y": 7,
      "z": 4,
      "name": "Wood_Goldenwood_Planks_Half",
      "rotation": 5
    },
    {
      "x": 0,
      "y": 8,
      "z": 4,
      "name": "Wood_Hardwood_Planks"
    },
    {
      "x": 0,
      "y": 9,
      "z": 4,
      "name": "Wood_Hardwood_Roof_Shallow",
      "rotation": 3
    },
    {
      "x": 0,
      "y": -3,
      "z": 5,
      "name": "Rock_Basalt_Brick"
    },
    {
      "x": 0,
      "y": -2,
      "z": 5,
      "name": "Rock_Basalt_Brick"
    },
    {
      "x": 0,
      "y": -1,
      "z": 5,
      "name": "Rock_Basalt_Brick"
    },
    {
      "x": 0,
      "y": 0,
      "z": 5,
      "name": "Rock_Basalt_Brick"
    },
    {
      "x": 0,
      "y": 1,
      "z": 5,
      "name": "Rock_Basalt_Brick"
    },
    {
      "x": 0,
      "y": 2,
      "z": 5,
      "name": "Rock_Basalt_Brick"
    },
    {
      "x": 0,
      "y": 3,
      "z": 5,
      "name": "Wood_Goldenwood_Planks"
    },
    {
      "x": 0,
      "y": 4,
      "z": 5,
      "name": "Furniture_Human_Ruins_Shelf",
      "rotation": 1
    },
    {
      "x": 0,
      "y": 5,
      "z": 5,
      "name": "Furniture_Human_Ruins_Candle"
    },
    {
      "x": 0,
      "y": 6,
      "z": 5,
      "name": "Furniture_Human_Ruins_Candle",
      "filler": 1024
    },
    {
      "x": 0,
      "y": 7,
      "z": 5,
      "name": "Wood_Goldenwood_Planks_Half",
      "rotation": 5
    },
    {
      "x": 0,
      "y": 8,
      "z": 5,
      "name": "Wood_Hardwood_Planks"
    },
    {
      "x": 0,
      "y": 9,
      "z": 5,
      "name": "Wood_Hardwood_Beam",
      "rotation": 4
    },
    {
      "x": 0,
      "y": -3,
      "z": 6,
      "name": "Rock_Basalt_Brick"
    },
    {
      "x": 0,
      "y": -2,
      "z": 6,
      "name": "Rock_Basalt_Brick"
    },
    {
      "x": 0,
      "y": -1,
      "z": 6,
      "name": "Rock_Basalt_Brick"
    },
    {
      "x": 0,
      "y": 0,
      "z": 6,
      "name": "Rock_Basalt_Brick"
    },
    {
      "x": 0,
      "y": 1,
      "z": 6,
      "name": "Rock_Basalt_Brick"
    },
    {
      "x": 0,
      "y": 2,
      "z": 6,
      "name": "Rock_Basalt_Brick"
    },
    {
      "x": 0,
      "y": 3,
      "z": 6,
      "name": "Wood_Goldenwood_Planks"
    },
    {
      "x": 0,
      "y": 4,
      "z": 6,
      "name": "Furniture_Human_Ruins_Shelf",
      "rotation": 1
    },
    {
      "x": 0,
      "y": 5,
      "z": 6,
      "name": "Potion_Health_Large"
    },
    {
      "x": 0,
      "y": 7,
      "z": 6,
      "name": "Wood_Goldenwood_Planks"
    },
    {
      "x": 0,
      "y": 8,
      "z": 6,
      "name": "Wood_Hardwood_Planks"
    },
    {
      "x": 0,
      "y": 9,
      "z": 6,
      "name": "Wood_Hardwood_Roof_Shallow",
      "rotation": 3
    },
    {
      "x": 0,
      "y": -3,
      "z": 7,
      "name": "Rock_Basalt_Brick"
    },
    {
      "x": 0,
      "y": -2,
      "z": 7,
      "name": "Rock_Basalt_Brick"
    },
    {
      "x": 0,
      "y": -1,
      "z": 7,
      "name": "Rock_Basalt_Brick"
    },
    {
      "x": 0,
      "y": 0,
      "z": 7,
      "name": "Rock_Basalt_Brick"
    },
    {
      "x": 0,
      "y": 1,
      "z": 7,
      "name": "Rock_Basalt_Brick"
    },
    {
      "x": 0,
      "y": 2,
      "z": 7,
      "name": "Rock_Basalt_Brick"
    },
    {
      "x": 0,
      "y": 3,
      "z": 7,
      "name": "Wood_Goldenwood_Planks"
    },
    {
      "x": 0,
      "y": 4,
      "z": 7,
      "name": "Wood_Hardwood_Beam",
      "rotation": 5
    },
    {
      "x": 0,
      "y": 5,
      "z": 7,
      "name": "Wood_Hardwood_Beam",
      "rotation": 5
    },
    {
      "x": 0,
      "y": 6,
      "z": 7,
      "name": "Wood_Sallow_Trunk",
      "support": 15,
      "rotation": 5
    },
    {
      "x": 0,
      "y": 7,
      "z": 7,
      "name": "Wood_Hardwood_Planks"
    },
    {
      "x": 0,
      "y": 8,
      "z": 7,
      "name": "Wood_Hardwood_Planks"
    },
    {
      "x": 0,
      "y": 9,
      "z": 7,
      "name": "Wood_Hardwood_Roof_Shallow",
      "rotation": 3
    },
    {
      "x": 0,
      "y": 9,
      "z": 8,
      "name": "Wood_Hardwood_Roof_Shallow",
      "rotation": 3
    },
    {
      "x": 1,
      "y": 7,
      "z": -6,
      "name": "Wood_Hardwood_Roof_Hollow",
      "rotation": 2
    },
    {
      "x": 1,
      "y": -3,
      "z": -5,
      "name": "Rock_Basalt_Brick"
    },
    {
      "x": 1,
      "y": -2,
      "z": -5,
      "name": "Rock_Basalt_Brick"
    },
    {
      "x": 1,
      "y": -1,
      "z": -5,
      "name": "Rock_Basalt_Brick"
    },
    {
      "x": 1,
      "y": 0,
      "z": -5,
      "name": "Rock_Basalt_Cobble"
    },
    {
      "x": 1,
      "y": 1,
      "z": -5,
      "name": "Rock_Basalt_Brick"
    },
    {
      "x": 1,
      "y": 2,
      "z": -5,
      "name": "Rock_Basalt_Brick"
    },
    {
      "x": 1,
      "y": 3,
      "z": -5,
      "name": "Wood_Goldenwood_Planks"
    },
    {
      "x": 1,
      "y": 4,
      "z": -5,
      "name": "Wood_Goldenwood_Planks"
    },
    {
      "x": 1,
      "y": 5,
      "z": -5,
      "name": "Wood_Goldenwood_Planks"
    },
    {
      "x": 1,
      "y": 6,
      "z": -5,
      "name": "Wood_Sallow_Trunk",
      "support": 15,
      "rotation": 5
    },
    {
      "x": 1,
      "y": 7,
      "z": -5,
      "name": "Wood_Hardwood_Planks"
    },
    {
      "x": 1,
      "y": 8,
      "z": -5,
      "name": "Wood_Hardwood_Roof",
      "rotation": 2
    },
    {
      "x": 1,
      "y": -3,
      "z": -4,
      "name": "Rock_Basalt_Brick"
    },
    {
      "x": 1,
      "y": -2,
      "z": -4,
      "name": "Rock_Basalt"
    },
    {
      "x": 1,
      "y": -1,
      "z": -4,
      "name": "Furniture_Human_Ruins_Desk",
      "filler": 31
    },
    {
      "x": 1,
      "y": 0,
      "z": -4,
      "name": "Furniture_Human_Ruins_Candle"
    },
    {
      "x": 1,
      "y": 1,
      "z": -4,
      "name": "Furniture_Human_Ruins_Candle",
      "filler": 1024
    },
    {
      "x": 1,
      "y": 2,
      "z": -4,
      "name": "Empty"
    },
    {
      "x": 1,
      "y": 3,
      "z": -4,
      "name": "Wood_Goldenwood_Planks"
    },
    {
      "x": 1,
      "y": 7,
      "z": -4,
      "name": "Wood_Goldenwood_Planks_Half",
      "rotation": 4
    },
    {
      "x": 1,
      "y": 8,
      "z": -4,
      "name": "Wood_Hardwood_Planks"
    },
    {
      "x": 1,
      "y": 9,
      "z": -4,
      "name": "Wood_Hardwood_Beam",
      "rotation": 5
    },
    {
      "x": 1,
      "y": -3,
      "z": -3,
      "name": "Rock_Basalt_Brick"
    },
    {
      "x": 1,
      "y": -2,
      "z": -3,
      "name": "Rock_Basalt_Cobble"
    },
    {
      "x": 1,
      "y": -1,
      "z": -3,
      "name": "Empty"
    },
    {
      "x": 1,
      "y": 0,
      "z": -3,
      "name": "Empty"
    },
    {
      "x": 1,
      "y": 1,
      "z": -3,
      "name": "Empty"
    },
    {
      "x": 1,
      "y": 2,
      "z": -3,
      "name": "Empty"
    },
    {
      "x": 1,
      "y": 3,
      "z": -3,
      "name": "Wood_Goldenwood_Planks"
    },
    {
      "x": 1,
      "y": 8,
      "z": -3,
      "name": "Wood_Hardwood_Planks"
    },
    {
      "x": 1,
      "y": 10,
      "z": -3,
      "name": "Wood_Hardwood_Roof_Hollow",
      "rotation": 2
    },
    {
      "x": 1,
      "y": -3,
      "z": -2,
      "name": "Rock_Basalt_Brick"
    },
    {
      "x": 1,
      "y": -2,
      "z": -2,
      "name": "Rock_Basalt_Cobble"
    },
    {
      "x": 1,
      "y": -1,
      "z": -2,
      "name": "Empty"
    },
    {
      "x": 1,
      "y": 0,
      "z": -2,
      "name": "Empty"
    },
    {
      "x": 1,
      "y": 1,
      "z": -2,
      "name": "Empty"
    },
    {
      "x": 1,
      "y": 2,
      "z": -2,
      "name": "Empty"
    },
    {
      "x": 1,
      "y": 3,
      "z": -2,
      "name": "Wood_Hardwood_Beam",
      "rotation": 5
    },
    {
      "x": 1,
      "y": 8,
      "z": -2,
      "name": "Wood_Hardwood_Planks"
    },
    {
      "x": 1,
      "y": 11,
      "z": -2,
      "name": "Wood_Hardwood_Roof_Hollow",
      "rotation": 2
    },
    {
      "x": 1,
      "y": -3,
      "z": -1,
      "name": "Rock_Basalt_Brick"
    },
    {
      "x": 1,
      "y": -2,
      "z": -1,
      "name": "Rock_Basalt"
    },
    {
      "x": 1,
      "y": -1,
      "z": -1,
      "name": "Empty"
    },
    {
      "x": 1,
      "y": 0,
      "z": -1,
      "name": "Empty"
    },
    {
      "x": 1,
      "y": 1,
      "z": -1,
      "name": "Empty"
    },
    {
      "x": 1,
      "y": 2,
      "z": -1,
      "name": "Empty"
    },
    {
      "x": 1,
      "y": 3,
      "z": -1,
      "name": "Wood_Goldenwood_Stairs",
      "rotation": 10
    },
    {
      "x": 1,
      "y": 8,
      "z": -1,
      "name": "Wood_Hardwood_Planks"
    },
    {
      "x": 1,
      "y": 11,
      "z": -1,
      "name": "Wood_Hardwood_Roof_Hollow"
    },
    {
      "x": 1,
      "y": -3,
      "z": 0,
      "name": "Rock_Basalt_Brick"
    },
    {
      "x": 1,
      "y": -2,
      "z": 0,
      "name": "Rock_Basalt"
    },
    {
      "x": 1,
      "y": -1,
      "z": 0,
      "name": "Empty"
    },
    {
      "x": 1,
      "y": 0,
      "z": 0,
      "name": "Empty"
    },
    {
      "x": 1,
      "y": 1,
      "z": 0,
      "name": "Empty"
    },
    {
      "x": 1,
      "y": 2,
      "z": 0,
      "name": "Empty"
    },
    {
      "x": 1,
      "y": 3,
      "z": 0,
      "name": "Wood_Hardwood_Beam",
      "rotation": 4
    },
    {
      "x": 1,
      "y": 8,
      "z": 0,
      "name": "Wood_Hardwood_Planks"
    },
    {
      "x": 1,
      "y": 11,
      "z": 0,
      "name": "Wood_Hardwood_Roof_Flat",
      "rotation": 3
    },
    {
      "x": 1,
      "y": -3,
      "z": 1,
      "name": "Rock_Basalt_Brick"
    },
    {
      "x": 1,
      "y": -2,
      "z": 1,
      "name": "Rock_Basalt"
    },
    {
      "x": 1,
      "y": -1,
      "z": 1,
      "name": "Empty"
    },
    {
      "x": 1,
      "y": 0,
      "z": 1,
      "name": "Empty"
    },
    {
      "x": 1,
      "y": 1,
      "z": 1,
      "name": "Empty"
    },
    {
      "x": 1,
      "y": 2,
      "z": 1,
      "name": "Empty"
    },
    {
      "x": 1,
      "y": 3,
      "z": 1,
      "name": "Wood_Goldenwood_Planks"
    },
    {
      "x": 1,
      "y": 8,
      "z": 1,
      "name": "Wood_Hardwood_Planks"
    },
    {
      "x": 1,
      "y": 10,
      "z": 1,
      "name": "Wood_Hardwood_Roof_Hollow"
    },
    {
      "x": 1,
      "y": -3,
      "z": 2,
      "name": "Rock_Basalt_Brick"
    },
    {
      "x": 1,
      "y": -2,
      "z": 2,
      "name": "Rock_Basalt"
    },
    {
      "x": 1,
      "y": -1,
      "z": 2,
      "name": "Furniture_Human_Ruins_Pot_Small"
    },
    {
      "x": 1,
      "y": 0,
      "z": 2,
      "name": "Empty"
    },
    {
      "x": 1,
      "y": 1,
      "z": 2,
      "name": "Empty"
    },
    {
      "x": 1,
      "y": 2,
      "z": 2,
      "name": "Empty"
    },
    {
      "x": 1,
      "y": 3,
      "z": 2,
      "name": "Wood_Goldenwood_Planks"
    },
    {
      "x": 1,
      "y": 8,
      "z": 2,
      "name": "Wood_Hardwood_Planks"
    },
    {
      "x": 1,
      "y": 9,
      "z": 2,
      "name": "*Wood_Hardwood_Roof_State_Definitions_Inverted_Corner_Left",
      "rotation": 3
    },
    {
      "x": 1,
      "y": -3,
      "z": 3,
      "name": "Rock_Basalt_Brick"
    },
    {
      "x": 1,
      "y": -2,
      "z": 3,
      "name": "Rock_Basalt_Brick"
    },
    {
      "x": 1,
      "y": -1,
      "z": 3,
      "name": "Rock_Basalt_Brick"
    },
    {
      "x": 1,
      "y": 0,
      "z": 3,
      "name": "Rock_Basalt_Cobble"
    },
    {
      "x": 1,
      "y": 1,
      "z": 3,
      "name": "Rock_Basalt_Brick"
    },
    {
      "x": 1,
      "y": 2,
      "z": 3,
      "name": "Rock_Basalt_Brick"
    },
    {
      "x": 1,
      "y": 3,
      "z": 3,
      "name": "Wood_Goldenwood_Planks"
    },
    {
      "x": 1,
      "y": 4,
      "z": 3,
      "name": "Wood_Goldenwood_Planks"
    },
    {
      "x": 1,
      "y": 5,
      "z": 3,
      "name": "Wood_Goldenwood_Planks"
    },
    {
      "x": 1,
      "y": 6,
      "z": 3,
      "name": "Wood_Goldenwood_Planks"
    },
    {
      "x": 1,
      "y": 7,
      "z": 3,
      "name": "Wood_Goldenwood_Planks"
    },
    {
      "x": 1,
      "y": 8,
      "z": 3,
      "name": "Wood_Hardwood_Planks"
    },
    {
      "x": 1,
      "y": 9,
      "z": 3,
      "name": "Wood_Hardwood_Beam",
      "rotation": 4
    },
    {
      "x": 1,
      "y": -3,
      "z": 4,
      "name": "Rock_Basalt_Brick"
    },
    {
      "x": 1,
      "y": -2,
      "z": 4,
      "name": "Rock_Basalt_Brick"
    },
    {
      "x": 1,
      "y": -1,
      "z": 4,
      "name": "Rock_Basalt_Cobble"
    },
    {
      "x": 1,
      "y": 0,
      "z": 4,
      "name": "Rock_Basalt_Brick"
    },
    {
      "x": 1,
      "y": 1,
      "z": 4,
      "name": "Rock_Basalt_Brick"
    },
    {
      "x": 1,
      "y": 2,
      "z": 4,
      "name": "Rock_Basalt_Brick"
    },
    {
      "x": 1,
      "y": 3,
      "z": 4,
      "name": "Wood_Goldenwood_Planks"
    },
    {
      "x": 1,
      "y": 8,
      "z": 4,
      "name": "Wood_Hardwood_Planks"
    },
    {
      "x": 1,
      "y": 9,
      "z": 4,
      "name": "Wood_Hardwood_Roof_Shallow",
      "filler": 1,
      "rotation": 3
    },
    {
      "x": 1,
      "y": -3,
      "z": 5,
      "name": "Rock_Basalt_Brick"
    },
    {
      "x": 1,
      "y": -2,
      "z": 5,
      "name": "Rock_Basalt_Brick"
    },
    {
      "x": 1,
      "y": -1,
      "z": 5,
      "name": "Rock_Basalt_Brick"
    },
    {
      "x": 1,
      "y": 0,
      "z": 5,
      "name": "Rock_Basalt_Brick"
    },
    {
      "x": 1,
      "y": 1,
      "z": 5,
      "name": "Rock_Basalt_Brick"
    },
    {
      "x": 1,
      "y": 2,
      "z": 5,
      "name": "Rock_Basalt_Brick"
    },
    {
      "x": 1,
      "y": 3,
      "z": 5,
      "name": "Wood_Goldenwood_Planks"
    },
    {
      "x": 1,
      "y": 8,
      "z": 5,
      "name": "Wood_Hardwood_Planks"
    },
    {
      "x": 1,
      "y": 9,
      "z": 5,
      "name": "Wood_Hardwood_Beam",
      "rotation": 4
    },
    {
      "x": 1,
      "y": -3,
      "z": 6,
      "name": "Rock_Basalt_Brick"
    },
    {
      "x": 1,
      "y": -2,
      "z": 6,
      "name": "Rock_Basalt_Brick"
    },
    {
      "x": 1,
      "y": -1,
      "z": 6,
      "name": "Rock_Basalt_Brick"
    },
    {
      "x": 1,
      "y": 0,
      "z": 6,
      "name": "Rock_Basalt_Brick"
    },
    {
      "x": 1,
      "y": 1,
      "z": 6,
      "name": "Rock_Basalt_Brick"
    },
    {
      "x": 1,
      "y": 2,
      "z": 6,
      "name": "Rock_Basalt_Brick"
    },
    {
      "x": 1,
      "y": 3,
      "z": 6,
      "name": "Wood_Goldenwood_Planks"
    },
    {
      "x": 1,
      "y": 7,
      "z": 6,
      "name": "Wood_Goldenwood_Planks_Half",
      "rotation": 6
    },
    {
      "x": 1,
      "y": 9,
      "z": 6,
      "name": "Wood_Hardwood_Roof_Shallow",
      "filler": 1,
      "rotation": 3
    },
    {
      "x": 1,
      "y": -3,
      "z": 7,
      "name": "Rock_Basalt_Brick"
    },
    {
      "x": 1,
      "y": -2,
      "z": 7,
      "name": "Rock_Basalt_Brick"
    },
    {
      "x": 1,
      "y": -1,
      "z": 7,
      "name": "Rock_Basalt_Brick"
    },
    {
      "x": 1,
      "y": 0,
      "z": 7,
      "name": "Rock_Basalt_Brick"
    },
    {
      "x": 1,
      "y": 1,
      "z": 7,
      "name": "Rock_Basalt_Brick"
    },
    {
      "x": 1,
      "y": 2,
      "z": 7,
      "name": "Rock_Basalt_Brick"
    },
    {
      "x": 1,
      "y": 3,
      "z": 7,
      "name": "Wood_Goldenwood_Planks"
    },
    {
      "x": 1,
      "y": 4,
      "z": 7,
      "name": "Wood_Goldenwood_Planks"
    },
    {
      "x": 1,
      "y": 5,
      "z": 7,
      "name": "Wood_Hardwood_Beam",
      "rotation": 5
    },
    {
      "x": 1,
      "y": 6,
      "z": 7,
      "name": "Wood_Sallow_Trunk",
      "support": 15,
      "rotation": 5
    },
    {
      "x": 1,
      "y": 7,
      "z": 7,
      "name": "Wood_Hardwood_Planks"
    },
    {
      "x": 1,
      "y": 8,
      "z": 7,
      "name": "Wood_Hardwood_Planks"
    },
    {
      "x": 1,
      "y": 9,
      "z": 7,
      "name": "Wood_Hardwood_Roof_Shallow",
      "filler": 1,
      "rotation": 3
    },
    {
      "x": 1,
      "y": 9,
      "z": 8,
      "name": "Wood_Hardwood_Roof_Shallow",
      "filler": 1,
      "rotation": 3
    },
    {
      "x": 2,
      "y": 7,
      "z": -6,
      "name": "Wood_Hardwood_Roof_Hollow",
      "rotation": 2
    },
    {
      "x": 2,
      "y": -3,
      "z": -5,
      "name": "Rock_Basalt_Brick"
    },
    {
      "x": 2,
      "y": -2,
      "z": -5,
      "name": "Rock_Basalt_Brick"
    },
    {
      "x": 2,
      "y": -1,
      "z": -5,
      "name": "Rock_Basalt_Brick"
    },
    {
      "x": 2,
      "y": 0,
      "z": -5,
      "name": "Rock_Basalt_Brick"
    },
    {
      "x": 2,
      "y": 1,
      "z": -5,
      "name": "Rock_Basalt_Brick"
    },
    {
      "x": 2,
      "y": 2,
      "z": -5,
      "name": "Rock_Basalt_Brick"
    },
    {
      "x": 2,
      "y": 3,
      "z": -5,
      "name": "Wood_Goldenwood_Planks"
    },
    {
      "x": 2,
      "y": 4,
      "z": -5,
      "name": "Wood_Goldenwood_Planks"
    },
    {
      "x": 2,
      "y": 5,
      "z": -5,
      "name": "Wood_Goldenwood_Planks"
    },
    {
      "x": 2,
      "y": 6,
      "z": -5,
      "name": "Wood_Sallow_Trunk",
      "support": 15,
      "rotation": 5
    },
    {
      "x": 2,
      "y": 7,
      "z": -5,
      "name": "Wood_Hardwood_Planks"
    },
    {
      "x": 2,
      "y": 8,
      "z": -5,
      "name": "Wood_Hardwood_Roof",
      "rotation": 2
    },
    {
      "x": 2,
      "y": -3,
      "z": -4,
      "name": "Rock_Basalt_Brick"
    },
    {
      "x": 2,
      "y": -2,
      "z": -4,
      "name": "Rock_Basalt"
    },
    {
      "x": 2,
      "y": -1,
      "z": -4,
      "name": "Furniture_Human_Ruins_Desk"
    },
    {
      "x": 2,
      "y": 0,
      "z": -4,
      "name": "Empty"
    },
    {
      "x": 2,
      "y": 1,
      "z": -4,
      "name": "Empty"
    },
    {
      "x": 2,
      "y": 2,
      "z": -4,
      "name": "Empty"
    },
    {
      "x": 2,
      "y": 3,
      "z": -4,
      "name": "Wood_Goldenwood_Planks"
    },
    {
      "x": 2,
      "y": 7,
      "z": -4,
      "name": "Wood_Goldenwood_Planks_Half",
      "rotation": 4
    },
    {
      "x": 2,
      "y": 8,
      "z": -4,
      "name": "Wood_Hardwood_Planks"
    },
    {
      "x": 2,
      "y": 9,
      "z": -4,
      "name": "Wood_Hardwood_Beam",
      "rotation": 5
    },
    {
      "x": 2,
      "y": -3,
      "z": -3,
      "name": "Rock_Basalt_Brick"
    },
    {
      "x": 2,
      "y": -2,
      "z": -3,
      "name": "Rock_Basalt"
    },
    {
      "x": 2,
      "y": -1,
      "z": -3,
      "name": "Empty"
    },
    {
      "x": 2,
      "y": 0,
      "z": -3,
      "name": "Empty"
    },
    {
      "x": 2,
      "y": 1,
      "z": -3,
      "name": "Empty"
    },
    {
      "x": 2,
      "y": 2,
      "z": -3,
      "name": "Empty"
    },
    {
      "x": 2,
      "y": 3,
      "z": -3,
      "name": "Wood_Goldenwood_Planks"
    },
    {
      "x": 2,
      "y": 8,
      "z": -3,
      "name": "Wood_Hardwood_Planks"
    },
    {
      "x": 2,
      "y": 10,
      "z": -3,
      "name": "Wood_Hardwood_Beam",
      "rotation": 5
    },
    {
      "x": 2,
      "y": -3,
      "z": -2,
      "name": "Rock_Basalt_Brick"
    },
    {
      "x": 2,
      "y": -2,
      "z": -2,
      "name": "Rock_Basalt"
    },
    {
      "x": 2,
      "y": -1,
      "z": -2,
      "name": "Empty"
    },
    {
      "x": 2,
      "y": 0,
      "z": -2,
      "name": "Empty"
    },
    {
      "x": 2,
      "y": 1,
      "z": -2,
      "name": "Empty"
    },
    {
      "x": 2,
      "y": 2,
      "z": -2,
      "name": "Empty"
    },
    {
      "x": 2,
      "y": 3,
      "z": -2,
      "name": "Wood_Goldenwood_Planks"
    },
    {
      "x": 2,
      "y": 8,
      "z": -2,
      "name": "Wood_Hardwood_Planks"
    },
    {
      "x": 2,
      "y": 11,
      "z": -2,
      "name": "Wood_Hardwood_Roof_Hollow",
      "rotation": 2
    },
    {
      "x": 2,
      "y": -3,
      "z": -1,
      "name": "Rock_Basalt_Brick"
    },
    {
      "x": 2,
      "y": -2,
      "z": -1,
      "name": "Rock_Basalt"
    },
    {
      "x": 2,
      "y": -1,
      "z": -1,
      "name": "Alchemy_Cauldron_Big",
      "rotation": 1
    },
    {
      "x": 2,
      "y": 0,
      "z": -1,
      "name": "Empty"
    },
    {
      "x": 2,
      "y": 1,
      "z": -1,
      "name": "Empty"
    },
    {
      "x": 2,
      "y": 2,
      "z": -1,
      "name": "Empty"
    },
    {
      "x": 2,
      "y": 3,
      "z": -1,
      "name": "Wood_Goldenwood_Planks"
    },
    {
      "x": 2,
      "y": 8,
      "z": -1,
      "name": "Wood_Hardwood_Planks"
    },
    {
      "x": 2,
      "y": 11,
      "z": -1,
      "name": "Wood_Hardwood_Roof_Hollow"
    },
    {
      "x": 2,
      "y": -3,
      "z": 0,
      "name": "Rock_Basalt_Brick"
    },
    {
      "x": 2,
      "y": -2,
      "z": 0,
      "name": "Rock_Basalt"
    },
    {
      "x": 2,
      "y": -1,
      "z": 0,
      "name": "Empty"
    },
    {
      "x": 2,
      "y": 0,
      "z": 0,
      "name": "Empty"
    },
    {
      "x": 2,
      "y": 1,
      "z": 0,
      "name": "Empty"
    },
    {
      "x": 2,
      "y": 2,
      "z": 0,
      "name": "Empty"
    },
    {
      "x": 2,
      "y": 3,
      "z": 0,
      "name": "Wood_Goldenwood_Planks"
    },
    {
      "x": 2,
      "y": 8,
      "z": 0,
      "name": "Wood_Hardwood_Planks"
    },
    {
      "x": 2,
      "y": 11,
      "z": 0,
      "name": "Wood_Hardwood_Roof_Flat",
      "rotation": 3
    },
    {
      "x": 2,
      "y": -3,
      "z": 1,
      "name": "Rock_Basalt_Brick"
    },
    {
      "x": 2,
      "y": -2,
      "z": 1,
      "name": "Rock_Basalt"
    },
    {
      "x": 2,
      "y": -1,
      "z": 1,
      "name": "Empty"
    },
    {
      "x": 2,
      "y": 0,
      "z": 1,
      "name": "Empty"
    },
    {
      "x": 2,
      "y": 1,
      "z": 1,
      "name": "Empty"
    },
    {
      "x": 2,
      "y": 2,
      "z": 1,
      "name": "Empty"
    },
    {
      "x": 2,
      "y": 3,
      "z": 1,
      "name": "Wood_Goldenwood_Planks"
    },
    {
      "x": 2,
      "y": 8,
      "z": 1,
      "name": "Wood_Hardwood_Planks"
    },
    {
      "x": 2,
      "y": 10,
      "z": 1,
      "name": "*Wood_Hardwood_Roof_Hollow_State_Definitions_Inverted_Corner_Left",
      "rotation": 3
    },
    {
      "x": 2,
      "y": -3,
      "z": 2,
      "name": "Rock_Basalt_Brick"
    },
    {
      "x": 2,
      "y": -2,
      "z": 2,
      "name": "Rock_Basalt"
    },
    {
      "x": 2,
      "y": -1,
      "z": 2,
      "name": "Furniture_Human_Ruins_Desk",
      "rotation": 2
    },
    {
      "x": 2,
      "y": 0,
      "z": 2,
