{
  "version": 8,
  "blockIdVersion": 11,
  "anchorX": 2,
  "anchorY": -1,
  "anchorZ": 1,
  "blocks": [
    {
      "x": -2,
      "y": 4,
      "z": -2,
      "name": "Wood_Darkwood_Planks_Half",
      "rotation": 7
    },
    {
      "x": -2,
      "y": 5,
      "z": -2,
      "name": "Wood_Darkwood_Beam"
    },
    {
      "x": -2,
      "y": 6,
      "z": -2,
      "name": "Wood_Darkwood_Beam"
    },
    {
      "x": -2,
      "y": 7,
      "z": -2,
      "name": "Cloth_Roof_Orange",
      "rotation": 3
    },
    {
      "x": -2,
      "y": 4,
      "z": -1,
      "name": "Wood_Darkwood_Planks_Half",
      "rotation": 7
    },
    {
      "x": -2,
      "y": 7,
      "z": -1,
      "name": "Cloth_Roof_Orange",
      "rotation": 3
    },
    {
      "x": -2,
      "y": -1,
      "z": 0,
      "name": "Furniture_Ancient_Barrel"
    },
    {
      "x": -2,
      "y": 4,
      "z": 1,
      "name": "Wood_Darkwood_Planks_Half",
      "rotation": 7
    },
    {
      "x": -2,
      "y": 5,
      "z": 1,
      "name": "Wood_Darkwood_Beam"
    },
    {
      "x": -2,
      "y": 6,
      "z": 1,
      "name": "Wood_Darkwood_Beam"
    },
    {
      "x": -2,
      "y": 7,
      "z": 1,
      "name": "Cloth_Roof_Orange",
      "rotation": 3
    },
    {
      "x": -2,
      "y": 7,
      "z": 2,
      "name": "*Cloth_Roof_Orange_State_Definitions_Corner_Right"
    },
    {
      "x": -1,
      "y": -1,
      "z": -2,
      "name": "Wood_Darkwood_Beam"
    },
    {
      "x": -1,
      "y": 0,
      "z": -2,
      "name": "Wood_Darkwood_Beam"
    },
    {
      "x": -1,
      "y": 1,
      "z": -2,
      "name": "*Wood_Darkwood_Fence_State_Definitions_Corner",
      "rotation": 1
    },
    {
      "x": -1,
      "y": 2,
      "z": -2,
      "name": "Wood_Darkwood_Beam"
    },
    {
      "x": -1,
      "y": 3,
      "z": -2,
      "name": "Wood_Darkwood_Beam"
    },
    {
      "x": -1,
      "y": 4,
      "z": -2,
      "name": "Wood_Darkwood_Planks"
    },
    {
      "x": -1,
      "y": 8,
      "z": -2,
      "name": "*Cloth_Roof_Orange_State_Definitions_Corner_Left",
      "rotation": 2
    },
    {
      "x": -1,
      "y": 1,
      "z": -1,
      "name": "Wood_Darkwood_Fence",
      "rotation": 3
    },
    {
      "x": -1,
      "y": 4,
      "z": -1,
      "name": "Wood_Darkwood_Planks"
    },
    {
      "x": -1,
      "y": 8,
      "z": -1,
      "name": "Cloth_Roof_Orange",
      "rotation": 3
    },
    {
      "x": -1,
      "y": -1,
      "z": 0,
      "name": "Furniture_Ancient_Barrel"
    },
    {
      "x": -1,
      "y": 1,
      "z": 0,
      "name": "Wood_Darkwood_Fence",
      "rotation": 3
    },
    {
      "x": -1,
      "y": 4,
      "z": 0,
      "name": "Wood_Darkwood_Planks"
    },
    {
      "x": -1,
      "y": 8,
      "z": 0,
      "name": "Cloth_Roof_Orange",
      "rotation": 3
    },
    {
      "x": -1,
      "y": -1,
      "z": 1,
      "name": "Wood_Darkwood_Beam"
    },
    {
      "x": -1,
      "y": 0,
      "z": 1,
      "name": "Wood_Darkwood_Beam"
    },
    {
      "x": -1,
      "y": 1,
      "z": 1,
      "name": "*Wood_Darkwood_Fence_State_Definitions_Corner",
      "rotation": 2
    },
    {
      "x": -1,
      "y": 2,
      "z": 1,
      "name": "Wood_Darkwood_Beam"
    },
    {
      "x": -1,
      "y": 4,
      "z": 1,
      "name": "Wood_Darkwood_Planks_Half",
      "rotation": 4
    },
    {
      "x": -1,
      "y": 8,
      "z": 1,
      "name": "*Cloth_Roof_Orange_State_Definitions_Corner_Right"
    },
    {
      "x": -1,
      "y": 4,
      "z": 2,
      "name": "Wood_Darkwood_Planks_Half",
      "rotation": 4
    },
    {
      "x": -1,
      "y": 5,
      "z": 2,
      "name": "Wood_Darkwood_Beam"
    },
    {
      "x": -1,
      "y": 6,
      "z": 2,
      "name": "Wood_Darkwood_Beam"
    },
    {
      "x": -1,
      "y": 7,
      "z": 2,
      "name": "Cloth_Roof_Orange"
    },
    {
      "x": 0,
      "y": -1,
      "z": -2,
      "name": "Furniture_Ancient_Crate",
      "rotation": 2
    },
    {
      "x": 0,
      "y": 1,
      "z": -2,
      "name": "Wood_Darkwood_Fence"
    },
    {
      "x": 0,
      "y": 4,
      "z": -2,
      "name": "Wood_Darkwood_Planks"
    },
    {
      "x": 0,
      "y": 5,
      "z": -2,
      "name": "Block_Spawner_Block",
      "components": {
        "Components": {
          "PlacedByInteraction": {
            "WhoPlacedUuid": {
              "$binary": "5RPZJ2uQSJ2g+KZxfjqR+g==",
              "$type": "04"
            }
          },
          "BlockSpawner": {
            "BlockSpawnerId": "Thunderstorm_Tier1"
          }
        }
      }
    },
    {
      "x": 0,
      "y": 8,
      "z": -2,
      "name": "Cloth_Roof_Orange",
      "rotation": 2
    },
    {
      "x": 0,
      "y": -1,
      "z": -1,
      "name": "Furniture_Ancient_Crate",
      "rotation": 2
    },
    {
      "x": 0,
      "y": 0,
      "z": -1,
      "name": "Furniture_Ancient_Crate",
      "rotation": 2
    },
    {
      "x": 0,
      "y": 3,
      "z": -1,
      "name": "Wood_Darkwood_Planks_Half",
      "rotation": 8
    },
    {
      "x": 0,
      "y": 4,
      "z": -1,
      "name": "Wood_Darkwood_Planks"
    },
    {
      "x": 0,
      "y": 9,
      "z": -1,
      "name": "Cloth_Roof_Orange_Flat"
    },
    {
      "x": 0,
      "y": 3,
      "z": 0,
      "name": "Wood_Darkwood_Planks_Half",
      "rotation": 8
    },
    {
      "x": 0,
      "y": 4,
      "z": 0,
      "name": "Wood_Darkwood_Planks"
    },
    {
      "x": 0,
      "y": 9,
      "z": 0,
      "name": "Cloth_Roof_Orange_Flat"
    },
    {
      "x": 0,
      "y": 1,
      "z": 1,
      "name": "Wood_Darkwood_Fence"
    },
    {
      "x": 0,
      "y": 4,
      "z": 1,
      "name": "Wood_Darkwood_Planks"
    },
    {
      "x": 0,
      "y": 8,
      "z": 1,
      "name": "Cloth_Roof_Orange"
    },
    {
      "x": 0,
      "y": 4,
      "z": 2,
      "name": "Wood_Darkwood_Planks_Half",
      "rotation": 4
    },
    {
      "x": 0,
      "y": 7,
      "z": 2,
      "name": "Cloth_Roof_Orange"
    },
    {
      "x": 1,
      "y": 1,
      "z": -2,
      "name": "Wood_Darkwood_Fence",
      "rotation": 2
    },
    {
      "x": 1,
      "y": 4,
      "z": -2,
      "name": "Wood_Darkwood_Planks"
    },
    {
      "x": 1,
      "y": 8,
      "z": -2,
      "name": "Cloth_Roof_Orange",
      "rotation": 2
    },
    {
      "x": 1,
      "y": -1,
      "z": -1,
      "name": "Furniture_Ancient_Crate",
      "rotation": 2
    },
    {
      "x": 1,
      "y": 3,
      "z": -1,
      "name": "Wood_Darkwood_Planks_Half",
      "rotation": 8
    },
    {
      "x": 1,
      "y": 4,
      "z": -1,
      "name": "Wood_Darkwood_Planks"
    },
    {
      "x": 1,
      "y": 9,
      "z": -1,
      "name": "Cloth_Roof_Orange_Flat"
    },
    {
      "x": 1,
      "y": -1,
      "z": 0,
      "name": "Furniture_Human_Ruins_Ladder"
    },
    {
      "x": 1,
      "y": 0,
      "z": 0,
      "name": "Furniture_Human_Ruins_Ladder"
    },
    {
      "x": 1,
      "y": 1,
      "z": 0,
      "name": "Furniture_Human_Ruins_Ladder"
    },
    {
      "x": 1,
      "y": 2,
      "z": 0,
      "name": "Furniture_Human_Ruins_Ladder"
    },
    {
      "x": 1,
      "y": 3,
      "z": 0,
      "name": "Furniture_Human_Ruins_Ladder"
    },
    {
      "x": 1,
      "y": 4,
      "z": 0,
      "name": "Furniture_Human_Ruins_Ladder"
    },
    {
      "x": 1,
      "y": 9,
      "z": 0,
      "name": "Cloth_Roof_Orange_Flat"
    },
    {
      "x": 1,
      "y": 1,
      "z": 1,
      "name": "Wood_Darkwood_Fence"
    },
    {
      "x": 1,
      "y": 4,
      "z": 1,
      "name": "Wood_Darkwood_Planks"
    },
    {
      "x": 1,
      "y": 8,
      "z": 1,
      "name": "Cloth_Roof_Orange"
    },
    {
      "x": 1,
      "y": 7,
      "z": 2,
      "name": "Cloth_Roof_Orange"
    },
    {
      "x": 2,
      "y": -1,
      "z": -2,
      "name": "Wood_Darkwood_Beam"
    },
    {
      "x": 2,
      "y": 0,
      "z": -2,
      "name": "Wood_Darkwood_Beam"
    },
    {
      "x": 2,
      "y": 2,
      "z": -2,
      "name": "Wood_Darkwood_Beam"
    },
    {
      "x": 2,
      "y": 3,
      "z": -2,
      "name": "Wood_Darkwood_Beam"
    },
    {
      "x": 2,
      "y": 4,
      "z": -2,
      "name": "Wood_Darkwood_Planks"
    },
    {
      "x": 2,
      "y": 8,
      "z": -2,
      "name": "*Cloth_Roof_Orange_State_Definitions_Corner_Left",
      "rotation": 1
    },
    {
      "x": 2,
      "y": 4,
      "z": -1,
      "name": "Wood_Darkwood_Planks"
    },
    {
      "x": 2,
      "y": 8,
      "z": -1,
      "name": "Cloth_Roof_Orange",
      "rotation": 1
    },
    {
      "x": 2,
      "y": 1,
      "z": 0,
      "name": "Wood_Darkwood_Fence",
      "rotation": 1
    },
    {
      "x": 2,
      "y": 4,
      "z": 0,
      "name": "Wood_Darkwood_Planks_Half",
      "rotation": 4
    },
    {
      "x": 2,
      "y": 8,
      "z": 0,
      "name": "Cloth_Roof_Orange",
      "rotation": 1
    },
    {
      "x": 2,
      "y": -1,
      "z": 1,
      "name": "Wood_Darkwood_Beam"
    },
    {
      "x": 2,
      "y": 0,
      "z": 1,
      "name": "Wood_Darkwood_Beam"
    },
    {
      "x": 2,
      "y": 1,
      "z": 1,
      "name": "*Wood_Darkwood_Fence_State_Definitions_Corner",
      "rotation": 3
    },
    {
      "x": 2,
      "y": 2,
      "z": 1,
      "name": "Wood_Darkwood_Beam"
    },
    {
      "x": 2,
      "y": 3,
      "z": 1,
      "name": "Wood_Darkwood_Beam"
    },
    {
      "x": 2,
      "y": 4,
      "z": 1,
      "name": "Wood_Darkwood_Planks"
    },
    {
      "x": 2,
      "y": 8,
      "z": 1,
      "name": "*Cloth_Roof_Orange_State_Definitions_Corner_Left"
    },
    {
      "x": 2,
      "y": 4,
      "z": 2,
      "name": "Wood_Darkwood_Planks_Half",
      "rotation": 4
    },
    {
      "x": 2,
      "y": 5,
      "z": 2,
      "name": "Wood_Darkwood_Beam"
    },
    {
      "x": 2,
      "y": 6,
      "z": 2,
      "name": "Wood_Darkwood_Beam"
    },
    {
      "x": 2,
      "y": 7,
      "z": 2,
      "name": "Cloth_Roof_Orange"
    },
    {
      "x": 3,
      "y": -1,
      "z": -2,
      "name": "Furniture_Ancient_Crate",
      "rotation": 1
    },
    {
      "x": 3,
      "y": 0,
      "z": -2,
      "name": "Furniture_Ancient_Crate",
      "rotation": 1
    },
    {
      "x": 3,
      "y": 4,
      "z": -2,
      "name": "Wood_Darkwood_Planks_Half",
      "rotation": 5
    },
    {
      "x": 3,
      "y": 5,
      "z": -2,
      "name": "Wood_Darkwood_Beam"
    },
    {
      "x": 3,
      "y": 6,
      "z": -2,
      "name": "Wood_Darkwood_Beam"
    },
    {
      "x": 3,
      "y": 7,
      "z": -2,
      "name": "Cloth_Roof_Orange",
      "rotation": 1
    },
    {
      "x": 3,
      "y": 4,
      "z": -1,
      "name": "Wood_Darkwood_Planks_Half",
      "rotation": 5
    },
    {
      "x": 3,
      "y": 7,
      "z": -1,
      "name": "Cloth_Roof_Orange",
      "rotation": 1
    },
    {
      "x": 3,
      "y": 4,
      "z": 0,
      "name": "Wood_Darkwood_Planks_Half",
      "rotation": 5
    },
    {
      "x": 3,
      "y": 7,
      "z": 0,
      "name": "Cloth_Roof_Orange",
      "rotation": 1
    },
    {
      "x": 3,
      "y": 4,
      "z": 1,
      "name": "Wood_Darkwood_Planks_Half",
      "rotation": 5
    },
    {
      "x": 3,
      "y": 5,
      "z": 1,
      "name": "Wood_Darkwood_Beam"
    },
    {
      "x": 4,
      "y": -1,
      "z": -2,
      "name": "Furniture_Ancient_Barrel"
    }
  ],
  "entities": [
    {
      "Components": {
        "EffectController": {},
        "DisplayName": {
          "DisplayName": {
            "MessageId": "server.npcRoles.Skeleton_Burnt_Gunner.name",
            "Bold": null,
            "Italic": null,
            "Monospace": null,
            "Underline": null
          }
        },
        "UIComponentList": {},
        "Transform": {
          "Position": {
            "X": 2.5966353276186798,
            "Y": 5.0,
            "Z": -0.6697698261574216
          },
          "Rotation": {
            "Pitch": 0.0,
            "Yaw": -3.0380542278289795,
            "Roll": 0.0
          }
        },
        "Velocity": {
          "Velocity": {
            "X": 0.0,
            "Y": 0.0,
            "Z": 0.0
          }
        },
        "PrefabCopyable": {},
        "Interactions": {
          "Interactions": {
            "Use": "*UseNPC"
          }
        },
        "Model": {
          "Model": {
            "Id": "Skeleton_Burnt_Gunner",
            "Scale": 1.0,
            "Static": false
          }
        },
        "UUID": {
          "UUID": {
            "$binary": "7PICE2z7PmmQOilndcStQA==",
            "$type": "04"
          }
        },
        "EntityStats": {
          "Version": 5,
          "Stats": {
            "Oxygen": {
              "Id": "Oxygen",
              "Value": 100.0
            },
            "Mana": {
              "Id": "Mana",
              "Value": 0.0
            },
            "Health": {
              "Id": "Health",
              "Value": 81.0,
              "Modifiers": {
                "NPC_Max": {
                  "Id": "Static",
                  "CalculationType": "Additive",
                  "Amount": -19.0
                }
              }
            },
            "GlidingActive": {
              "Id": "GlidingActive",
              "Value": 0.0
            },
            "Immunity": {
              "Id": "Immunity",
              "Value": 0.0
            },
            "SignatureCharges": {
              "Id": "SignatureCharges",
              "Value": 0.0
            },
            "Stamina": {
              "Id": "Stamina",
              "Value": 10.0
            },
            "Ammo": {
              "Id": "Ammo",
              "Value": 0.0
            },
            "Unknown": {
              "Id": "Unknown",
              "Value": 0.0
            },
            "SignatureEnergy": {
              "Id": "SignatureEnergy",
              "Value": 0.0
            },
            "DeployablePreview": {
              "Id": "DeployablePreview",
              "Value": 0.0
            },
            "StaminaRegenDelay": {
              "Id": "StaminaRegenDelay",
              "Value": 0.0
            },
            "MagicCharges": {
              "Id": "MagicCharges",
              "Value": 0.0
            }
          }
        },
        "NPC": {
          "Version": 5,
          "UUID": {
            "$binary": "28gYILSNNqi5tH6s4S5ZjA==",
            "$type": "04"
          },
          "Inventory": {
            "Version": 4,
            "Storage": {
              "Id": "Empty"
            },
            "Armor": {
              "Id": "Simple",
              "Capacity": 4,
              "Items": {}
            },
            "HotBar": {
              "Id": "Simple",
              "Capacity": 3,
              "Items": {
                "0": {
                  "Id": "Weapon_Gun_Blunderbuss_Rusty",
                  "Quantity": 1,
                  "Durability": 0.0,
                  "MaxDurability": 0.0,
                  "OverrideDroppedItemAnimation": false
                }
              }
            },
            "Utility": {
              "Id": "Simple",
              "Capacity": 2,
              "Items": {
                "0": {
                  "Id": "Furniture_Crude_Torch",
                  "Quantity": 1,
                  "Durability": 0.0,
                  "MaxDurability": 0.0,
                  "OverrideDroppedItemAnimation": false
                }
              }
            },
            "Backpack": {
              "Id": "Empty"
            },
            "ActiveHotbarSlot": 0,
            "Tool": {
              "Id": "Empty"
            },
            "ActiveToolsSlot": -1,
            "ActiveUtilitySlot": -1,
            "SortType": "Name"
          },
          "HvrPhs": 0.0,
          "HvrHght": 0.0,
          "MdlScl": 1.0,
          "SpawnInstant": "0001-01-01T12:00:00Z",
          "WorldgenId": 0,
          "PathManager": {},
          "LeashPos": {
            "X": 2.5966353276186798,
            "Y": 60.0,
            "Z": -0.6697698261574216
          },
          "LeashHdg": -3.0380542278289795,
          "LeashPtch": 0.0,
          "RoleName": "Skeleton_Burnt_Gunner_Patrol"
        },
        "HeadRotation": {
          "Rotation": {
            "Pitch": 0.0,
            "Yaw": -3.0380542278289795,
            "Roll": 0.0
          }
        }
      }
    }
  ]
}