{
  "version": 8,
  "blockIdVersion": 11,
  "anchorX": 2,
  "anchorY": -1,
  "anchorZ": 1,
  "blocks": [
    {
      "x": -2,
      "y": 7,
      "z": 0,
      "name": "*Cloth_Roof_Orange_State_Definitions_Corner_Right",
      "rotation": 3
    },
    {
      "x": -2,
      "y": -1,
      "z": 1,
      "name": "Furniture_Ancient_Crate",
      "rotation": 1
    },
    {
      "x": -2,
      "y": 0,
      "z": 1,
      "name": "Furniture_Ancient_Crate",
      "rotation": 1
    },
    {
      "x": -2,
      "y": 4,
      "z": 1,
      "name": "Wood_Darkwood_Planks_Half",
      "rotation": 7
    },
    {
      "x": -2,
      "y": 5,
      "z": 1,
      "name": "Wood_Darkwood_Beam"
    },
    {
      "x": -2,
      "y": 6,
      "z": 1,
      "name": "Wood_Darkwood_Beam"
    },
    {
      "x": -2,
      "y": 7,
      "z": 1,
      "name": "Cloth_Roof_Orange",
      "rotation": 3
    },
    {
      "x": -2,
      "y": -1,
      "z": 2,
      "name": "Furniture_Ancient_Crate",
      "rotation": 1
    },
    {
      "x": -2,
      "y": 4,
      "z": 2,
      "name": "Wood_Darkwood_Planks_Half",
      "rotation": 7
    },
    {
      "x": -2,
      "y": 7,
      "z": 2,
      "name": "Cloth_Roof_Orange",
      "rotation": 3
    },
    {
      "x": -2,
      "y": -1,
      "z": 3,
      "name": "Furniture_Ancient_Barrel"
    },
    {
      "x": -2,
      "y": 4,
      "z": 4,
      "name": "Wood_Darkwood_Planks_Half",
      "rotation": 7
    },
    {
      "x": -2,
      "y": 5,
      "z": 4,
      "name": "Wood_Darkwood_Beam"
    },
    {
      "x": -2,
      "y": 6,
      "z": 4,
      "name": "Wood_Darkwood_Beam"
    },
    {
      "x": -2,
      "y": 7,
      "z": 4,
      "name": "Cloth_Roof_Orange",
      "rotation": 3
    },
    {
      "x": -2,
      "y": 7,
      "z": 5,
      "name": "*Cloth_Roof_Orange_State_Definitions_Corner_Right"
    },
    {
      "x": -1,
      "y": -1,
      "z": 0,
      "name": "Furniture_Ancient_Barrel"
    },
    {
      "x": -1,
      "y": 4,
      "z": 0,
      "name": "Wood_Darkwood_Planks_Half",
      "rotation": 6
    },
    {
      "x": -1,
      "y": 5,
      "z": 0,
      "name": "Wood_Darkwood_Beam"
    },
    {
      "x": -1,
      "y": 6,
      "z": 0,
      "name": "Wood_Darkwood_Beam"
    },
    {
      "x": -1,
      "y": 7,
      "z": 0,
      "name": "Cloth_Roof_Orange",
      "rotation": 2
    },
    {
      "x": -1,
      "y": -1,
      "z": 1,
      "name": "Wood_Darkwood_Beam"
    },
    {
      "x": -1,
      "y": 0,
      "z": 1,
      "name": "Wood_Darkwood_Beam"
    },
    {
      "x": -1,
      "y": 1,
      "z": 1,
      "name": "*Wood_Darkwood_Fence_State_Definitions_Corner",
      "rotation": 1
    },
    {
      "x": -1,
      "y": 2,
      "z": 1,
      "name": "Wood_Darkwood_Beam"
    },
    {
      "x": -1,
      "y": 4,
      "z": 1,
      "name": "Wood_Darkwood_Planks"
    },
    {
      "x": -1,
      "y": 8,
      "z": 1,
      "name": "*Cloth_Roof_Orange_State_Definitions_Corner_Left",
      "rotation": 2
    },
    {
      "x": -1,
      "y": -1,
      "z": 2,
      "name": "Furniture_Ancient_Crate",
      "rotation": 1
    },
    {
      "x": -1,
      "y": 1,
      "z": 2,
      "name": "Wood_Darkwood_Fence",
      "rotation": 3
    },
    {
      "x": -1,
      "y": 4,
      "z": 2,
      "name": "Wood_Darkwood_Planks"
    },
    {
      "x": -1,
      "y": 8,
      "z": 2,
      "name": "Cloth_Roof_Orange",
      "rotation": 3
    },
    {
      "x": -1,
      "y": 1,
      "z": 3,
      "name": "Wood_Darkwood_Fence",
      "rotation": 3
    },
    {
      "x": -1,
      "y": 8,
      "z": 3,
      "name": "Cloth_Roof_Orange",
      "rotation": 3
    },
    {
      "x": -1,
      "y": -1,
      "z": 4,
      "name": "Wood_Darkwood_Beam"
    },
    {
      "x": -1,
      "y": 0,
      "z": 4,
      "name": "Wood_Darkwood_Beam"
    },
    {
      "x": -1,
      "y": 1,
      "z": 4,
      "name": "*Wood_Darkwood_Fence_State_Definitions_Corner",
      "rotation": 2
    },
    {
      "x": -1,
      "y": 2,
      "z": 4,
      "name": "Wood_Darkwood_Beam"
    },
    {
      "x": -1,
      "y": 3,
      "z": 4,
      "name": "Wood_Darkwood_Beam"
    },
    {
      "x": -1,
      "y": 8,
      "z": 4,
      "name": "*Cloth_Roof_Orange_State_Definitions_Corner_Right"
    },
    {
      "x": -1,
      "y": 4,
      "z": 5,
      "name": "Wood_Darkwood_Planks_Half",
      "rotation": 4
    },
    {
      "x": -1,
      "y": 5,
      "z": 5,
      "name": "Wood_Darkwood_Beam"
    },
    {
      "x": -1,
      "y": 6,
      "z": 5,
      "name": "Wood_Darkwood_Beam"
    },
    {
      "x": -1,
      "y": 7,
      "z": 5,
      "name": "Cloth_Roof_Orange"
    },
    {
      "x": 0,
      "y": 4,
      "z": 0,
      "name": "Wood_Darkwood_Planks_Half",
      "rotation": 6
    },
    {
      "x": 0,
      "y": 7,
      "z": 0,
      "name": "Cloth_Roof_Orange",
      "rotation": 2
    },
    {
      "x": 0,
      "y": 1,
      "z": 1,
      "name": "Wood_Darkwood_Fence"
    },
    {
      "x": 0,
      "y": 4,
      "z": 1,
      "name": "Wood_Darkwood_Planks"
    },
    {
      "x": 0,
      "y": 5,
      "z": 1,
      "name": "Block_Spawner_Block",
      "components": {
        "Components": {
          "PlacedByInteraction": {
            "WhoPlacedUuid": {
              "$binary": "5RPZJ2uQSJ2g+KZxfjqR+g==",
              "$type": "04"
            }
          },
          "BlockSpawner": {
            "BlockSpawnerId": "Thunderstorm_Tier1"
          }
        }
      }
    },
    {
      "x": 0,
      "y": 8,
      "z": 1,
      "name": "Cloth_Roof_Orange",
      "rotation": 2
    },
    {
      "x": 0,
      "y": -1,
      "z": 2,
      "name": "Furniture_Ancient_Barrel"
    },
    {
      "x": 0,
      "y": 3,
      "z": 2,
      "name": "Wood_Darkwood_Planks_Half",
      "rotation": 8
    },
    {
      "x": 0,
      "y": 4,
      "z": 2,
      "name": "Wood_Darkwood_Planks"
    },
    {
      "x": 0,
      "y": 9,
      "z": 2,
      "name": "Cloth_Roof_Orange_Flat"
    },
    {
      "x": 0,
      "y": 3,
      "z": 3,
      "name": "Wood_Darkwood_Planks_Half",
      "rotation": 8
    },
    {
      "x": 0,
      "y": 4,
      "z": 3,
      "name": "Wood_Darkwood_Planks"
    },
    {
      "x": 0,
      "y": 1,
      "z": 4,
      "name": "Wood_Darkwood_Fence"
    },
    {
      "x": 0,
      "y": 4,
      "z": 4,
      "name": "Wood_Darkwood_Planks"
    },
    {
      "x": 0,
      "y": 4,
      "z": 5,
      "name": "Wood_Darkwood_Planks_Half",
      "rotation": 4
    },
    {
      "x": 0,
      "y": 7,
      "z": 5,
      "name": "Cloth_Roof_Orange"
    },
    {
      "x": 1,
      "y": 4,
      "z": 0,
      "name": "Wood_Darkwood_Planks_Half",
      "rotation": 6
    },
    {
      "x": 1,
      "y": 7,
      "z": 0,
      "name": "Cloth_Roof_Orange",
      "rotation": 2
    },
    {
      "x": 1,
      "y": 1,
      "z": 1,
      "name": "Wood_Darkwood_Fence",
      "rotation": 2
    },
    {
      "x": 1,
      "y": 4,
      "z": 1,
      "name": "Wood_Darkwood_Planks"
    },
    {
      "x": 1,
      "y": 8,
      "z": 1,
      "name": "Cloth_Roof_Orange",
      "rotation": 2
    },
    {
      "x": 1,
      "y": -1,
      "z": 2,
      "name": "Furniture_Ancient_Barrel"
    },
    {
      "x": 1,
      "y": 3,
      "z": 2,
      "name": "Wood_Darkwood_Planks_Half",
      "rotation": 8
    },
    {
      "x": 1,
      "y": 4,
      "z": 2,
      "name": "Wood_Darkwood_Planks"
    },
    {
      "x": 1,
      "y": 9,
      "z": 2,
      "name": "Cloth_Roof_Orange_Flat"
    },
    {
      "x": 1,
      "y": -1,
      "z": 3,
      "name": "Furniture_Human_Ruins_Ladder"
    },
    {
      "x": 1,
      "y": 0,
      "z": 3,
      "name": "Furniture_Human_Ruins_Ladder"
    },
    {
      "x": 1,
      "y": 1,
      "z": 3,
      "name": "Furniture_Human_Ruins_Ladder"
    },
    {
      "x": 1,
      "y": 2,
      "z": 3,
      "name": "Furniture_Human_Ruins_Ladder"
    },
    {
      "x": 1,
      "y": 3,
      "z": 3,
      "name": "Furniture_Human_Ruins_Ladder"
    },
    {
      "x": 1,
      "y": 4,
      "z": 3,
      "name": "Furniture_Human_Ruins_Ladder"
    },
    {
      "x": 1,
      "y": 9,
      "z": 3,
      "name": "Cloth_Roof_Orange_Flat"
    },
    {
      "x": 1,
      "y": 1,
      "z": 4,
      "name": "Wood_Darkwood_Fence"
    },
    {
      "x": 1,
      "y": 4,
      "z": 4,
      "name": "Wood_Darkwood_Planks"
    },
    {
      "x": 1,
      "y": 8,
      "z": 4,
      "name": "Cloth_Roof_Orange"
    },
    {
      "x": 1,
      "y": 7,
      "z": 5,
      "name": "Cloth_Roof_Orange"
    },
    {
      "x": 2,
      "y": 4,
      "z": 0,
      "name": "Wood_Darkwood_Planks_Half",
      "rotation": 6
    },
    {
      "x": 2,
      "y": 5,
      "z": 0,
      "name": "Wood_Darkwood_Beam"
    },
    {
      "x": 2,
      "y": 6,
      "z": 0,
      "name": "Wood_Darkwood_Beam"
    },
    {
      "x": 2,
      "y": 7,
      "z": 0,
      "name": "Cloth_Roof_Orange",
      "rotation": 2
    },
    {
      "x": 2,
      "y": -1,
      "z": 1,
      "name": "Wood_Darkwood_Beam"
    },
    {
      "x": 2,
      "y": 0,
      "z": 1,
      "name": "Wood_Darkwood_Beam"
    },
    {
      "x": 2,
      "y": 1,
      "z": 1,
      "name": "Wood_Darkwood_Fence",
      "rotation": 2
    },
    {
      "x": 2,
      "y": 2,
      "z": 1,
      "name": "Wood_Darkwood_Beam"
    },
    {
      "x": 2,
      "y": 3,
      "z": 1,
      "name": "Wood_Darkwood_Beam"
    },
    {
      "x": 2,
      "y": 4,
      "z": 1,
      "name": "Wood_Darkwood_Planks"
    },
    {
      "x": 2,
      "y": 8,
      "z": 1,
      "name": "*Cloth_Roof_Orange_State_Definitions_Corner_Left",
      "rotation": 1
    },
    {
      "x": 2,
      "y": -1,
      "z": 2,
      "name": "Furniture_Ancient_Crate",
      "rotation": 2
    },
    {
      "x": 2,
      "y": 4,
      "z": 2,
      "name": "Wood_Darkwood_Planks"
    },
    {
      "x": 2,
      "y": 8,
      "z": 2,
      "name": "Cloth_Roof_Orange",
      "rotation": 1
    },
    {
      "x": 2,
      "y": -1,
      "z": 3,
      "name": "Furniture_Ancient_Crate",
      "rotation": 2
    },
    {
      "x": 2,
      "y": 0,
      "z": 3,
      "name": "Furniture_Ancient_Crate",
      "rotation": 2
    },
    {
      "x": 2,
      "y": 1,
      "z": 3,
      "name": "Wood_Darkwood_Fence",
      "rotation": 1
    },
    {
      "x": 2,
      "y": 4,
      "z": 3,
      "name": "Wood_Darkwood_Planks"
    },
    {
      "x": 2,
      "y": 8,
      "z": 3,
      "name": "Cloth_Roof_Orange",
      "rotation": 1
    },
    {
      "x": 2,
      "y": -1,
      "z": 4,
      "name": "Wood_Darkwood_Beam"
    },
    {
      "x": 2,
      "y": 0,
      "z": 4,
      "name": "Wood_Darkwood_Beam"
    },
    {
      "x": 2,
      "y": 1,
      "z": 4,
      "name": "*Wood_Darkwood_Fence_State_Definitions_Corner",
      "rotation": 3
    },
    {
      "x": 2,
      "y": 2,
      "z": 4,
      "name": "Wood_Darkwood_Beam"
    },
    {
      "x": 2,
      "y": 3,
      "z": 4,
      "name": "Wood_Darkwood_Beam"
    },
    {
      "x": 2,
      "y": 4,
      "z": 4,
      "name": "Wood_Darkwood_Planks"
    },
    {
      "x": 2,
      "y": 4,
      "z": 5,
      "name": "Wood_Darkwood_Planks_Half",
      "rotation": 4
    },
    {
      "x": 2,
      "y": 5,
      "z": 5,
      "name": "Wood_Darkwood_Beam"
    },
    {
      "x": 2,
      "y": 6,
      "z": 5,
      "name": "Wood_Darkwood_Beam"
    },
    {
      "x": 2,
      "y": 7,
      "z": 5,
      "name": "Cloth_Roof_Orange"
    },
    {
      "x": 3,
      "y": 7,
      "z": 0,
      "name": "*Cloth_Roof_Orange_State_Definitions_Corner_Left",
      "rotation": 1
    },
    {
      "x": 3,
      "y": -1,
      "z": 1,
      "name": "Furniture_Ancient_Crate",
      "rotation": 1
    },
    {
      "x": 3,
      "y": 4,
      "z": 1,
      "name": "Wood_Darkwood_Planks_Half",
      "rotation": 5
    },
    {
      "x": 3,
      "y": 5,
      "z": 1,
      "name": "Wood_Darkwood_Beam"
    },
    {
      "x": 3,
      "y": 6,
      "z": 1,
      "name": "Wood_Darkwood_Beam"
    },
    {
      "x": 3,
      "y": 7,
      "z": 1,
      "name": "Cloth_Roof_Orange",
      "rotation": 1
    },
    {
      "x": 3,
      "y": -1,
      "z": 2,
      "name": "Furniture_Ancient_Barrel"
    },
    {
      "x": 3,
      "y": 4,
      "z": 2,
      "name": "Wood_Darkwood_Planks_Half",
      "rotation": 5
    },
    {
      "x": 3,
      "y": 7,
      "z": 2,
      "name": "Cloth_Roof_Orange",
      "rotation": 1
    },
    {
      "x": 3,
      "y": 4,
      "z": 3,
      "name": "Wood_Darkwood_Planks_Half",
      "rotation": 5
    },
    {
      "x": 3,
      "y": 7,
      "z": 3,
      "name": "Cloth_Roof_Orange",
      "rotation": 1
    },
    {
      "x": 3,
      "y": 4,
      "z": 4,
      "name": "Wood_Darkwood_Planks_Half",
      "rotation": 5
    },
    {
      "x": 3,
      "y": 5,
      "z": 4,
      "name": "Wood_Darkwood_Beam"
    }
  ],
  "entities": [
    {
      "Components": {
        "EffectController": {},
        "DisplayName": {
          "DisplayName": {
            "MessageId": "server.npcRoles.Skeleton_Burnt_Archer.name",
            "Bold": null,
            "Italic": null,
            "Monospace": null,
            "Underline": null
          }
        },
        "UIComponentList": {},
        "Transform": {
          "Position": {
            "X": 2.3591064426106123,
            "Y": 5.0,
            "Z": 4.28207331695689
          },
          "Rotation": {
            "Pitch": 0.0,
            "Yaw": 1.5654363632202148,
            "Roll": 0.0
          }
        },
        "Velocity": {
          "Velocity": {
            "X": 0.0,
            "Y": 0.0,
            "Z": 0.0
          }
        },
        "PrefabCopyable": {},
        "Interactions": {
          "Interactions": {
            "Use": "*UseNPC"
          }
        },
        "Model": {
          "Model": {
            "Id": "Skeleton_Burnt_Archer",
            "Scale": 1.0,
            "Static": false
          }
        },
        "UUID": {
          "UUID": {
            "$binary": "MENx1dU7Nv+jVNIwCmnYDg==",
            "$type": "04"
          }
        },
        "EntityStats": {
          "Version": 5,
          "Stats": {
            "Oxygen": {
              "Id": "Oxygen",
              "Value": 100.0
            },
            "Mana": {
              "Id": "Mana",
              "Value": 0.0
            },
            "Health": {
              "Id": "Health",
              "Value": 74.0,
              "Modifiers": {
                "NPC_Max": {
                  "Id": "Static",
                  "CalculationType": "Additive",
                  "Amount": -26.0
                }
              }
            },
            "GlidingActive": {
              "Id": "GlidingActive",
              "Value": 0.0
            },
            "Immunity": {
              "Id": "Immunity",
              "Value": 0.0
            },
            "SignatureCharges": {
              "Id": "SignatureCharges",
              "Value": 0.0,
              "Modifiers": {
                "*Weapon_0": {
                  "Id": "Static",
                  "CalculationType": "Additive",
                  "Amount": 1.0
                }
              }
            },
            "Stamina": {
              "Id": "Stamina",
              "Value": 10.0
            },
            "Ammo": {
              "Id": "Ammo",
              "Value": 0.0
            },
            "Unknown": {
              "Id": "Unknown",
              "Value": 0.0
            },
            "SignatureEnergy": {
              "Id": "SignatureEnergy",
              "Value": 0.0,
              "Modifiers": {
                "*Weapon_0": {
                  "Id": "Static",
                  "CalculationType": "Additive",
                  "Amount": 6.0
                }
              }
            },
            "DeployablePreview": {
              "Id": "DeployablePreview",
              "Value": 0.0
            },
            "StaminaRegenDelay": {
              "Id": "StaminaRegenDelay",
              "Value": 0.0
            },
            "MagicCharges": {
              "Id": "MagicCharges",
              "Value": 0.0
            }
          }
        },
        "NPC": {
          "Version": 5,
          "UUID": {
            "$binary": "MENx1dU7Nv+jVNIwCmnYDg==",
            "$type": "04"
          },
          "Inventory": {
            "Version": 4,
            "Storage": {
              "Id": "Empty"
            },
            "Armor": {
              "Id": "Simple",
              "Capacity": 4,
              "Items": {}
            },
            "HotBar": {
              "Id": "Simple",
              "Capacity": 3,
              "Items": {
                "0": {
                  "Id": "Weapon_Shortbow_Iron_Rusty",
                  "Quantity": 1,
                  "Durability": 120.0,
                  "MaxDurability": 120.0,
                  "OverrideDroppedItemAnimation": false
                }
              }
            },
            "Utility": {
              "Id": "Simple",
              "Capacity": 2,
              "Items": {
                "0": {
                  "Id": "Furniture_Crude_Torch",
                  "Quantity": 1,
                  "Durability": 0.0,
                  "MaxDurability": 0.0,
                  "OverrideDroppedItemAnimation": false
                }
              }
            },
            "Backpack": {
              "Id": "Empty"
            },
            "ActiveHotbarSlot": 0,
            "Tool": {
              "Id": "Empty"
            },
            "ActiveToolsSlot": -1,
            "ActiveUtilitySlot": -1,
            "SortType": "Name"
          },
          "HvrPhs": 0.0,
          "HvrHght": 0.0,
          "MdlScl": 1.0,
          "SpawnInstant": "0001-01-01T12:00:00Z",
          "WorldgenId": 0,
          "PathManager": {},
          "LeashPos": {
            "X": 2.3591064426106123,
            "Y": 60.0,
            "Z": 4.28207331695689
          },
          "LeashHdg": 1.5654363632202148,
          "LeashPtch": 0.0,
          "RoleName": "Skeleton_Burnt_Archer"
        },
        "HeadRotation": {
          "Rotation": {
            "Pitch": 0.0,
            "Yaw": 1.5654363632202148,
            "Roll": 0.0
          }
        }
      }
    }
  ]
}